Workbook
Name Print_Area: #REF!

Sheet Guideline
A1: Guideline to make and understand Unit Test Case
A3: 1. Overview
A4: - In the template, Unit test cases are based on functions. Each sheet presents test cases for one function.
A5: - Cover: General information of the project and Unit Test cases
A6: - FunctionList: The list of Classes and Functions in the document. + To control that the number of Unit TC meets customer's requirement or the norm, user should fill value for 'Normal number of Test cases/KLOC'.
A7: + Click on Function link to open the related Test cases of the function. Note: You should create new Function sheet before creating the link
A8: - Test Report: provive the overview results of Functions Unit test: Test coverage, Test successful coverage (Summary, for normal/abnormal/boundary cases)
A9: Note: Should check the formula of "Sub Total" if you add more functions
A11: 2. Content in Test function sheet
A12: 2.1 Combination of test cases.
A13: - To verify that number of Unit TC meets customer's requirement or not. User has to fill number LOC of tested function and fill value of 'Normal number test cases/KLOC' item in FunctionList sheet, which is required by customer or normal value. The number of lacked TC is shown in 'Lack of test cases' item.
A14: - If the number of Unit TC does not meet the requirement, creator should explain the reasons.
... A46: - Test requirement: Brief description about requirements which are tested in this function, it is not mandatory.

Sheet Cover
B2: UNIT TEST DOCUMENT
A4: Project Name | B4: Clawbot System | E4: Creator | F4: Diepnt
A5: Project Code | E5: Issue Date | F5: 46241
A6: Document Code | E6: Version | F6: Version 1.0
A9: Record of change
A10: Effective Date | B10: Version | C10: Change Item | D10: *A,D,M | E10: Change description | F10: Reference
A11: 45950 | B11: 1.0 | C11: All | D11: A | E11: Create unit test file
A12: 45958 | B12: 1.0 | C12: Login, register, updateUser | D12: A | E12: Test case for authentication and user management.
A13: 45959 | B13: 1.0 | C13: CreateTourCategory, GetCategoryById, DeleteCategoryById, UpdateCategoryById | D13: A | E13: Test case for category management.
A14: 45969 | B14: 1.0 | C14: CreateBooking, UpdateBooking | D14: A | E14: Test case for booking management.
A15: 45981 | B15: 1.0 | C15: CreateReview, UpdateReview, CreateNews, DeleteNews, UpdateNews, GetNewsById, | D15: A | E15: Test case for review and news management.
A16: 45989 | B16: 1.0 | C16: GetCompanyByIdAsync, GetLocationByIdAsync, DeleteLocationAsync, UpdateLocationAsync | D16: A | E16: Test case for location management.

Sheet MethodList
C2: Method List
A4: Project Name | C4: =Cover!B4 -> Clawbot System
A5: Project Code | C5: =Cover!B5
A6: Test Environment Setup Description | C6: 1. Frontend: React + Vite (localhost:15876) 2. API Backend: .NET 8 (localhost:15874) 3. AgentService gRPC (localhost:15875) 4. Gateway: .NET 8 Ocelot (localhost:15873) 5. SQL Server 2022 (Docker :1433) 6. Redis 7 (Docker :6379) 7. Qdrant (Docker :6333) 8. MinIO (Docker :9001) 9. RabbitMQ (Docker :15672) 10. Dev account: admin@clawbot.local / Admin@12345
A8: No | B8: Module Name | C8: Method Name | D8: Sheet Name | E8: Pre-Condition
A9: 1 | B9: LlmBaseUrlGuard | C9: IsAllowedBaseUrl | D9: IsAllowedBaseUrl | E9: ResolveHostAddresses stubbed via DNS seam; Target URI scheme is HTTP/HTTPS.
A10: 2 | B10: LlmBaseUrlGuard | C10: CreateGuardedHttpClient | D10: CreateGuardedHttpClient | E10: Base URI validated via IsAllowedBaseUrl; HttpClientCache initialized.
A11: 3 | B11: SocialCredentialEnvelopeCodec | C11: Decode | D11: SocialCredential_Decode | E11: Valid IAuthenticatedEncryptor instance; TenantId and Provider context established.
A12: 4 | B12: PancakeTokenCipher | C12: DecryptOrRaw | D12: PancakeToken_DecryptOrRaw | E12: AesEncryptor configured with 256-bit Base64 Key; Ciphertext or raw token string.
A13: 5 | B13: RefreshTokenService | C13: RotateAsync | D13: RefreshToken_RotateAsync | E13: AppDbContext initialized; Existing RefreshToken entity seeded in Database.
A14: 6 | B14: ContentAssetReader | C14: ValidateStorageKey | D14: AssetReader_ValidateKey | E14: MinIO/S3 Storage provider configured; Tenant asset directory structure established.
A15: 7 | B15: AnthropicChatClient | C15: CompleteAsync-AnthropicChat | D15: Anthropic_CompleteAsync | E15: ResolvedLlmConfig set (ApiKey, BaseUrl); MockHttpMessageHandler initialized.
A16: 8 | B16: OpenAiChatClient | C16: CompleteAsync-OpenAiChat | D16: OpenAi_CompleteAsync | E16: ResolvedLlmConfig set (ApiKey, Provider); Mock HTTP response handler active.
A17: 9 | B17: OpenAiChatClient | C17: ParseDirectReply | D17: OpenAi_ParseDirectReply | E17: Direct HTTP Fallback raw JSON payload received from OpenAI-compatible endpoint.
A18: 10 | B18: OpenAiChatClient | C18: NormalizeApiKey | D18: OpenAi_NormalizeApiKey | E18: Raw API key string provided from configuration or Admin input form.
A19: 11 | B19: LlmTokenEstimator | C19: CountPrompt / CountText | D19: LlmTokenEstimator | E19: Encoding model initialized; ChatTurn list or raw text string provided.
A20: 12 | B20: LlmVisionCapabilityResolver | C20: ResolveFromConfig | D20: LlmVisionResolver_Cache | E20: ConcurrentDictionary Cache initialized; Model vision capability registry active.
... A38: 30 | B38: ChatReplyReviewTrigger | C38: NeedsLlmReview | D38: ChatTrigger_NeedsReview | E38: Bot generated reply text; Regex rules for URLs, Phone numbers, and Nicknames loaded.

Sheet Statistics
A2: UNIT TEST REPORT
A4: Project Name | B4: =Cover!B4 -> Clawbot System | D4: Creator | F4: Diepnt
A5: Project Code | B5: =Cover!B5 | D5: Reviewer/Approver
A6: Document Code | B6: =B5&"_"&"Test Report"&"_"&"vx.x" -> _Test Report_vx.x | D6: Issue Date | F6: 46241
A7: Notes
A11: No | B11: Function code | C11: Passed | D11: Failed | E11: Untested | F11: N | G11: A | H11: B | I11: Total Test Cases
A12: 1 | B12: IsAllowedBaseUrl | C12: =IsAllowedBaseUrl!A5 -> 21 | D12: =IsAllowedBaseUrl!C5 -> 0 | E12: =IsAllowedBaseUrl!F5 -> 0 | F12: =IsAllowedBaseUrl!L5 -> 2 | G12: =IsAllowedBaseUrl!M5 -> 17 | H12: =IsAllowedBaseUrl!N5 -> 2 | I12: =IsAllowedBaseUrl!O5 -> 21
A13: 2 | B13: CreateGuardedHttpClient | C13: =CreateGuardedHttpClient!A5 -> 14 | D13: =CreateGuardedHttpClient!C5 -> 0 | E13: =CreateGuardedHttpClient!F5 -> 0 | F13: =CreateGuardedHttpClient!L5 -> 1 | G13: =CreateGuardedHttpClient!M5 -> 10 | H13: =CreateGuardedHttpClient!N5 -> 3 | I13: =CreateGuardedHttpClient!O5 -> 14
A14: 3 | B14: Decode | C14: =Decode!A5 -> 11 | D14: =Decode!C5 -> 0 | E14: =Decode!F5 -> 0 | F14: =Decode!L5 -> 1 | G14: =Decode!M5 -> 9 | H14: =Decode!N5 -> 1 | I14: =Decode!O5 -> 11
A15: 4 | B15: DecryptOrRaw | C15: =DecryptOrRaw!A5 -> 7 | D15: =DecryptOrRaw!C5 -> 0 | E15: =DecryptOrRaw!F5 -> 0 | F15: =DecryptOrRaw!L5 -> 2 | G15: =DecryptOrRaw!M5 -> 4 | H15: =DecryptOrRaw!N5 -> 1 | I15: =DecryptOrRaw!O5 -> 7
A16: 5 | B16: RotateAsync | C16: =RotateAsync!A5 -> 7 | D16: =RotateAsync!C5 -> 0 | E16: =RotateAsync!F5 -> 0 | F16: =RotateAsync!L5 -> 2 | G16: =RotateAsync!M5 -> 5 | H16: =RotateAsync!N5 -> 0 | I16: =RotateAsync!O5 -> 7
A17: 6 | B17: ValidateStorageKey | C17: =ValidateStorageKey!A5 -> 17 | D17: =ValidateStorageKey!C5 -> 0 | E17: =ValidateStorageKey!F5 -> 0 | F17: =ValidateStorageKey!L5 -> 0 | G17: =ValidateStorageKey!M5 -> 16 | H17: =ValidateStorageKey!N5 -> 1 | I17: =ValidateStorageKey!O5 -> 17
A18: 7 | B18: CompleteAsync-AnthropicChat | C18: =CompleteAsyncAnthropicChat!A5 -> 16 | D18: =CompleteAsyncAnthropicChat!C5 -> 0 | E18: =CompleteAsyncAnthropicChat!F5 -> 0 | F18: =CompleteAsyncAnthropicChat!L5 -> 10 | G18: =CompleteAsyncAnthropicChat!M5 -> 5 | H18: =CompleteAsyncAnthropicChat!N5 -> 1 | I18: =CompleteAsyncAnthropicChat!O5 -> 16
A19: 8 | B19: CompleteAsync-OpenAiChat | C19: =CompleteAsyncOpenAiChat!A5 -> 8 | D19: =CompleteAsyncOpenAiChat!C5 -> 0 | E19: =CompleteAsyncOpenAiChat!F5 -> 0 | F19: =CompleteAsyncOpenAiChat!L5 -> 3 | G19: =CompleteAsyncOpenAiChat!M5 -> 3 | H19: =CompleteAsyncOpenAiChat!N5 -> 2 | I19: =CompleteAsyncOpenAiChat!O5 -> 8
A20: 9 | B20: ParseDirectReply | C20: =ParseDirectReply!A5 -> 6 | D20: =ParseDirectReply!C5 -> 0 | E20: =ParseDirectReply!F5 -> 0 | F20: =ParseDirectReply!L5 -> 2 | G20: =ParseDirectReply!M5 -> 2 | H20: =ParseDirectReply!N5 -> 2 | I20: =ParseDirectReply!O5 -> 6
A21: 10 | B21: NormalizeApiKey | C21: =NormalizeApiKey!A5 -> 6 | D21: =NormalizeApiKey!C5 -> 0 | E21: =NormalizeApiKey!F5 -> 0 | F21: =NormalizeApiKey!L5 -> 2 | G21: =NormalizeApiKey!M5 -> 0 | H21: =NormalizeApiKey!N5 -> 4 | I21: =NormalizeApiKey!O5 -> 6
A22: 11 | B22: CountPrompt / CountText | C22: =CountPromptCountText!A5 -> 8 | D22: =CountPromptCountText!C5 -> 0 | E22: =CountPromptCountText!F5 -> 2 | F22: =CountPromptCountText!L5 -> 5 | G22: =CountPromptCountText!M5 -> 1 | H22: =CountPromptCountText!N5 -> 4 | I22: =CountPromptCountText!O5 -> 10
A23: 12 | B23: ResolveFromConfig | C23: =ResolveFromConfig!A5 -> 15 | D23: =ResolveFromConfig!C5 -> 0 | E23: =ResolveFromConfig!F5 -> 0 | F23: =ResolveFromConfig!L5 -> 4 | G23: =ResolveFromConfig!M5 -> 5 | H23: =ResolveFromConfig!N5 -> 6 | I23: =ResolveFromConfig!O5 -> 15
A24: 13 | B24: CheckBody | C24: =CheckBody!A5 -> 8 | D24: =CheckBody!C5 -> 0 | E24: =CheckBody!F5 -> 0 | F24: =CheckBody!L5 -> 1 | G24: =CheckBody!M5 -> 7 | H24: =CheckBody!N5 -> 0 | I24: =CheckBody!O5 -> 8
A25: 14 | B25: LanguageMismatch | C25: =LanguageMismatch!A5 -> 5 | D25: =LanguageMismatch!C5 -> 0 | E25: =LanguageMismatch!F5 -> 0 | F25: =LanguageMismatch!L5 -> 3 | G25: =LanguageMismatch!M5 -> 1 | H25: =LanguageMismatch!N5 -> 1 | I25: =LanguageMismatch!O5 -> 5
A26: 15 | B26: CopiesBrief | C26: =CopiesBrief!A5 -> 7 | D26: =CopiesBrief!C5 -> 0 | E26: =CopiesBrief!F5 -> 0 | F26: =CopiesBrief!L5 -> 2 | G26: =CopiesBrief!M5 -> 3 | H26: =CopiesBrief!N5 -> 2 | I26: =CopiesBrief!O5 -> 7
A27: 16 | B27: SelectHook | C27: =SelectHook!A5 -> 8 | D27: =SelectHook!C5 -> 0 | E27: =SelectHook!F5 -> 0 | F27: =SelectHook!L5 -> 4 | G27: =SelectHook!M5 -> 1 | H27: =SelectHook!N5 -> 1 | I27: =SelectHook!O5 -> 3
A28: 17 | B28: ParsePlan / ParseOutline / ParsePackage | C28: =ParsePlanParseOutlineParsePacka!A5 -> 18 | D28: =ParsePlanParseOutlineParsePacka!C5 -> 0 | E28: =ParsePlanParseOutlineParsePacka!F5 -> 0 | F28: =ParsePlanParseOutlineParsePacka!L5 -> 4 | G28: =ParsePlanParseOutlineParsePacka!M5 -> 11 | H28: =ParsePlanParseOutlineParsePacka!N5 -> 3 | I28: =ParsePlanParseOutlineParsePacka!O5 -> 18
A29: 18 | B29: RunAsync | C29: =RunAsync!A5 -> 7 | D29: =RunAsync!C5 -> 0 | E29: =RunAsync!F5 -> 0 | F29: =RunAsync!L5 -> 1 | G29: =RunAsync!M5 -> 5 | H29: =RunAsync!N5 -> 1 | I29: =RunAsync!O5 -> 7
A30: 19 | B30: ResumeFromWriteAsync | C30: =ResumeFromWriteAsync!A5 -> 4 | D30: =ResumeFromWriteAsync!C5 -> 0 | E30: =ResumeFromWriteAsync!F5 -> 0 | F30: =ResumeFromWriteAsync!L5 -> 1 | G30: =ResumeFromWriteAsync!M5 -> 2 | H30: =ResumeFromWriteAsync!N5 -> 1 | I30: =ResumeFromWriteAsync!O5 -> 4
A31: 20 | B31: ReviewAsync | C31: =ReviewAsync!A5 -> 12 | D31: =ReviewAsync!C5 -> 0 | E31: =ReviewAsync!F5 -> 0 | F31: =ReviewAsync!L5 -> 2 | G31: =ReviewAsync!M5 -> 7 | H31: =ReviewAsync!N5 -> 3 | I31: =ReviewAsync!O5 -> 12
A32: 21 | B32: LooksLikeInstructionInjection | C32: =LooksLikeInstructionInjection!A5 -> 10 | D32: =LooksLikeInstructionInjection!C5 -> 0 | E32: =LooksLikeInstructionInjection!F5 -> 0 | F32: =LooksLikeInstructionInjection!L5 -> 7 | G32: =LooksLikeInstructionInjection!M5 -> 1 | H32: =LooksLikeInstructionInjection!N5 -> 2 | I32: =LooksLikeInstructionInjection!O5 -> 10
A33: 22 | B33: Parse / ParseVision | C33: =ParseVision!A5 -> 17 | D33: =ParseVision!C5 -> 0 | E33: =ParseVision!F5 -> 0 | F33: =ParseVision!L5 -> 3 | G33: =ParseVision!M5 -> 12 | H33: =ParseVision!N5 -> 2 | I33: =ParseVision!O5 -> 17
A34: 23 | B34: Check / ContainsAbsoluteGuarantee | C34: =CheckContainsAbsoluteGuarantee!A5 -> 8 | D34: =CheckContainsAbsoluteGuarantee!C5 -> 0 | E34: =CheckContainsAbsoluteGuarantee!F5 -> 0 | F34: =CheckContainsAbsoluteGuarantee!L5 -> 1 | G34: =CheckContainsAbsoluteGuarantee!M5 -> 5 | H34: =CheckContainsAbsoluteGuarantee!N5 -> 2 | I34: =CheckContainsAbsoluteGuarantee!O5 -> 8
A35: 24 | B35: RedactHistoryAsync | C35: =RedactHistoryAsync!A5 -> 5 | D35: =RedactHistoryAsync!C5 -> 0 | E35: =RedactHistoryAsync!F5 -> 0 | F35: =RedactHistoryAsync!L5 -> 2 | G35: =RedactHistoryAsync!M5 -> 3 | H35: =RedactHistoryAsync!N5 -> 0 | I35: =RedactHistoryAsync!O5 -> 5
A36: 25 | B36: IsCostCapReached | C36: =IsCostCapReached!A5 -> 7 | D36: =IsCostCapReached!C5 -> 0 | E36: =IsCostCapReached!F5 -> 0 | F36: =IsCostCapReached!L5 -> 3 | G36: =IsCostCapReached!M5 -> 0 | H36: =IsCostCapReached!N5 -> 4 | I36: =IsCostCapReached!O5 -> 7
A37: 26 | B37: ApplyOnceAsync | C37: =ApplyOnceAsync!A5 -> 8 | D37: =ApplyOnceAsync!C5 -> 0 | E37: =ApplyOnceAsync!F5 -> 0 | F37: =ApplyOnceAsync!L5 -> 3 | G37: =ApplyOnceAsync!M5 -> 2 | H37: =ApplyOnceAsync!N5 -> 3 | I37: =ApplyOnceAsync!O5 -> 8
A38: 27 | B38: IsAmbiguousMetaFailure | C38: =IsAmbiguousMetaFailure!A5 -> 8 | D38: =IsAmbiguousMetaFailure!C5 -> 0 | E38: =IsAmbiguousMetaFailure!F5 -> 0 | F38: =IsAmbiguousMetaFailure!L5 -> 1 | G38: =IsAmbiguousMetaFailure!M5 -> 3 | H38: =IsAmbiguousMetaFailure!N5 -> 4 | I38: =IsAmbiguousMetaFailure!O5 -> 8
A39: 28 | B39: ExecuteAsync | C39: =ExecuteAsync!A5 -> 6 | D39: =ExecuteAsync!C5 -> 0 | E39: =ExecuteAsync!F5 -> 0 | F39: =ExecuteAsync!L5 -> 1 | G39: =ExecuteAsync!M5 -> 3 | H39: =ExecuteAsync!N5 -> 2 | I39: =ExecuteAsync!O5 -> 6
A40: 29 | B40: PollConversationsAsync | C40: =PollConversationsAsync!A5 -> 11 | D40: =PollConversationsAsync!C5 -> 0 | E40: =PollConversationsAsync!F5 -> 0 | F40: =PollConversationsAsync!L5 -> 3 | G40: =PollConversationsAsync!M5 -> 1 | H40: =PollConversationsAsync!N5 -> 7 | I40: =PollConversationsAsync!O5 -> 11
A41: 30 | B41: NeedsLlmReview | C41: =NeedsLlmReview!A5 -> 10 | D41: =NeedsLlmReview!C5 -> 0 | E41: =NeedsLlmReview!F5 -> 0 | F41: =NeedsLlmReview!L5 -> 6 | G41: =NeedsLlmReview!M5 -> 1 | H41: =NeedsLlmReview!N5 -> 3 | I41: =NeedsLlmReview!O5 -> 10
B44: Sub total | C44: =SUM(C12:C41) -> 295 | D44: =SUM(D10:D16) -> 0 | E44: =SUM(E10:E16) -> 0 | F44: =SUM(F10:F16) -> 8 | G44: =SUM(G10:G16) -> 45 | H44: =SUM(H10:H16) -> 7 | I44: =SUM(I12:I41) -> 292
B46: Test coverage | D46: =(C44+D44)*100/(I44) -> 101.0274 | E46: %
B47: Test successful coverage | D47: =C44*100/(I44) -> 101.0274 | E47: %
B48: Normal case | D48: =F44*100/I44 -> 2.739726 | E48: %
...

Sheet IsAllowedBaseUrl
A1: Code Module | C1: LlmBaseUrlGuard | F1: Method | L1: IsAllowedBaseUrl
A2: Created By | C2: Diepnt | F2: Executed By | P2: Diepnt
A3: Test requirement | C3: <Brief description about requirements which are tested in this function>
A4: Passed | C4: Failed | F4: Untested | L4: N/A/B | O4: Total Test Cases
A5: =COUNTIF(F73:HW73,"P") -> 21 | C5: =COUNTIF(F73:HW73,"F") -> 0 | F5: =SUM(O5,-A5,-C5) -> 0 | L5: =COUNTIF(E72:HW72,"N") -> 2 | M5: =COUNTIF(E72:HW72,"A") -> 17 | N5: =COUNTIF(E72:HW72,"B") -> 2 | O5: =COUNTA(E7:HZ7) -> 21
F7: UTCID01 | G7: UTCID02 | H7: UTCID03 | I7: UTCID04 | J7: UTCID05 | K7: UTCID06 | L7: UTCID07 | M7: UTCID08 | N7: UTCID09 | O7: UTCID10 | P7: UTCID11 | Q7: UTCID12 | R7: UTCID13 | S7: UTCID14 | T7: UTCID15 | U7: UTCID16 | V7: UTCID17 | W7: UTCID18 | X7: UTCID19 | Y7: UTCID20 | Z7: UTCID21
A8: Condition | B8: Input
D9: baseUrl = invalid URI "not-a-url" | F9: O
D10: baseUrl = unsupported scheme "ftp://example.com" | G10: O
D11: baseUrl = public HTTPS "https://api.openai.com" | H11: O
D12: baseUrl = public HTTPS "https://api.anthropic.com" | I12: O
D13: baseUrl = HTTP public "http://httpbin.org/get" | J13: O
D14: baseUrl = HTTP Cloud Metadata "http://169.254.169.254/latest/meta-data/" | K14: O
D15: baseUrl = HTTPS loopback "https://127.0.0.1:8080/v1" | L15: O
D16: baseUrl = HTTPS localhost "https://localhost/api" | M16: O
D17: baseUrl = HTTPS 10.x "https://10.0.0.5/internal" | N17: O
D18: baseUrl = HTTPS 172.16.x "https://172.16.0.1/v1" | O18: O
D19: baseUrl = HTTPS 192.168.x "https://192.168.1.1/api" | P19: O
D20: baseUrl = HTTPS Cloud Metadata "https://169.254.169.254/latest/meta-data/" | Q20: O
D21: baseUrl = HTTPS CGNAT "https://100.64.0.1/svc" | R21: O
D22: baseUrl = HTTPS empty host "https:///path" | S22: O
D23: baseUrl = HTTPS with UserInfo "https://user:pass@secret.com/v1" | T23: O
D24: baseUrl = empty string "" | U24: O
D25: baseUrl = HTTP hostname → private IP "http://my-proxy.corp/api" | V25: O
D26: baseUrl = HTTPS mixed DNS "https://mixed.example.com" | W26: O
D27: baseUrl = HTTPS unresolved DNS "https://noresolve.example.com" | X27: O
B28: Option
D29: allowPrivateHosts = false (default) | F29: O | G29: O | H29: O | I29: O | J29: O | K29: O | L29: O | M29: O | N29: O | O29: O | P29: O | Q29: O | R29: O | S29: O | T29: O | U29: O | V29: O | W29: O | X29: O | Y29: O | Z29: O
D30: allowPrivateHosts = true | N30: O | Q30: O | W30: O | X30: O
D31: allowedPrivateOrigins = null (default) | F31: O | G31: O | H31: O | I31: O | J31: O | K31: O | L31: O | M31: O | N31: O | O31: O | P31: O | Q31: O | R31: O | S31: O | T31: O | U31: O | V31: O | W31: O | X31: O | Y31: O | Z31: O
D32: allowedPrivateOrigins = ["https://10.0.0.5"] | N32: O | X32: O
D33: allowedPrivateOrigins = ["https://192.168.1.1"] | P33: O
D34: allowedPrivateOrigins = ["https://other.host"] (non-matching) | Z34: O
D35: allowedPrivateOrigins = ["https://10.0.0.5/"] (trailing slash) | N35: O | X35: O
D36: allowedPrivateOrigins = [] (empty list) | Z36: O
B37: DNS Stub
D38: ResolveHostAddresses = default (real DNS) | F38: O | G38: O | H38: O | I38: O | J38: O | K38: O | L38: O | M38: O | P38: O | Q38: O | R38: O | S38: O | T38: O | U38: O
D39: ResolveHostAddresses stub → [public IP] | V39: O | W39: O
D40: ResolveHostAddresses stub → [public, private] (mixed) | W40: O
D41: ResolveHostAddresses stub → SocketException | X41: O
...

Sheet CreateGuardedHttpClient
A1: Code Module | C1: LlmBaseUrlGuard | F1: Method | L1: CreateGuardedHttpClient
A2: Created By | C2: Diepnt | F2: Executed By | P2: Diepnt
A3: Test requirement | C3: <Brief description about requirements which are tested in this function>
A4: Passed | C4: Failed | F4: Untested | L4: N/A/B | O4: Total Test Cases
A5: =COUNTIF(F50:HP50,"P") -> 14 | C5: =COUNTIF(F50:HP50,"F") -> 0 | F5: =SUM(O5,-A5,-C5) -> 0 | L5: =COUNTIF(E49:HP49,"N") -> 1 | M5: =COUNTIF(E49:HP49,"A") -> 10 | N5: =COUNTIF(E49:HP49,"B") -> 3 | O5: =COUNTA(E7:HS7) -> 14
F7: UTCID01 | G7: UTCID02 | H7: UTCID03 | I7: UTCID04 | J7: UTCID05 | K7: UTCID06 | L7: UTCID07 | M7: UTCID08 | N7: UTCID09 | O7: UTCID10 | P7: UTCID11 | Q7: UTCID12 | R7: UTCID13 | S7: UTCID14
A8: Condition | B8: Input
D9: baseUri = null | F9: O
D10: baseUri = "https://api.openai.com" (public HTTPS) | G10: O | P10: O | R10: O
D11: baseUri = "https://api.anthropic.com" (public HTTPS) | H11: O
D12: baseUri = "http://httpbin.org" (HTTP public) | I12: O
D13: baseUri = "https://10.0.0.5/v1" (private HTTPS) | J13: O | M13: O
D14: baseUri = "https://192.168.1.1/api" (private HTTPS) | K14: O
D15: baseUri = "https://169.254.169.254/metadata" (Cloud Metadata HTTPS) | L15: O
D16: baseUri = "https://mixed.example.com" (mixed DNS) | N16: O
D17: baseUri = "https://API.OpenAI.COM" (same origin, different casing) | Q17: O
D18: IPv4-mapped IPv6 DNS address for "https://api.openai.com" | R18: O
B19: Option
D20: allowPrivateHosts = false (default) | F20: O | G20: O | H20: O | I20: O | J20: O | K20: O | L20: O | M20: O | N20: O | O20: O | P20: O | Q20: O | R20: O | S20: O
D21: allowPrivateHosts = true | L21: O | N21: O
D22: allowedPrivateOrigins = null (default) | F22: O | G22: O | H22: O | I22: O | J22: O | K22: O | L22: O | M22: O | N22: O | O22: O | P22: O | Q22: O | R22: O | S22: O
D23: allowedPrivateOrigins = ["https://10.0.0.5"] | M23: O | S23: O
D24: timeoutSeconds = 120 (default) | F24: O | G24: O | H24: O | I24: O | J24: O | K24: O | L24: O | M24: O | N24: O | O24: O | P24: O | Q24: O | R24: O | S24: O
D25: timeoutSeconds = 60 (custom) | O25: O
B26: DNS Stub
D27: ResolveHostAddresses = default (real DNS) | F27: O | G27: O | H27: O | I27: O | J27: O | K27: O | L27: O | M27: O | N27: O | O27: O | P27: O | Q27: O
D28: ResolveHostAddresses stub → [public IP] | R28: O
A29: Confirm | B29: Exception
D30: ArgumentNullException ("baseUri") | F30: O
D31: InvalidOperationException ("not allowed") | H31: O | I31: O | J31: O | K31: O | N31: O
B32: Return
D33: Returns HttpClient (not null) | G33: O | L33: O | M33: O | O33: O | P33: O | Q33: O | R33: O | S33: O
B34: Handler
D35: AllowAutoRedirect = false | G35: O | L35: O | M35: O | O35: O | P35: O | Q35: O | R35: O | S35: O
D36: UseProxy = false | G36: O | L36: O | M36: O | O36: O | P36: O | Q36: O | R36: O | S36: O
D37: PooledConnectionLifetime = 5 minutes | G37: O | L37: O | M37: O | O37: O | P37: O | Q37: O | R37: O | S37: O
D38: BaseAddress = origin (scheme+host+port, no path) | G38: O | L38: O | M38: O | O38: O | P38: O | Q38: O | R38: O | S38: O
D39: Timeout = 120s (default) | G39: O | L39: O | M39: O | P39: O | Q39: O | R39: O | S39: O
D40: Timeout = 60s (custom) | O40: O
D41: ConnectCallback = present (public host, SSRF protection at connect time) | G41: O | I41: O | O41: O | Q41: O | S41: O
...

Sheet Decode
A1: Code Module | C1: SocialCredentialEnvelopeCodec | F1: Method | L1: Decode
A2: Created By | C2: Diepnt | F2: Executed By | P2: Diepnt
A3: Test requirement | C3: <Brief description about requirements which are tested in this function>
A4: Passed | C4: Failed | F4: Untested | L4: N/A/B | O4: Total Test Cases
A5: =COUNTIF(F47:HM47,"P") -> 11 | C5: =COUNTIF(F47:HM47,"F") -> 0 | F5: =SUM(O5,-A5,-C5) -> 0 | L5: =COUNTIF(E46:HM46,"N") -> 1 | M5: =COUNTIF(E46:HM46,"A") -> 9 | N5: =COUNTIF(E46:HM46,"B") -> 1 | O5: =COUNTA(E7:HP7) -> 11
F7: UTCID01 | G7: UTCID02 | H7: UTCID03 | I7: UTCID04 | J7: UTCID05 | K7: UTCID06 | L7: UTCID07 | M7: UTCID08 | N7: UTCID09 | O7: UTCID10 | P7: UTCID11
A8: Condition | B8: Input
D9: encryptor = null | F9: O
D10: encryptor = valid IAuthenticatedEncryptor | G10: O | H10: O | I10: O | J10: O | K10: O | L10: O | M10: O | N10: O | O10: O | P10: O
D11: encryptor = IEncryptor (not IAuthenticatedEncryptor) | H11: O
D12: tenantId = Guid.Empty | I12: O
D13: tenantId = Guid.NewGuid() (valid) | G13: O | J13: O | K13: O | L13: O | M13: O | N13: O | O13: O | P13: O
D14: provider = null/empty | J14: O
D15: provider = "facebook" (valid) | G15: O | K15: O | L15: O | M15: O | N15: O | O15: O | P15: O
D16: provider = "Facebook" (different casing) | K16: O
D17: ciphertext = null/empty | L17: O
D18: ciphertext = valid encrypted JSON (correct version, matching tenant/provider/page) | G18: O | M18: O
D19: ciphertext = valid encrypted JSON (version != CurrentVersion) | N19: O
D20: ciphertext = valid encrypted JSON (wrong tenantId) | O20: O
D21: ciphertext = valid encrypted JSON (wrong provider) | O21: O
D22: ciphertext = valid encrypted JSON (wrong pageId) | O22: O
D23: ciphertext = valid encrypted JSON (missing "version" field = legacy) | P23: O
D24: ciphertext = malformed JSON | P24: O
D25: ciphertext = non-encrypted garbage | P25: O
B26: Option
D27: pageId = null (both caller and envelope) | G27: O | M27: O
D28: pageId = "12345" (matching) | M28: O
D29: pageId = "99999" (non-matching) | O29: O
A30: Confirm | B30: Return Invalid
D31: encryptor = null → Invalid | F31: O
D32: encryptor = IEncryptor (not authenticated) → Invalid | H32: O
D33: tenantId = Guid.Empty → Invalid | I33: O
D34: provider = null/empty → Invalid | J34: O
D35: provider casing mismatch ("Facebook" vs "facebook") → Invalid | K35: O
D36: ciphertext = null/empty → Invalid | L36: O
D37: ciphertext = wrong version → Invalid | N37: O
D38: ciphertext = wrong tenant/provider/page binding → Invalid | O38: O
D39: ciphertext = legacy (no version field) → Invalid | P39: O
D40: ciphertext = malformed JSON → Invalid | P40: O
D41: ciphertext = CryptographicException → Invalid | P41: O
...

Sheet DecryptOrRaw
A1: Code Module | C1: PancakeTokenCipher | F1: Method | L1: DecryptOrRaw
A2: Created By | C2: Diepnt | F2: Executed By | P2: Diepnt
A3: Test requirement | C3: <Brief description about requirements which are tested in this function>
A4: Passed | C4: Failed | F4: Untested | L4: N/A/B | O4: Total Test Cases
A5: =COUNTIF(F27:HM27,"P") -> 7 | C5: =COUNTIF(F27:HM27,"F") -> 0 | F5: =SUM(O5,-A5,-C5) -> 0 | L5: =COUNTIF(E26:HM26,"N") -> 2 | M5: =COUNTIF(E26:HM26,"A") -> 4 | N5: =COUNTIF(E26:HM26,"B") -> 1 | O5: =COUNTA(E7:HP7) -> 7
F7: UTCID01 | G7: UTCID02 | H7: UTCID03 | I7: UTCID04 | J7: UTCID05 | K7: UTCID06 | L7: UTCID07
A8: Condition | B8: Input
D9: encryptor = null | F9: O
D10: encryptor = valid IEncryptor | G10: O | H10: O | I10: O | J10: O | K10: O | L10: O
D11: stored = null/empty | G11: O
D12: stored = valid encrypted token | H12: O
D13: stored = raw JWT string (not encrypted) | I13: O
D14: stored = garbage string (not base64, not encrypted) | J14: O
D15: stored = base64 that looks like authenticated envelope but decrypt fails | K15: O
D16: stored = base64 that looks like legacy ciphertext but decrypt fails | L16: O
A17: Confirm | B17: Return value
D18: null/empty stored → "" (empty string) | G18: O
D19: valid encrypted → decrypted plaintext | H19: O
D20: raw JWT → raw JWT (unchanged) | I20: O
D21: garbage string → raw garbage (unchanged, FormatException path) | J21: O
B22: Return Resolved
D23: null encryptor → ArgumentNullException | F23: O
D24: authenticated envelope + CryptographicException → throw (not swallowed) | K24: O
D25: legacy ciphertext + CryptographicException → throw (not swallowed) | L25: O
A26: Result | B26: Type(N : Normal, A : Abnormal, B : Boundary) | F26: A | G26: B | H26: N | I26: N | J26: A | K26: A | L26: A
B27: Passed/Failed | F27: P | G27: P | H27: P | I27: P | J27: P | K27: P | L27: P
B28: Executed Date | F28: 46240 | G28: 46240 | H28: 46240 | I28: 46240 | J28: 46240 | K28: 46240 | L28: 46240
B29: Defect ID

Sheet RotateAsync
A1: Code Module | C1: RefreshTokenService | F1: Method | L1: RotateAsync
A2: Created By | C2: Diepnt | F2: Executed By | P2: Diepnt
A3: Test requirement | C3: <Brief description about requirements which are tested in this function>
A4: Passed | C4: Failed | F4: Untested | L4: N/A/B | O4: Total Test Cases
A5: =COUNTIF(F33:HM33,"P") -> 7 | C5: =COUNTIF(F33:HM33,"F") -> 0 | F5: =SUM(O5,-A5,-C5) -> 0 | L5: =COUNTIF(E32:HM32,"N") -> 2 | M5: =COUNTIF(E32:HM32,"A") -> 5 | N5: =COUNTIF(E32:HM32,"B") -> 0 | O5: =COUNTA(E7:HP7) -> 7
F7: UTCID01 | G7: UTCID02 | H7: UTCID03 | I7: UTCID04 | J7: UTCID05 | K7: UTCID06 | L7: UTCID07
A8: Condition | B8: Input
D9: rawToken = "valid-raw-token" | F9: O | G9: O | H9: O | I9: O | J9: O | K9: O | L9: O
D10: rawToken hash not found in DB | F10: O
D11: rawToken hash found, RevokedAt = null, ExpiresAt > now (valid live token) | G11: O
D12: rawToken hash found, RevokedAt != null, ReplacedBy != null, within grace window | H12: O
D13: rawToken hash found, RevokedAt != null, outside grace window | I13: O
D14: rawToken hash found, ExpiresAt <= now (expired) | J14: O
D15: rawToken hash found, RevokedAt != null, ReplacedBy = null (revoke-only, no successor) | K15: O
D16: rawToken hash found, valid → second rotate with same token | L16: O
D17: ip = "1.2.3.4" | G17: O | H17: O
D18: ip = null | J18: O
A19: Confirm | B19: RotateOutcome.Invalid
D20: Token not found → Invalid | F20: O
D21: Token expired → Invalid | J21: O
B22: RotateOutcome.Success
D23: Valid live token → Success, new raw token, old revoked | G23: O
D24: Revoked + within grace → Success, sibling minted | H24: O
B25: RotateOutcome.Reuse (family revoked)
D26: Revoked + outside grace → Reuse, entire family revoked | I26: O
D27: Revoked + no successor + outside grace → Reuse | K27: O
B28: DB state
D29: After Success: old token RevokedAt != null, ReplacedBy = new token.Id | G29: O
D30: After Reuse: ALL family tokens RevokedAt != null | I30: O
D31: After Reuse: old token ReplacedBy = null (not touched) | I31: O
A32: Result | B32: Type(N : Normal, A : Abnormal, B : Boundary) | F32: A | G32: N | H32: N | I32: A | J32: A | K32: A | L32: A
B33: Passed/Failed | F33: P | G33: P | H33: P | I33: P | J33: P | K33: P | L33: P
B34: Executed Date | F34: 46240 | G34: 46240 | H34: 46240 | I34: 46240 | J34: 46240 | K34: 46240 | L34: 46240
B35: Defect ID

Sheet ValidateStorageKey
A1: Code Module | C1: ContentAssetReader | F1: Method | L1: ValidateStorageKey
A2: Created By | C2: Diepnt | F2: Executed By | P2: Diepnt
A3: Test requirement | C3: <Brief description about requirements which are tested in this function>
A4: Passed | C4: Failed | F4: Untested | L4: N/A/B | O4: Total Test Cases
A5: =COUNTIF(F46:HR46,"P") -> 17 | C5: =COUNTIF(F46:HR46,"F") -> 0 | F5: =SUM(O5,-A5,-C5) -> 0 | L5: =COUNTIF(E45:HR45,"N") -> 0 | M5: =COUNTIF(E45:HR45,"A") -> 16 | N5: =COUNTIF(E45:HR45,"B") -> 1 | O5: =COUNTA(E7:HU7) -> 17
F7: UTCID01 | G7: UTCID02 | H7: UTCID03 | I7: UTCID04 | J7: UTCID05 | K7: UTCID06 | L7: UTCID07 | M7: UTCID08 | N7: UTCID09 | O7: UTCID10 | P7: UTCID11 | Q7: UTCID12 | R7: UTCID13 | S7: UTCID14 | T7: UTCID15 | U7: UTCID16 | V7: UTCID17
A8: Condition | B8: Input
D9: storageKey = null/empty | F9: O
D10: storageKey = "tenants/{T}/content/{C}/{A}" (exact match) | G10: O
D11: storageKey = "tenants/{T}/content/{C}/{A}/extra" (path traversal suffix) | H11: O
D12: storageKey = "../../../etc/passwd" | I12: O
D13: storageKey = "tenants/{T}/content/{C}/{A}\\evil" (backslash) | J13: O
D14: storageKey = "tenants/{T}/content/{C}/{A}\0evil" (null byte) | K14: O
D15: storageKey = "tenants/{T}/content/{C}/{A}?query" (query string) | L15: O
D16: storageKey = "tenants/{T}/content/{C}/{A}#fragment" | M16: O
D17: storageKey = "tenants/{T}/content/{C}/{A}%tricky" (encoded %) | N17: O
D18: storageKey = "tenants/{T}/content/{C}/{A}:stream" (colon) | O18: O
D19: storageKey = "/tenants/{T}/content/{C}/{A}" (absolute path) | P19: O
D20: storageKey = "tenants/{T}/content/{C}//{A}" (double slash) | Q20: O
D21: storageKey = "tenants/{T}/content/{C}/./{A}" (dot segment) | R21: O
D22: storageKey = "tenants/{T}/content/{C}/../{A}" (dotdot segment) | S22: O
D23: storageKey = "tenants/{T}/content/{C}/%2e/{A}" (encoded dot) | T23: O
D24: storageKey = "tenants/{T}/content/{C}/%2e%2e/{A}" (encoded dotdot) | U24: O
D25: tenantId/contentItemId/assetId mismatch with key pattern | V25: O
A26: Confirm | B26: Exception thrown
D27: null/empty → InvalidOperationException("content_asset_storage_key_invalid") | F27: O
D28: Path traversal suffix → InvalidOperationException("content_asset_storage_key_mismatch") | H28: O
D29: ../ traversal → InvalidOperationException("content_asset_storage_key_invalid") | I29: O
D30: Backslash → InvalidOperationException("content_asset_storage_key_invalid") | J30: O
D31: Null byte → InvalidOperationException("content_asset_storage_key_invalid") | K31: O
D32: Query string → InvalidOperationException("content_asset_storage_key_invalid") | L32: O
D33: Fragment → InvalidOperationException("content_asset_storage_key_invalid") | M33: O
D34: Encoded % → InvalidOperationException("content_asset_storage_key_invalid") | N34: O
D35: Colon → InvalidOperationException("content_asset_storage_key_invalid") | O35: O
D36: Absolute path → InvalidOperationException("content_asset_storage_key_invalid") | P36: O
D37: Double slash → InvalidOperationException("content_asset_storage_key_invalid") | Q37: O
D38: Dot segment → InvalidOperationException("content_asset_storage_key_invalid") | R38: O
D39: Dotdot segment → InvalidOperationException("content_asset_storage_key_invalid") | S39: O
D40: Encoded dot → InvalidOperationException("content_asset_storage_key_invalid") | T40: O
D41: Encoded dotdot → InvalidOperationException("content_asset_storage_key_invalid") | U41: O
...

Sheet CompleteAsyncAnthropicChat
A1: Code Module | C1: AnthropicChatClient | F1: Method | L1: CompleteAsync
A2: Created By | C2: Diepnt | F2: Executed By | P2: Diepnt
A3: Test requirement | C3: <Brief description about requirements which are tested in this function>
A4: Passed | C4: Failed | F4: Untested | L4: N/A/B | O4: Total Test Cases
A5: =COUNTIF(F66:HQ66,"P") -> 16 | C5: =COUNTIF(F66:HQ66,"F") -> 0 | F5: =SUM(O5,-A5,-C5) -> 0 | L5: =COUNTIF(E65:HQ65,"N") -> 10 | M5: =COUNTIF(E65:HQ65,"A") -> 5 | N5: =COUNTIF(E65:HQ65,"B") -> 1 | O5: =COUNTA(E7:HT7) -> 16
F7: UTCID01 | G7: UTCID02 | H7: UTCID03 | I7: UTCID04 | J7: UTCID05 | K7: UTCID06 | L7: UTCID07 | M7: UTCID08 | N7: UTCID09 | O7: UTCID10 | P7: UTCID11 | Q7: UTCID12 | R7: UTCID13 | S7: UTCID14 | T7: UTCID15 | U7: UTCID16
A8: Condition | B8: Input
D9: systemPrompt = "You are a helpful assistant" | F9: O | G9: O | H9: O | I9: O | J9: O | K9: O | L9: O | M9: O | N9: O | O9: O | P9: O | Q9: O | R9: O | S9: O | T9: O
D10: systemPrompt = "" (empty) | I10: O
D11: history = [] | F11: O | G11: O | H11: O | I11: O | J11: O | K11: O | L11: O | M11: O | N11: O | O11: O | P11: O | Q11: O | R11: O | S11: O | T11: O
D12: history = [{user:"Hi"}, {assistant:"Hello"}] (2 turns) | H12: O
D13: history = [{user:"Hi"}, ...x50] (50 turns) | S13: O
D14: userMessage = "Hello" | F14: O | G14: O | H14: O | I14: O | J14: O | K14: O | L14: O | M14: O | N14: O | O14: O | P14: O | Q14: O | R14: O | S14: O | T14: O
D15: userMessage = "" (empty) | I15: O
D16: CancellationToken = default | F16: O | G16: O | H16: O | I16: O | J16: O | K16: O | L16: O | M16: O | N16: O | O16: O | P16: O | Q16: O | R16: O | T16: O
D17: CancellationToken = already cancelled | R17: O
B18: Config
D19: config.ApiKey = "sk-ant-test123" (valid) | F19: O | G19: O | H19: O | I19: O | J19: O | K19: O | L19: O | M19: O | N19: O | O19: O | P19: O | Q19: O | S19: O | T19: O
D20: config.ApiKey = null/empty | J20: O
D21: config.BaseUrl = null/empty (default) | F21: O | G21: O | H21: O | I21: O | J21: O | K21: O | L21: O | M21: O | N21: O | O21: O | P21: O | Q21: O | S21: O | T21: O
D22: config.BaseUrl = "https://my-proxy.example.com" | P22: O
D23: config.MaxOutputTokens = null (default 3000) | F23: O | G23: O | H23: O | I23: O | J23: O | K23: O | L23: O | M23: O | N23: O | O23: O | P23: O | Q23: O | S23: O | T23: O
D24: config.MaxOutputTokens = 2000 | Q24: O
D25: config.InputUsdPer1M = null (default 3.00) | F25: O | G25: O | H25: O | I25: O | J25: O | K25: O | L25: O | M25: O | N25: O | O25: O | P25: O | Q25: O | R25: O | S25: O
D26: config.InputUsdPer1M = 8.00, OutputUsdPer1M = 24.00 | T26: O
B27: HTTP Response
D28: Status = 200 OK with JSON | F28: O | G28: O | H28: O | I28: O | J28: O | K28: O | L28: O | M28: O | N28: O | O28: O | P28: O | Q28: O | S28: O | T28: O
D29: Status = 429 | K29: O
D30: Body = "null" string | L30: O
D31: Usage = {input_tokens:10, output_tokens:5} | F31: O | G31: O | H31: O | I31: O | J31: O | K31: O | L31: O | M31: O | N31: O | O31: O | P31: O | Q31: O | S31: O | T31: O
D32: Usage = {input_tokens:0, output_tokens:0} | M32: O
D33: Content = 1 text block | F33: O | G33: O | H33: O | I33: O | J33: O | K33: O | L33: O | M33: O | N33: O | O33: O | P33: O | Q33: O | S33: O | T33: O
D34: Content = 3 text blocks | N34: O
D35: Content = mixed types (text + tool_use + text) | O35: O
D36: Content = null in JSON | U36: O
A37: Confirm
B38: Return
D39: ClaudeReply.Text = concatenated text from content blocks | F39: O | G39: O | H39: O | I39: O | J39: O | K39: O | L39: O | M39: O | N39: O | O39: O | P39: O | Q39: O | R39: O | S39: O | T39: O
D40: ClaudeReply.Text = "Part1Part2Part3" | N40: O
D41: ClaudeReply.Text = "HelloWorld" (tool_use skipped) | O41: O
...

Sheet CompleteAsyncOpenAiChat
A1: Code Module | C1: OpenAiChatClient | F1: Method | L1: CompleteAsync
A2: Created By | C2: Diepnt | F2: Executed By | P2: Diepnt
A3: Test requirement | C3: <Brief description about requirements which are tested in this function>
A4: Passed | C4: Failed | F4: Untested | L4: N/A/B | O4: Total Test Cases
A5: =COUNTIF(F36:HQ36,"P") -> 8 | C5: =COUNTIF(F36:HQ36,"F") -> 0 | F5: =SUM(O5,-A5,-C5) -> 0 | L5: =COUNTIF(E35:HQ35,"N") -> 3 | M5: =COUNTIF(E35:HQ35,"A") -> 3 | N5: =COUNTIF(E35:HQ35,"B") -> 2 | O5: =COUNTA(E7:HT7) -> 8
F7: UTCID01 | G7: UTCID02 | H7: UTCID03 | I7: UTCID04 | J7: UTCID05 | K7: UTCID06 | L7: UTCID07 | M7: UTCID08
A8: Condition | B8: Input
D9: systemPrompt, history, userMessage | F9: O | G9: O | H9: O | I9: O | J9: O | K9: O | L9: O | M9: O
D10: config.ApiKey = "sk-test" (valid, normalized) | F10: O | G10: O | H10: O | I10: O | J10: O | K10: O | L10: O | M10: O
D11: config.ApiKey = "Bearer sk-test" (with Bearer prefix) | K11: O
D12: config.BaseUrl = "https://custom-proxy.com" | F12: O | H12: O | J12: O
D13: config.Provider = "openai-compatible" | H13: O | J13: O
D14: config.Provider = "openai" + non-default host | H14: O
D15: config.MaxOutputTokens = null | F15: O | H15: O | J15: O
D16: config.MaxOutputTokens = 500 | I16: O
B17: SDK Response
D18: SDK returns success with usage | F18: O | G18: O | I18: O
D19: SDK returns success with zero usage | G19: O
D20: SDK throws ClientResultException(Status=400) + fallback enabled | H20: O
D21: SDK throws HttpRequestException(Status=500) + fallback enabled → still throws (not fallback-eligible) | L21: O
D22: SDK throws ClientResultException(Status=401) + no _directHttp → still throws | M22: O
A23: Confirm
B24: Return
D25: ClaudeReply with real tokens + cost | F25: O | I25: O
D26: ClaudeReply with estimated tokens + IsEstimated=true | G26: O
D27: ClaudeReply via Direct HTTP fallback | H27: O
B28: Exception
D29: SDK exception, no fallback → propagate | L29: O | M29: O
D30: InvalidApiKey → InvalidOperationException | J30: O
B31: Request (Direct fallback path)
D32: Authorization: Bearer {normalized key} | H32: O
D33: URL = {BaseUrl}/chat/completions | H33: O
D34: Body contains model + messages + max_tokens | H34: O | I34: O
A35: Result | B35: Type(N : Normal, A : Abnormal, B : Boundary) | F35: N | G35: N | H35: B | I35: N | J35: A | K35: B | L35: A | M35: A
B36: Passed/Failed | F36: P | G36: P | H36: P | I36: P | J36: P | K36: P | L36: P | M36: P
B37: Executed Date | F37: 46240 | G37: 46240 | H37: 46240 | I37: 46240 | J37: 46240 | K37: 46240 | L37: 46240 | M37: 46240
B38: Defect ID

Sheet ParseDirectReply
A1: Code Module | C1: OpenAiChatClient | F1: Method | L1: ParseDirectReply
A2: Created By | C2: Diepnt | F2: Executed By | P2: Diepnt
A3: Test requirement | C3: <Brief description about requirements which are tested in this function>
A4: Passed | C4: Failed | F4: Untested | L4: N/A/B | O4: Total Test Cases
A5: =COUNTIF(F32:HQ32,"P") -> 6 | C5: =COUNTIF(F32:HQ32,"F") -> 0 | F5: =SUM(O5,-A5,-C5) -> 0 | L5: =COUNTIF(E31:HQ31,"N") -> 2 | M5: =COUNTIF(E31:HQ31,"A") -> 2 | N5: =COUNTIF(E31:HQ31,"B") -> 2 | O5: =COUNTA(E7:HT7) -> 6
F7: UTCID01 | G7: UTCID02 | H7: UTCID03 | I7: UTCID04 | J7: UTCID05 | K7: UTCID06
A8: Condition | B8: Input
D9: body = valid JSON with string content + usage | F9: O
D10: body = valid JSON with array content + usage | G10: O
D11: body = valid JSON with null content | H11: O
D12: body = valid JSON with zero/null usage | I12: O
D13: body = "not json" | J13: O
D14: body = valid JSON but no choices array | K14: O
D15: body = valid JSON with empty choices | K15: O
D16: systemPrompt = "System" | F16: O | G16: O | H16: O | I16: O | J16: O | K16: O
D17: history = [] | F17: O | G17: O | H17: O | I17: O | J17: O | K17: O
D18: userMessage = "Hi" | F18: O | G18: O | H18: O | I18: O | J18: O | K18: O
A19: Confirm | B19: Return
D20: Text = "Hello World" (string content) | F20: O
D21: Text = "Part1Part2" (array content concatenated) | G21: O
D22: Text = "" (null content) | H22: O
D23: InputTokens = prompt_tokens | F23: O | G23: O | H23: O
D24: CompletionTokens = completion_tokens | F24: O | G24: O | H24: O
D25: IsEstimated = false (usage present) | F25: O | G25: O | H25: O
D26: IsEstimated = true (no usage) | I26: O
D27: Model = config.Model | F27: O | G27: O | H27: O | I27: O
B28: No exception on malformed input
D29: Invalid JSON → default/empty values (fail-open for fallback path) | J29: O
D30: Empty choices → empty text | K30: O
A31: Result | B31: Type(N : Normal, A : Abnormal, B : Boundary) | F31: N | G31: N | H31: B | I31: B | J31: A | K31: A
B32: Passed/Failed | F32: P | G32: P | H32: P | I32: P | J32: P | K32: P
B33: Executed Date | F33: 46240 | G33: 46240 | H33: 46240 | I33: 46240 | J33: 46240 | K33: 46240
B34: Defect ID

Sheet NormalizeApiKey
A1: Code Module | C1: OpenAiChatClient | F1: Method | L1: NormalizeApiKey
A2: Created By | C2: Diepnt | F2: Executed By | P2: Diepnt
A3: Test requirement | C3: <Brief description about requirements which are tested in this function>
A4: Passed | C4: Failed | F4: Untested | L4: N/A/B | O4: Total Test Cases
A5: =COUNTIF(F23:HQ23,"P") -> 6 | C5: =COUNTIF(F23:HQ23,"F") -> 0 | F5: =SUM(O5,-A5,-C5) -> 0 | L5: =COUNTIF(E22:HQ22,"N") -> 2 | M5: =COUNTIF(E22:HQ22,"A") -> 0 | N5: =COUNTIF(E22:HQ22,"B") -> 4 | O5: =COUNTA(E7:HT7) -> 6
F7: UTCID01 | G7: UTCID02 | H7: UTCID03 | I7: UTCID04 | J7: UTCID05 | K7: UTCID06
A8: Condition | B8: Input
D9: apiKey = "sk-test123" (normal) | F9: O
D10: apiKey = " sk-test123 " (with whitespace) | G10: O
D11: apiKey = "Bearer sk-test123" (Bearer prefix) | H11: O
D12: apiKey = "bearer sk-test123" (lowercase bearer) | I12: O
D13: apiKey = "Bearer sk-test123" (Bearer + extra space) | J13: O
D14: apiKey = "sk- test" (space inside key) | K14: O
A15: Confirm | B15: Return
D16: "sk-test123" | F16: O
D17: "sk-test123" (trimmed) | G17: O
D18: "sk-test123" (Bearer stripped) | H18: O
D19: "sk-test123" (bearer stripped) | I19: O
D20: "sk-test123" (Bearer + extra space stripped) | J20: O
D21: "sk- test" (preserved, only leading space trimmed) | K21: O
A22: Result | B22: Type(N : Normal, A : Abnormal, B : Boundary) | F22: N | G22: N | H22: B | I22: B | J22: B | K22: B
B23: Passed/Failed | F23: P | G23: P | H23: P | I23: P | J23: P | K23: P
B24: Executed Date | F24: 46240 | G24: 46240 | H24: 46240 | I24: 46240 | J24: 46240 | K24: 46240
B25: Defect ID

Sheet CountPromptCountText
A1: Code Module | C1: LlmTokenEstimator | F1: Method | L1: CountPrompt / CountText
A2: Created By | C2: Diepnt | F2: Executed By | P2: Diepnt
A3: Test requirement | C3: <Brief description about requirements which are tested in this function>
A4: Passed | C4: Failed | F4: Untested | L4: N/A/B | O4: Total Test Cases
A5: =COUNTIF(F37:HQ37,"P") -> 8 | C5: =COUNTIF(F37:HQ37,"F") -> 0 | F5: =SUM(O5,-A5,-C5) -> 2 | L5: =COUNTIF(E36:HQ36,"N") -> 5 | M5: =COUNTIF(E36:HQ36,"A") -> 1 | N5: =COUNTIF(E36:HQ36,"B") -> 4 | O5: =COUNTA(E7:HT7) -> 10
F7: UTCID01 | G7: UTCID02 | H7: UTCID03 | I7: UTCID04 | J7: UTCID05 | K7: UTCID06 | L7: UTCID07 | M7: UTCID08 | N7: UTCID09 | O7: UTCID10
A8: Condition | B8: Input (CountText)
D9: text = null/empty | F9: O
D10: text = "Hello" (short text) | G10: O
D11: text = long paragraph | H11: O
D12: model = "gpt-4o" | F12: O | G12: O | H12: O | I12: O | J12: O | K12: O
D13: model = "gpt-4" | I13: O
D14: model = "claude-sonnet-4-20250514" (unknown → null encoding → fallback) | J14: O
D15: model = null/empty | K15: O
B16: Input (CountPrompt)
D17: systemPrompt = "You are helpful" | L17: O
D18: systemPrompt = null/empty | M18: O
D19: history = [] | L19: O | M19: O
D20: history = [{user:"Hi"}, {assistant:"Hello"}] | N20: O
D21: userMessage = "Hello" | L21: O | M21: O | N21: O
D22: userMessage = null/empty | O22: O
A23: Confirm | B23: CountText
D24: null/empty → 0 | F24: O
D25: "Hello" with gpt-4o → > 0 (tokenizer) | G25: O
D26: Long text → proportional to length | H26: O
D27: gpt-4 → cl100k_base encoding | I27: O
D28: claude model → fallback chars/4 | J28: O
D29: null model → o200k_base default | K29: O
B30: CountPrompt
D31: PrimingTokens(3) + TokensPerMessage(4) + system text tokens | L31: O
D32: No system prompt → no system tokens added | M32: O
D33: 2 history turns → +2*(4 + text tokens) | N33: O
D34: No user message → no user tokens added | O34: O
D35: Total >= PrimingTokens always | O35: O
A36: Result | B36: Type(N : Normal, A : Abnormal, B : Boundary) | F36: B | G36: N | H36: N | I36: N | J36: A | K36: B | L36: N | M36: B | N36: N | O36: B
B37: Passed/Failed | F37: P | G37: P | H37: P | I37: P | J37: P | K37: P | L37: P | O37: P
B38: Executed Date | F38: 46240 | G38: 46240 | H38: 46240 | I38: 46240 | J38: 46240 | K38: 46240 | L38: 46240 | M38: 46240 | N38: 46240 | O38: 46240
B39: Defect ID

Sheet ResolveFromConfig
A1: Code Module | C1: LlmVisionCapabilityResolver | F1: Method | L1: ResolveFromConfig
A2: Created By | C2: Diepnt | F2: Executed By | P2: Diepnt
A3: Test requirement | C3: <Brief description about requirements which are tested in this function>
A4: Passed | C4: Failed | F4: Untested | L4: N/A/B | O4: Total Test Cases
A5: =COUNTIF(F43:HQ43,"P") -> 15 | C5: =COUNTIF(F43:HQ43,"F") -> 0 | F5: =SUM(O5,-A5,-C5) -> 0 | L5: =COUNTIF(E42:HQ42,"N") -> 4 | M5: =COUNTIF(E42:HQ42,"A") -> 5 | N5: =COUNTIF(E42:HQ42,"B") -> 6 | O5: =COUNTA(E7:HT7) -> 15
F7: UTCID01 | G7: UTCID02 | H7: UTCID03 | I7: UTCID04 | J7: UTCID05 | K7: UTCID06 | L7: UTCID07 | M7: UTCID08 | N7: UTCID09 | O7: UTCID10 | P7: UTCID11 | Q7: UTCID12 | R7: UTCID13 | S7: UTCID14 | T7: UTCID15
A8: Condition | B8: Input
D9: provider = "openai", modelId = "gpt-4o", override = null | F9: O
D10: provider = "openai", modelId = "gpt-3.5-turbo", override = null | G10: O
D11: provider = "anthropic", modelId = "claude-sonnet-4-20250514", override = null | H11: O
D12: provider = "openai-compatible", modelId = "gpt-4o", override = null | I12: O
D13: provider = "openai", modelId = "gpt-4o", override = true | J13: O
D14: provider = "openai", modelId = "gpt-4o", override = false | K14: O
D15: provider = "", modelId = "gpt-4o", override = null | L15: O
D16: provider = "openai", modelId = "", override = null | M16: O
D17: provider = "unknown-provider", modelId = "custom-model", override = null | N17: O
D18: provider = "openai", modelId = "gpt-4.1-nano", override = null | O18: O
D19: provider = "anthropic", modelId = "claude-3-opus", override = null | P19: O
B20: Cache
D21: Cache key = tenantId+agentCode+llmConfigId+configUpdatedAt | Q21: O | R21: O | S21: O | T21: O
D22: Set then TryGet same key | Q22: O
D23: TryGet different llmConfigId → miss | R23: O
D24: Invalidate(llmConfigId) → all entries with that ID removed | S24: O
D25: Invalidate → TryGet same key → miss | T25: O
A26: Confirm | B26: ResolveFromConfig
D27: gpt-4o (openai) → Available | F27: O
D28: gpt-3.5-turbo (openai) → Unavailable | G28: O
D29: claude-sonnet-4 (anthropic) → Available | H29: O
D30: openai-compatible → Unknown | I30: O
D31: override=true → Available (overrides registry) | J31: O
D32: override=false → Unavailable (overrides registry) | K32: O
D33: empty provider → Unknown | L33: O
D34: empty model → Unknown | M34: O
D35: unknown provider+model → Unknown | N35: O
D36: gpt-4.1-nano → Available (gpt-4.1 prefix match) | O36: O
D37: claude-3-opus → Available | P37: O
B38: Cache
D39: Set + TryGet same key → hit, capability matches | Q39: O
D40: TryGet different ID → miss | R40: O
D41: Invalidate removes matching entries | S41: O | T41: O
...

Sheet CheckBody
A1: Code Module | C1: ContentChainGates | F1: Method | L1: CheckBody
A2: Created By | C2: Diepnt | F2: Executed By | P2: Diepnt
A3: Test requirement | C3: <Brief description about requirements which are tested in this function>
A4: Passed | C4: Failed | F4: Untested | L4: N/A/B | O4: Total Test Cases
A5: =COUNTIF(F36:HQ36,"P") -> 8 | C5: =COUNTIF(F36:HQ36,"F") -> 0 | F5: =SUM(O5,-A5,-C5) -> 0 | L5: =COUNTIF(E35:HQ35,"N") -> 1 | M5: =COUNTIF(E35:HQ35,"A") -> 7 | N5: =COUNTIF(E35:HQ35,"B") -> 0 | O5: =COUNTA(E7:HT7) -> 8
F7: UTCID01 | G7: UTCID02 | H7: UTCID03 | I7: UTCID04 | J7: UTCID05 | K7: UTCID06 | L7: UTCID07 | M7: UTCID08
A8: Condition | B8: Input
D9: body = null/empty | F9: O
D10: body = valid text within limits | G10: O
D11: body = text shorter than limits.Min | H11: O
D12: body = text longer than limits.Max | I12: O
D13: body = text with "https://example.com" | J13: O
D14: body = text with "http://evil.com" | J14: O
D15: body = text with "www.evil.com" | J15: O
D16: body = text with "{{name}}" | K16: O
D17: body = text that copies brief verbatim (>60% words match) | L17: O
D18: body = Vietnamese text + language="vi" | G18: O
D19: body = English text + language="vi" (mismatch) | M19: O
D20: body = short text + language="vi" (below MinBodyLengthForLanguageCheck=60) | G20: O
D21: brief = "" (empty brief) | G21: O
D22: brief = short text (< MinBriefLengthForCopyCheck=40) | G22: O
D23: limits = {Min: 100, Max: 5000} | G23: O | H23: O | I23: O | J23: O | K23: O | L23: O | M23: O
A24: Confirm
B25: Fail
D26: empty body → WriteEmptyOutput | F26: O
D27: too short → WriteTooShort | H27: O
D28: too long → WriteTooLong | I28: O
D29: contains URL → WriteContainsUrl | J29: O
D30: placeholder leftover → WritePlaceholderLeft | K30: O
D31: copies brief → WriteCopiesBrief | L31: O
D32: language mismatch → WriteLanguageMismatch | M32: O
B33: Pass
D34: valid text within limits → Ok | G34: O
A35: Result | B35: Type(N : Normal, A : Abnormal, B : Boundary) | F35: A | G35: N | H35: A | I35: A | J35: A | K35: A | L35: A | M35: A
B36: Passed/Failed | F36: P | G36: P | H36: P | I36: P | J36: P | K36: P | L36: P | M36: P
B37: Executed Date | F37: 46240 | G37: 46240 | H37: 46240 | I37: 46240 | J37: 46240 | K37: 46240 | L37: 46240 | M37: 46240
B38: Defect ID

Sheet LanguageMismatch
A1: Code Module | C1: ContentChainGates | F1: Method | L1: LanguageMismatch
A2: Created By | C2: Diepnt | F2: Executed By | P2: Diepnt
A3: Test requirement | C3: <Brief description about requirements which are tested in this function>
A4: Passed | C4: Failed | F4: Untested | L4: N/A/B | O4: Total Test Cases
A5: =COUNTIF(F22:HQ22,"P") -> 5 | C5: =COUNTIF(F22:HQ22,"F") -> 0 | F5: =SUM(O5,-A5,-C5) -> 0 | L5: =COUNTIF(E21:HQ21,"N") -> 3 | M5: =COUNTIF(E21:HQ21,"A") -> 1 | N5: =COUNTIF(E21:HQ21,"B") -> 1 | O5: =COUNTA(E7:HT7) -> 5
F7: UTCID01 | G7: UTCID02 | H7: UTCID03 | I7: UTCID04 | J7: UTCID05
A8: Condition | B8: Input
D9: body = Vietnamese text with diacritics (e.g., "Xin chào các bạn") | F9: O
D10: body = English text (all ASCII) + language="vi" | G10: O
D11: body = short Vietnamese text (< 60 chars) + language="vi" | H11: O
D12: body = Vietnamese text + language="en" | I12: O
D13: body = Vietnamese text + language=null | J13: O
A14: Confirm
B15: Return
D16: Vietnamese with diacritics + language="vi" → Ok | F16: O
D17: English ASCII + language="vi" → WriteLanguageMismatch | G17: O
D18: Short text + language="vi" → Ok (skip check) | H18: O
D19: Vietnamese + language="en" → Ok (not Vietnamese target) | I19: O
D20: Vietnamese + language=null → Ok | J20: O
A21: Result | B21: Type(N : Normal, A : Abnormal, B : Boundary) | F21: N | G21: A | H21: B | I21: N | J21: N
B22: Passed/Failed | F22: P | G22: P | H22: P | I22: P | J22: P
B23: Executed Date | F23: 46240 | G23: 46240 | H23: 46240 | I23: 46240 | J23: 46240
B24: Defect ID

Sheet CopiesBrief
A1: Code Module | C1: ContentChainGates | F1: Method | L1: CopiesBrief
A2: Created By | C2: Diepnt | F2: Executed By | P2: Diepnt
A3: Test requirement | C3: <Brief description about requirements which are tested in this function>
A4: Passed | C4: Failed | F4: Untested | L4: N/A/B | O4: Total Test Cases
A5: =COUNTIF(F26:HQ26,"P") -> 7 | C5: =COUNTIF(F26:HQ26,"F") -> 0 | F5: =SUM(O5,-A5,-C5) -> 0 | L5: =COUNTIF(E25:HQ25,"N") -> 2 | M5: =COUNTIF(E25:HQ25,"A") -> 3 | N5: =COUNTIF(E25:HQ25,"B") -> 2 | O5: =COUNTA(E7:HT7) -> 7
F7: UTCID01 | G7: UTCID02 | H7: UTCID03 | I7: UTCID04 | J7: UTCID05 | K7: UTCID06 | L7: UTCID07
A8: Condition | B8: Input
D9: body = original text (no overlap with brief) | F9: O
D10: body = text that contains entire brief verbatim | G10: O
D11: body = text with similar but not identical wording | H11: O
D12: brief = "" (empty) | I12: O
D13: brief = short text (< 40 chars) | J13: O
D14: body = text with extra spaces around brief text | K14: O
D15: body = text with case-different brief | L15: O
A16: Confirm
B17: Return
D18: No overlap → Ok | F18: O
D19: Contains entire brief → WriteCopiesBrief | G19: O
D20: Similar but not identical → Ok | H20: O
D21: Empty brief → Ok (skip check) | I21: O
D22: Short brief → Ok (skip check) | J22: O
D23: Extra spaces (CollapseWhitespace normalizes) → WriteCopiesBrief | K23: O
D24: Case-different (OrdinalIgnoreCase) → WriteCopiesBrief | L24: O
A25: Result | B25: Type(N : Normal, A : Abnormal, B : Boundary) | F25: N | G25: A | H25: N | I25: B | J25: B | K25: A | L25: A
B26: Passed/Failed | F26: P | G26: P | H26: P | I26: P | J26: P | K26: P | L26: P
B27: Executed Date | F27: 46240 | G27: 46240 | H27: 46240 | I27: 46240 | J27: 46240 | K27: 46240 | L27: 46240
B28: Defect ID

Sheet SelectHook
A1: Code Module | C1: ContentChainGates | F1: Method | L1: SelectHook
A2: Created By | C2: Diepnt | F2: Executed By | Q2: Diepnt
A3: Test requirement | C3: <Brief description about requirements which are tested in this function>
A4: Passed | C4: Failed | F4: Untested | L4: N/A/B | P4: Total Test Cases
A5: =COUNTIF(F28:HR28,"P") -> 8 | C5: =COUNTIF(F28:HR28,"F") -> 0 | F5: =SUM(P5,-A5,-C5) -> 0 | L5: =COUNTIF(E27:HR27,"N") -> 4 | M5: =COUNTIF(E27:HR27,"A") -> 1 | N5: =COUNTIF(E27:HR27,"A") -> 1 | O5: =COUNTIF(E27:HR27,"B") -> 3 | P5: =COUNTA(E7:HU7) -> 8
F7: UTCID01 | G7: UTCID02 | H7: UTCID03 | I7: UTCID04 | J7: UTCID05 | K7: UTCID06 | L7: UTCID07 | M7: UTCID08
A8: Condition | B8: Input
D9: hooks = null/empty | F9: O
D10: hooks = ["Hook short"] (< 16 chars) | G10: O
D11: hooks = ["This is a well-crafted hook for the campaign"] (16-120 chars) | H11: O
D12: hooks = ["Hook with 100% discount"] + mustInclude = ["100%"] | I12: O
D13: hooks = ["Hook with data 42%"] + hasProof = true | J13: O
D14: hooks = ["First hook", "Second hook"] + mustInclude = ["Second"] | K14: O
D15: hooks = ["Same idea", "Same idea duplicate"] (duplicate detection) | L15: O
D16: hooks = ["Hook A", "Hook B"] → best score wins; tie → first index | M16: O
A17: Confirm
B18: Return
D19: null/empty hooks → index=-1, empty scores | F19: O
D20: Short hook → low score | G20: O
D21: Good length → +2 bonus | H21: O
D22: mustInclude match → +1 per match | I22: O
D23: hasProof + digit → +1 | J23: O
D24: mustInclude on 2nd hook → 2nd wins | K24: O
D25: Duplicate hook → -2 penalty | L25: O
D26: Tie → first index selected | M26: O
A27: Result | B27: Type(N : Normal, A : Abnormal, B : Boundary) | F27: A | G27: B | H27: N | I27: N | J27: N | K27: N | L27: B | M27: B
B28: Passed/Failed | F28: P | G28: P | H28: P | I28: P | J28: P | K28: P | L28: P | M28: P
B29: Executed Date | F29: 46240 | G29: 46240 | H29: 46240 | I29: 46240 | J29: 46240 | K29: 46240 | L29: 46240 | M29: 46240
B30: Defect ID

Sheet ParsePlanParseOutlineParsePacka
A1: Code Module | C1: ContentAssetReader | F1: Method | L1: ParsePlan / ParseOutline / ParsePackage
A2: Created By | C2: Diepnt | F2: Executed By | P2: Diepnt
A3: Test requirement | C3: <Brief description about requirements which are tested in this function>
A4: Passed | C4: Failed | F4: Untested | L4: N/A/B | O4: Total Test Cases
A5: =COUNTIF(F50:HS50,"P") -> 18 | C5: =COUNTIF(F50:HS50,"F") -> 0 | F5: =SUM(O5,-A5,-C5) -> 0 | L5: =COUNTIF(E49:HS49,"N") -> 4 | M5: =COUNTIF(E49:HS49,"A") -> 11 | N5: =COUNTIF(E49:HS49,"B") -> 3 | O5: =COUNTA(E7:HV7) -> 18
F7: UTCID01 | G7: UTCID02 | H7: UTCID03 | I7: UTCID04 | J7: UTCID05 | K7: UTCID06 | L7: UTCID07 | M7: UTCID08 | N7: UTCID09 | O7: UTCID10 | P7: UTCID11 | Q7: UTCID12 | R7: UTCID13 | S7: UTCID14 | T7: UTCID15 | U7: UTCID16 | V7: UTCID17 | W7: UTCID18
A8: Condition | B8: ParsePlan Input
D9: rawText = null/empty | F9: O
D10: rawText = "not json" | G10: O
D11: rawText = valid JSON but missing keyMessage | H11: O
D12: rawText = valid JSON, invalid objective (not in allow list) | I12: O
D13: rawText = valid JSON, all fields valid | J13: O
D14: rawText = "```json\n{valid}\n```" (markdown fence) | J14: O
D15: rawText = valid JSON, mustInclude > 10 items | K15: O
D16: rawText = valid JSON, field > 400 chars | L16: O
D17: rawText = valid JSON, ctaText contains "http://..." | M17: O
B18: ParseOutline Input
D19: rawText = null/empty | N19: O
D20: rawText = valid JSON, hooks = [] | O20: O
D21: rawText = valid JSON, hooks = ["h1", "h2"] | P21: O
D22: rawText = valid JSON, proofPoints with citationId=1, citationCount=3 | Q22: O
D23: rawText = valid JSON, proofPoints with citationId=99 (out of range) | R23: O
B24: ParsePackage Input
D25: rawText = null/empty | S25: O
D26: rawText = valid JSON, caption + hashtags | T26: O
D27: rawText = valid JSON, hashtag = "follow4follow" (banned) | U27: O
D28: `rawText = valid JSON, duplicate hashtags → deduped** | V28: O
D29: `rawText = valid JSON, caption + hashtags > captionMax** | W29: O
A30: Confirm | B30: Fail
D31: null/empty → EmptyOutput | F31: O | N31: O | S31: O
D32: invalid JSON → ParseFailed | G32: O
D33: missing keyMessage → FieldMissing | H33: O
D34: invalid objective → EnumInvalid | I34: O
D35: mustInclude > 10 → TooManyItems | K35: O
D36: field > 400 chars → FieldTooLong | L36: O
D37: URL in ctaText → ContainsUrl | M37: O
D38: empty hooks → NoHooks | O38: O
D39: caption + hashtags > captionMax → CaptionTooLong | W39: O
B40: Pass
D41: valid plan JSON → Ok(plan) | J41: O
...

Sheet RunAsync
A1: Code Module | C1: ContentChain | F1: Method | L1: RunAsync
A2: Created By | C2: Diepnt | F2: Executed By | P2: Diepnt
A3: Test requirement | C3: <Brief description about requirements which are tested in this function>
A4: Passed | C4: Failed | F4: Untested | L4: N/A/B | O4: Total Test Cases
A5: =COUNTIF(F35:HQ35,"P") -> 7 | C5: =COUNTIF(F35:HQ35,"F") -> 0 | F5: =SUM(O5,-A5,-C5) -> 0 | L5: =COUNTIF(E34:HQ34,"N") -> 1 | M5: =COUNTIF(E34:HQ34,"A") -> 5 | N5: =COUNTIF(E34:HQ34,"B") -> 1 | O5: =COUNTA(E7:HT7) -> 7
F7: UTCID01 | G7: UTCID02 | H7: UTCID03 | I7: UTCID04 | J7: UTCID05 | K7: UTCID06 | L7: UTCID07
A8: Condition | B8: Input
D9: context = valid ContentChainContext with all fields | F9: O
D10: context = null | G10: O
D11: CancellationToken = default | F11: O | H11: O | I11: O | J11: O | K11: O
D12: CancellationToken = already cancelled | L12: O
B13: Steps
D14: 4 steps (Plan, Outline, Write, Package) all gate pass | F14: O
D15: Step 2 (Outline) gate fails, repair succeeds | H15: O
D16: Step 3 (Write) gate fails, repair also fails | I16: O
D17: Step 1 (Plan) LLM throws exception | J17: O
D18: Step 4 (Package) timeout | K18: O
A19: Confirm
B20: Return Success
D21: All steps pass → Succeeded=true, Body non-empty | F21: O
D22: Plan + Outline saved in outcome for repurpose | F22: O
D23: Traces contain all 4 step entries | F23: O
D24: okens/Cost aggregated across all steps | F24: O
B25: Return Fallback
D26: Gate fail after repair → Succeeded=false, FallbackReason="stepId:errorCode" | I26: O
D27: LLM exception → Succeeded=false, FallbackReason="stepId:step_error" | J27: O
D28: Timeout → Succeeded=false, FallbackReason="stepId:step_timeout" | K28: O
B29: Partial success
D30: Gate fail + repair succeed → advances, continues chain | H30: O
B31: Exception
D32: null context → ArgumentNullException | G32: O
D33: Caller cancellation → OperationCanceledException propagates | L33: O
A34: Result | B34: Type(N : Normal, A : Abnormal, B : Boundary) | F34: N | G34: A | H34: B | I34: A | J34: A | K34: A | L34: A
B35: Passed/Failed | F35: P | G35: P | H35: P | I35: P | J35: P | K35: P | L35: P
B36: Executed Date | F36: 46240 | G36: 46240 | H36: 46240 | I36: 46240 | J36: 46240 | K36: 46240 | L36: 46240
B37: Defect ID

Sheet ResumeFromWriteAsync
A1: Code Module | C1: ContentChain | F1: Method | L1: ResumeFromWriteAsync
A2: Created By | C2: Diepnt | F2: Executed By | P2: Diepnt
A3: Test requirement | C3: <Brief description about requirements which are tested in this function>
A4: Passed | C4: Failed | F4: Untested | L4: N/A/B | O4: Total Test Cases
A5: =COUNTIF(F25:HQ25,"P") -> 4 | C5: =COUNTIF(F25:HQ25,"F") -> 0 | F5: =SUM(O5,-A5,-C5) -> 0 | L5: =COUNTIF(E24:HQ24,"N") -> 1 | M5: =COUNTIF(E24:HQ24,"A") -> 2 | N5: =COUNTIF(E24:HQ24,"B") -> 1 | O5: =COUNTA(E7:HT7) -> 4
F7: UTCID01 | G7: UTCID02 | H7: UTCID03 | I7: UTCID04
