Workbook

Sheet Cover
B1: TEST REPORT DOCUMENT
A3: Project code | B3: ClawBot AI-Driven Marketing and Sales Automation System | E3: Creator | F3: Dev Team
A4: Project Code | B4: CB | E4: Issue Date | F4: 46242
A5: Document Code | B5: CB_Integration Test_v1.0 | E5: Version | F5: v1.0
A7: Record of change
A8: Effective Date | B8: Version | C8: Change Item | D8: A,D,M | E8: Change description | F8: Reference
A9: 2026-08-08 | B9: v1.0 | C9: Initial integration test document with detailed UI scenarios | D9: A

Sheet Test Cases
B1: TEST CASE LIST
B2: Project code | D2: CB
B4: Test Environment Setup Description | D4: 1. Frontend: React + Vite (localhost:15876) 2. API Backend: .NET 8 (localhost:15874) 3. AgentService gRPC (localhost:15875) 4. Gateway: .NET 8 Ocelot (localhost:15873) 5. SQL Server 2022 (Docker :1433) 6. Redis 7 (Docker :6379) 7. Qdrant (Docker :6333) 8. MinIO (Docker :9001) 9. RabbitMQ (Docker :15672) 10. Dev account: admin@clawbot.local / Admin@12345
B5: No | C5: Function code | D5: Sheet code | E5: Description | F5: Pre-Condition
B6: 1 | C6: Login & Authentication | D6: Login & Authentication | E6: JWT login, refresh, 2FA, RBAC, account lockout, password reset, profile management
B7: 2 | C7: Omnichannel Inbox | D7: Omnichannel Inbox | E7: Webhook ingest, conversation list/filter, assign, resolve, escalate, AI draft, outbound messages
B8: 3 | C8: Knowledge Base | D8: Knowledge Base | E8: Module CRUD, version deploy/rollback, accuracy test, upload, suggestions, auto-classify
B9: 4 | C9: AI Agent Management | D9: AI Agent Management | E9: Agent enable/disable, settings, sandbox test, traces, tools catalog, orchestration
B10: 5 | C10: Sale Assist | D10: Sale Assist | E10: AI draft generation, edit/reject draft, conversation summary, quick reply CRUD, daily summary, upsell
B11: 6 | C11: Lead & CRM | D11: Lead & CRM | E11: Lead list/filter, create, assign, stage update, activities, revenue, forecast, CSV import/export
B12: 7 | C12: Content Management | D12: Content Management | E12: Brief CRUD, trend scan, item generate/approve/reject, schedule, calendar, repurpose, hooks
B13: 8 | C13: Document Generation | D13: Document Generation | E13: Template CRUD, PDF generate, kit generate, download, open tracking, MinIO storage
B14: 9 | C14: Analytics | D14: Analytics | E14: Omnichannel KPI, funnel, agent performance, cost, anomaly, forecast, export
B15: 10 | C15: Admin & Security | D15: Admin & Security | E15: User CRUD, RBAC roles/permissions, API keys, integrations, audit logs, notifications, tenant orchestration

Sheet Test Statistics
B1: TEST STATISTICS
B2: Project code | C2: ClawBot AI-Driven Marketing and Sales Automation System
B3: Project Code | C3: CB
B4: Document Code | C4: CB_Test Report_v1.0 | E4: Issue Date | H4: 46242
B5: Notes | C5: Release 1 includes 10 modules (Ads Automation excluded)
B6: No | C6: Module code | D6: Passed | E6: Failed | F6: Pending | G6: N/A | H6: Number of test cases
B7: 1 | C7: ='Login & Authentication'!B6 | D7: ='Login & Authentication'!C6 | E7: ='Login & Authentication'!D6 | F7: ='Login & Authentication'!E6 | G7: ='Login & Authentication'!B4
B8: 2 | C8: ='Omnichannel Inbox'!B6 | D8: ='Omnichannel Inbox'!C6 | E8: ='Omnichannel Inbox'!D6 | F8: ='Omnichannel Inbox'!E6 | G8: ='Omnichannel Inbox'!B4
B9: 3 | C9: ='Knowledge Base'!B6 | D9: ='Knowledge Base'!C6 | E9: ='Knowledge Base'!D6 | F9: ='Knowledge Base'!E6 | G9: ='Knowledge Base'!B4
B10: 4 | C10: ='AI Agent Management'!B6 | D10: ='AI Agent Management'!C6 | E10: ='AI Agent Management'!D6 | F10: ='AI Agent Management'!E6 | G10: ='AI Agent Management'!B4
B11: 5 | C11: ='Sale Assist'!B6 | D11: ='Sale Assist'!C6 | E11: ='Sale Assist'!D6 | F11: ='Sale Assist'!E6 | G11: ='Sale Assist'!B4
B12: 6 | C12: ='Lead & CRM'!B6 | D12: ='Lead & CRM'!C6 | E12: ='Lead & CRM'!D6 | F12: ='Lead & CRM'!E6 | G12: ='Lead & CRM'!B4
B13: 7 | C13: ='Content Management'!B6 | D13: ='Content Management'!C6 | E13: ='Content Management'!D6 | F13: ='Content Management'!E6 | G13: ='Content Management'!B4
B14: 8 | C14: ='Document Generation'!B6 | D14: ='Document Generation'!C6 | E14: ='Document Generation'!D6 | F14: ='Document Generation'!E6 | G14: ='Document Generation'!B4
B15: 9 | C15: ='Analytics'!B6 | D15: ='Analytics'!C6 | E15: ='Analytics'!D6 | F15: ='Analytics'!E6 | G15: ='Analytics'!B4
B16: 10 | C16: ='Admin & Security'!B6 | D16: ='Admin & Security'!C6 | E16: ='Admin & Security'!D6 | F16: ='Admin & Security'!E6 | G16: ='Admin & Security'!B4

Sheet Login & Authentication
A2: Feature | B2: Login & Authentication
A3: Test requirement | B3: JWT authentication, refresh tokens, 2FA TOTP, RBAC permissions, account lockout, password reset, profile management
A4: Number of TCs | B4: =COUNTA(A12:A1014)
A5: Testing Round | B5: Passed | C5: Failed | D5: Pending | E5: N/A
A6: Round 1 | B6: =COUNTIF($F12:$F1014,B5) | C6: =COUNTIF($F12:$F1014,C5) | D6: =COUNTIF($F12:$F1014,D5) | E6: =COUNTIF($F12:$F1014,E5)
A7: Round 2 | B7: =COUNTIF($I12:$I1014,B5) | C7: =COUNTIF($I12:$I1014,C5) | D7: =COUNTIF($I12:$I1014,D5) | E7: =COUNTIF($I12:$I1014,E5)
A8: Round 3 | B8: =COUNTIF($L12:$L1014,B5) | C8: =COUNTIF($L12:$L1014,C5) | D8: =COUNTIF($L12:$L1014,D5) | E8: =COUNTIF($L12:$L1014,E5)
A10: Test Case ID | B10: Test Case Description | C10: Test Case Procedure | D10: Expected Results | E10: Pre-conditions | F10: Round 1 | G10: Test date | H10: Tester | I10: Round 2 | J10: Test date | K10: Tester | L10: Round 3 | M10: Test date | N10: Tester | O10: Note
A11: Login
A12: TC-LOG-001 | B12: Login with correct email and password | C12: Navigate to http://localhost:15876/login. Enter "admin@clawbot.local" in the email field. Enter "Admin@12345" in the password field. Click the "Dang nhap" button. | D12: The system authenticates the user successfully and redirects to the dashboard page at http://localhost:15876/. The sidebar menu displays items according to the admin role permissions. The user profile icon appears in the top-right corner. | E12: Can connect to server. User admin@clawbot.local exists in database with status active.
A13: TC-LOG-002 | B13: Login with incorrect password | C13: Navigate to http://localhost:15876/login. Enter "admin@clawbot.local" in the email field. Enter "WrongPassword123" in the password field. Click the "Dang nhap" button. | D13: The system displays an error message below the password field indicating the credentials are invalid. The user remains on the login page and does not proceed to the dashboard. | E13: Can connect to server. User admin@clawbot.local exists in database.
A14: TC-LOG-003 | B14: Login with non-existent email | C14: Navigate to http://localhost:15876/login. Enter "nonexistent@test.com" in the email field. Enter "AnyPassword123" in the password field. Click the "Dang nhap" button. | D14: The system displays an error message indicating the email or password is incorrect. The user remains on the login page. | E14: Can connect to server.
A15: TC-LOG-004 | B15: Login with empty email field | C15: Navigate to http://localhost:15876/login. Leave the email field empty. Enter "Admin@12345" in the password field. Click the "Dang nhap" button. | D15: The system displays a validation error message next to the email field asking the user to enter their email. Login does not proceed. | E15: Can connect to server.
A16: TC-LOG-005 | B16: Login with empty password field | C16: Navigate to http://localhost:15876/login. Enter "admin@clawbot.local" in the email field. Leave the password field empty. Click the "Dang nhap" button. | D16: The system displays a validation error message next to the password field asking the user to enter their password. Login does not proceed. | E16: Can connect to server.
A17: TC-LOG-006 | B17: Login with both fields empty | C17: Navigate to http://localhost:15876/login. Leave both email and password fields empty. Click the "Dang nhap" button. | D17: The system displays validation error messages for both fields. Login does not proceed. | E17: Can connect to server.
A18: TC-LOG-007 | B18: Account lockout after 5 failed attempts | C18: Navigate to http://localhost:15876/login. Enter "admin@clawbot.local" in the email field. Enter wrong password 5 times consecutively, clicking "Dang nhap" each time. | D18: After the 5th failed attempt, the system locks the account and displays a message indicating the account has been locked for 30 minutes. Subsequent login attempts with correct credentials are also rejected. | E18: Can connect to server. Account lockout policy is enabled.
A19: TC-LOG-008 | B19: Token refresh maintains session | C19: Login successfully with valid credentials. Wait for the access token to approach expiration (15 minutes). Perform any action that requires authentication (e.g., navigate to /leads). | D19: The system automatically refreshes the token using the refresh token. The user session continues without interruption. No redirect to login page occurs. | E19: Can connect to server. Refresh token cookie is set.
A20: TC-LOG-009 | B20: Logout invalidates session | C20: Login successfully with valid credentials. Click on the user profile icon in the top-right corner. Select "Dang xuat" from the dropdown menu. After logout, attempt to access http://localhost:15876/leads directly via browser URL. | D20: After clicking logout, the system clears the session and redirects to the login page. Attempting to access a protected page via URL redirects back to the login page. | E20: Can connect to server. User is logged in.
A21: Password Reset
A22: TC-LOG-010 | B22: Request password reset with valid email | C22: Navigate to http://localhost:15876/login. Click the "Quen mat khau" link. Enter "admin@clawbot.local" in the email field. Click the "Gui ma xac nhan" button. | D22: The system sends a password reset OTP to the registered email. The UI transitions to the OTP verification step with 6 digit input fields. | E22: Can connect to server. Email service is configured.
A23: TC-LOG-011 | B23: Request password reset with non-existent email | C23: Navigate to the forgot password page. Enter "nonexistent@test.com" in the email field. Click the "Gui ma xac nhan" button. | D23: For security, the system displays a generic message that an email has been sent (does not reveal whether the email exists). The UI transitions to the OTP step. | E23: Can connect to server.
A24: TC-LOG-012 | B24: Confirm password reset with valid OTP | C24: Request a password reset for admin@clawbot.local. Retrieve the OTP from the email or system logs. Enter the 6-digit OTP in the verification fields. Enter a new password "NewPass@123" in the new password field. Click the "Dat lai mat khau" button. | D24: The system validates the OTP and updates the password. A success message is displayed. The user can now login with the new password. | E24: Can connect to server. Reset OTP has been generated.
A25: TC-LOG-013 | B25: Confirm password reset with invalid OTP | C25: Request a password reset for admin@clawbot.local. Enter an incorrect 6-digit OTP (e.g., "000000"). Click the "Xac nhan" button. | D25: The system displays an error message indicating the OTP is incorrect. The password is not changed. | E25: Can connect to server. Reset OTP has been generated.
A26: 2FA Management
A27: TC-LOG-014 | B27: Enable 2FA on account | C27: Login successfully. Navigate to the profile page by clicking the profile icon. Click the "Xac thuc hai lop" toggle switch to enable. In the dialog, copy the displayed secret key. Enter the 6-digit TOTP code from an authenticator app in the "Ma xac nhan" field. Click the "Xac nhan" button. | D27: The system verifies the TOTP code and activates 2FA. The toggle switch shows as enabled. The secret key is displayed for backup. | E27: Can connect to server. Authenticator app is configured with the secret.
A28: TC-LOG-015 | B28: Verify 2FA with correct code | C28: Enable 2FA on the account. Logout. Login with correct email and password. On the 2FA verification page, enter the correct 6-digit TOTP code. Click the "Xac nhan" button. | D28: The system verifies the TOTP code and grants access. The user is redirected to the dashboard. | E28: Can connect to server. 2FA is enabled on the account.
A29: TC-LOG-016 | B29: Verify 2FA with incorrect code | C29: Enable 2FA on the account. Logout. Login with correct email and password. Enter an incorrect 6-digit TOTP code. Click the "Xac nhan" button. | D29: The system displays an error message indicating the verification code is incorrect. Access is denied. | E29: Can connect to server. 2FA is enabled on the account.
A30: TC-LOG-017 | B30: Disable 2FA | C30: Login with 2FA enabled. Navigate to the profile page. Click the "Xac thuc hai lop" toggle switch to disable. Confirm the action in the confirmation dialog. | D30: The system disables 2FA for the account. The toggle switch shows as disabled. Subsequent logins no longer require TOTP verification. | E30: Can connect to server. 2FA is currently enabled.
A31: Profile & Password
A32: TC-LOG-018 | B32: View user profile information | C32: Login successfully. Click on the user profile icon in the top-right corner. Navigate to the profile page. | D32: The profile page displays three tabs: "Thong tin co ban", "Phan quyen truc thuoc", and "Nhat ky bao mat". The basic info tab shows the user name, email, and tenant information. | E32: Can connect to server. User is logged in.
A33: TC-LOG-019 | B33: Change password with correct current password | C33: Login successfully. Navigate to the profile page. Click the "Doi mat khau" button. Enter the current password in the "Mat khau hien tai" field. Enter a new password in the "Mat khau moi" field. Enter the same new password in the "Xac nhan mat khau moi" field. Click the "Luu" button. | D33: The system validates the current password and updates to the new password. A success message is displayed. The dialog closes. The user can login with the new password. | E33: Can connect to server. User is logged in.
A34: TC-LOG-020 | B34: Change password with incorrect current password | C34: Login successfully. Navigate to the profile page. Click the "Doi mat khau" button. Enter an incorrect password in the "Mat khau hien tai" field. Enter a new password in the "Mat khau moi" field. Enter the same new password in the "Xac nhan mat khau moi" field. Click the "Luu" button. | D34: The system displays an error message next to the current password field indicating the current password is incorrect. The password is not changed. | E34: Can connect to server. User is logged in.
A35: TC-LOG-021 | B35: Change password with mismatched confirmation | C35: Login successfully. Navigate to the profile page. Click the "Doi mat khau" button. Enter the correct current password. Enter "NewPass@123" in the new password field. Enter "DifferentPass@123" in the confirmation field. Click the "Luu" button. | D35: The system displays an error message indicating the new password and confirmation do not match. The password is not changed. | E35: Can connect to server. User is logged in.
A36: TC-LOG-022 | B36: Access protected page without authentication | C36: Clear all cookies and session data. Navigate directly to http://localhost:15876/leads via browser URL. | D36: The system detects no valid authentication token and redirects the user to the login page at http://localhost:15876/login. | E36: Can connect to server. No user is logged in.
A37: TC-LOG-023 | B37: RBAC - user without permission cannot access restricted endpoint | C37: Login with a user account that does not have the "kb:write" permission. Navigate to the Knowledge Base page. Attempt to create a new KB module by clicking "Tao module" and filling in the form. | D37: The system either hides the create button or displays a 403 Forbidden error when attempting the action. The user cannot create KB modules. | E37: Can connect to server. User lacks kb:write permission.

Sheet Omnichannel Inbox
A2: Feature | B2: Omnichannel Inbox
A3: Test requirement | B3: Webhook ingest, conversation list/filter, assign, resolve, escalate, AI draft, outbound messages, realtime updates
A4: Number of TCs | B4: =COUNTA(A12:A1014)
A5: Testing Round | B5: Passed | C5: Failed | D5: Pending | E5: N/A
A6: Round 1 | B6: =COUNTIF($F12:$F1014,B5) | C6: =COUNTIF($F12:$F1014,C5) | D6: =COUNTIF($F12:$F1014,D5) | E6: =COUNTIF($F12:$F1014,E5)
A7: Round 2 | B7: =COUNTIF($I12:$I1014,B5) | C7: =COUNTIF($I12:$I1014,C5) | D7: =COUNTIF($I12:$I1014,D5) | E7: =COUNTIF($I12:$I1014,E5)
A8: Round 3 | B8: =COUNTIF($L12:$L1014,B5) | C8: =COUNTIF($L12:$L1014,C5) | D8: =COUNTIF($L12:$L1014,D5) | E8: =COUNTIF($L12:$L1014,E5)
A10: Test Case ID | B10: Test Case Description | C10: Test Case Procedure | D10: Expected Results | E10: Pre-conditions | F10: Round 1 | G10: Test date | H10: Tester | I10: Round 2 | J10: Test date | K10: Tester | L10: Round 3 | M10: Test date | N10: Tester | O10: Note
A11: Webhook Ingest
A12: TC-OMN-001 | B12: Pancake webhook with valid HMAC signature | C12: Configure Pancake webhook with the correct HMAC secret in the System admin page. Send a test webhook payload from Pancake or replay using the deploy/pancake-webhook-replay.ps1 script. Observe the API response and inbox. | D12: The API returns 202 Accepted. A new conversation appears in the inbox with the message content from the webhook. The contact is created or merged if the external_id already exists. | E12: Can connect to server. Pancake integration is configured with valid HMAC secret.
A13: TC-OMN-002 | B13: Pancake webhook with invalid HMAC signature | C13: Configure Pancake webhook with an incorrect HMAC secret. Send a test webhook payload. Observe the API response. | D13: The API returns 401 Unauthorized. The webhook payload is not processed. An attempt is recorded in the audit logs. | E13: Can connect to server. Pancake integration is configured.
A14: TC-OMN-003 | B14: Webhook creates new contact and conversation | C14: Ensure no existing contact with the webhook external_id. Send a webhook payload with a new message from an unknown contact. Navigate to the inbox page. | D14: A new contact is created in the database. A new conversation appears in the inbox list with status "open". The message content matches the webhook payload. | E14: Can connect to server. Pancake integration is active.
A15: TC-OMN-004 | B15: Webhook merges into existing contact | C15: Ensure a contact with the webhook external_id already exists. Send a webhook payload with a message from that contact. Navigate to the inbox and check the conversation. | D15: The new conversation is merged into the existing contact. No duplicate contact is created. The conversation history shows both old and new messages. | E15: Can connect to server. Contact with matching external_id exists.
A16: Conversation List & Filters
A17: TC-OMN-005 | B17: List all conversations | C17: Navigate to http://localhost:15876/conversations. Observe the conversation list. | D17: The conversation list displays all conversations with columns for contact name, platform icon (FB/Z/W), last message preview, assigned sale, status badge, and timestamp. Conversations are sorted by most recent message. | E17: Can connect to server. Conversations exist in the database.
A18: TC-OMN-006 | B18: Filter conversations by "Tat ca" | C18: Navigate to the conversations page. Click the "Tat ca" filter chip at the top of the list. | D18: All conversations are displayed regardless of status. The "Tat ca" chip is highlighted as active. | E18: Can connect to server. Multiple conversations with different statuses exist.
A19: TC-OMN-007 | B19: Filter conversations by "AI dang chat" | C19: Navigate to the conversations page. Click the "AI dang chat" filter chip. | D19: Only conversations with AI auto-reply enabled are displayed. Each shows a "smart_toy" icon indicating AI is active. | E19: Can connect to server. At least one conversation has AI auto-reply enabled.
A20: TC-OMN-008 | B20: Filter conversations by "Can ho tro" | C20: Navigate to the conversations page. Click the "Can ho tro" filter chip. | D20: Only escalated conversations are displayed. Each shows a warning icon. | E20: Can connect to server. At least one conversation is escalated.
A21: TC-OMN-009 | B21: Filter conversations by "Cua toi" | C21: Login as a sale user (not admin). Navigate to the conversations page. Click the "Cua toi" filter chip. | D21: Only conversations assigned to the current logged-in sale user are displayed. | E21: Can connect to server. Sale user has assigned conversations.
A22: TC-OMN-010 | B22: Filter conversations by "Da xu ly" | C22: Navigate to the conversations page. Click the "Da xu ly" filter chip. | D22: Only resolved conversations are displayed. Each shows a checkmark icon. | E22: Can connect to server. At least one conversation is resolved.
A23: TC-OMN-011 | B23: Search conversations by keyword | C23: Navigate to the conversations page. Type a keyword (e.g., a contact name or message content) in the search box at the top. Observe the filtered results. | D23: The conversation list updates to show only conversations matching the search keyword. The search is performed across contact names and message content. | E23: Can connect to server. Conversations with searchable content exist.
A24: Conversation Detail & Actions
A25: TC-OMN-012 | B25: Open conversation detail | C25: Navigate to the conversations page. Click on a conversation in the list. | D25: The conversation detail panel opens on the right side, showing the message thread with timestamps, sender names, and message content. The contact information panel shows the lead score, assigned sale, and conversation status. | E25: Can connect to server. Conversation has messages.
A26: TC-OMN-013 | B26: Assign conversation to a sale | C26: Open a conversation that is not yet assigned. Click the "Phan cong" button or dropdown. Select a sale user from the list. Confirm the assignment. | D26: The conversation is assigned to the selected sale. The assigned sale name appears in the conversation header. A notification is sent to the assigned sale via SignalR. | E26: Can connect to server. At least one sale user exists.
A27: TC-OMN-014 | B27: Resolve conversation | C27: Open an open conversation. Click the "Xu ly" button. Confirm the action. | D27: The conversation status changes to "resolved". The status badge updates. The conversation moves to the "Da xu ly" filter group. | E27: Can connect to server. Conversation status is open.
A28: TC-OMN-015 | B28: Escalate conversation | C28: Open a conversation. Click the "Chuyen cap" button. Confirm the escalation. | D28: The conversation status changes to "escalated". A warning icon appears next to the conversation. The conversation appears in the "Can ho tro" filter group. | E28: Can connect to server. Conversation exists.
A29: AI Auto-Reply
A30: TC-OMN-016 | B30: Enable AI auto-reply on conversation | C30: Open a conversation. Click the "Bat AI tra loi" button in the conversation header. Confirm the action. | D30: AI auto-reply is enabled for the conversation. The "AI dang chat" indicator appears. When a new inbound message arrives, the system generates an AI draft within 3 seconds. | E30: Can connect to server. LLM provider is configured.
A31: TC-OMN-017 | B31: Regenerate AI reply | C31: Open a conversation with AI auto-reply enabled. Click the "Tao lai phan hoi" button. | D31: The system generates a new AI draft reply. The draft appears in the Sale Assist panel for review. | E31: Can connect to server. AI auto-reply is enabled. LLM provider is configured.
A32: TC-OMN-018 | B32: Approve AI draft reply | C32: Open a conversation with an AI-generated draft. Review the draft in the Sale Assist panel. Click the "Gui" button to approve and send. | D32: The approved draft is sent as an outbound message to the customer. The message appears in the conversation thread. The draft status changes to sent. | E32: Can connect to server. AI draft exists.
A33: TC-OMN-019 | B33: Reject AI draft reply | C33: Open a conversation with an AI-generated draft. Click the "Tu choi" button to reject the draft. | D33: The draft is rejected and removed from the pending drafts. The conversation remains open for manual reply. | E33: Can connect to server. AI draft exists.
A34: Outbound Messages
A35: TC-OMN-020 | B35: Send outbound message manually | C35: Open a conversation. Type a message in the message input field at the bottom of the conversation thread. Click the send button. | D35: The message is sent to the customer via the configured channel (Pancake). The message appears in the conversation thread with a "sent" status. The customer receives the message on their platform. | E35: Can connect to server. Channel is configured. Pancake access token is valid.
A36: TC-OMN-021 | B36: Retry failed outbound message | C36: Identify a conversation with a failed outbound message (red error indicator). Click the "Thu gui lai" button next to the failed message. | D36: The system retries sending the message. If successful, the message status changes to "sent". If it fails again, an error message is displayed. | E36: Can connect to server. A failed message exists.
A37: Realtime Updates
A38: TC-OMN-022 | B38: New inbound message appears in real-time | C38: Open the conversations page in two browser windows. Send a webhook payload to create a new inbound message. Observe both browser windows. | D38: The new message appears in both browser windows in real-time via SignalR without requiring a page refresh. The conversation list updates to show the new message at the top. | E38: Can connect to server. SignalR hub is running.
A39: TC-OMN-023 | B39: Daily inbox summary | C39: Navigate to the conversations page. Click the "Tong hop ngay" button or link. | D39: A summary panel shows today's statistics: total conversations, new conversations, resolved conversations, average response time, and AI auto-reply count. | E39: Can connect to server. Conversation data exists for today.

Sheet Knowledge Base
A2: Feature | B2: Knowledge Base
A3: Test requirement | B3: KB module CRUD, version deploy/rollback, accuracy test, upload, suggestions, auto-classify
A4: Number of TCs | B4: =COUNTA(A12:A1014)
A5: Testing Round | B5: Passed | C5: Failed | D5: Pending | E5: N/A
A6: Round 1 | B6: =COUNTIF($F12:$F1014,B5) | C6: =COUNTIF($F12:$F1014,C5) | D6: =COUNTIF($F12:$F1014,D5) | E6: =COUNTIF($F12:$F1014,E5)
A7: Round 2 | B7: =COUNTIF($I12:$I1014,B5) | C7: =COUNTIF($I12:$I1014,C5) | D7: =COUNTIF($I12:$I1014,D5) | E7: =COUNTIF($I12:$I1014,E5)
A8: Round 3 | B8: =COUNTIF($L12:$L1014,B5) | C8: =COUNTIF($L12:$L1014,C5) | D8: =COUNTIF($L12:$L1014,D5) | E8: =COUNTIF($L12:$L1014,E5)
A10: Test Case ID | B10: Test Case Description | C10: Test Case Procedure | D10: Expected Results | E10: Pre-conditions | F10: Round 1 | G10: Test date | H10: Tester | I10: Round 2 | J10: Test date | K10: Tester | L10: Round 3 | M10: Test date | N10: Tester | O10: Note
A11: Module Management
A12: TC-KNO-001 | B12: Create a new KB module | C12: Navigate to http://localhost:15876/kb. Click the "Tao module" button. Enter "HSK4 Grammar" in the "Ten module" field. Enter "hsk4_grammar" in the "Ma code" field. Enter "Bo cuong truc ngu phap HSK4" in the "Mo ta" field. Click the "Tao" button. | D12: A new module appears in the module list with name "HSK4 Grammar", code "hsk4_grammar", and status "draft". The module count increases by 1. | E12: Can connect to server. User has kb:write permission.
A13: TC-KNO-002 | B13: List all KB modules | C13: Navigate to http://localhost:15876/kb. Observe the module list under the "Modules" tab. | D13: The page displays all KB modules in a table with columns for module name, code, description, latest version, status, and action buttons. A search bar is available at the top. | E13: Can connect to server. At least one KB module exists.
A14: TC-KNO-003 | B14: Search KB modules by name | C14: Navigate to the KB page. Type "HSK" in the search bar. Observe the filtered results. | D14: The module list updates to show only modules whose name or code contains "HSK". Other modules are hidden. | E14: Can connect to server. Modules with matching names exist.
A15: TC-KNO-004 | B15: Update KB module details | C15: Navigate to the KB page. Click on a module to open its detail. Click the "Chinh sua" button. Update the "Mo ta" field with new text. Click "Luu". | D15: The module description is updated. The change is reflected in the module list. | E15: Can connect to server. Module exists. User has kb:write permission.
A16: TC-KNO-005 | B16: Archive KB module | C16: Navigate to the KB page. Click on a module. Click the "Luu tru" button. Confirm the action. | D16: The module status changes to "archived". The module is moved to an archived section or hidden from the default list. No new versions can be created for archived modules. | E16: Can connect to server. Module exists and is not already archived.
A17: Version Management
A18: TC-KNO-006 | B18: Create a new draft version | C18: Navigate to a KB module detail page. Click the "Tao phien ban moi" button. Enter "Version 2.0" in the version name field. Click "Tao". | D18: A new version appears in the version list with status "draft". The version is not yet deployed. | E18: Can connect to server. Module exists and is not archived.
A19: TC-KNO-007 | B19: Upload content to a draft version | C19: Navigate to a module with a draft version. Click the "Tai len noi dung" button or drag-and-drop area. Select a .txt or .md file containing KB content. Wait for the upload to complete. | D19: The content is uploaded to the draft version. A success message is displayed. The version detail shows the uploaded content preview. | E19: Can connect to server. Draft version exists.
A20: TC-KNO-008 | B20: View version detail | C20: Navigate to a module. Click on a specific version in the version list. | D20: The version detail page opens showing the version name, status, created date, content preview, and accuracy score (if tested). Action buttons for deploy/rollback are displayed if applicable. | E20: Can connect to server. Version exists.
A21: TC-KNO-009 | B21: Compare two versions (diff) | C21: Navigate to a module with multiple versions. Click the "So sanh phien ban" button. Select two versions to compare. | D21: A diff view is displayed showing additions (green) and deletions (red) between the two selected versions. | E21: Can connect to server. Module has at least 2 versions.
A22: Deploy & Rollback
A23: TC-KNO-010 | B23: Deploy a version with sufficient accuracy | C23: Navigate to a version with accuracy score >= 0.85. Click the "Trien khai" button. Confirm the deployment. | D23: The version status changes to "deployed". The RAG cache is invalidated for the module. Agents referencing this module pick up the new content within 5 seconds. Previous deployed version status changes to "superseded". | E23: Can connect to server. Version has accuracy >= 0.85. Qdrant is running.
A24: TC-KNO-011 | B24: Deploy blocked due to low accuracy | C24: Navigate to a version with accuracy score < 0.85. Click the "Trien khai" button. | D24: The system displays a warning message indicating the accuracy score is below the 0.85 threshold. Deployment is blocked. The version remains in draft status. | E24: Can connect to server. Version accuracy < 0.85.
A25: TC-KNO-012 | B25: Rollback to previous version | C25: Navigate to a module where the current deployed version is v2.0. Click the "Quay lai" button on the v2.0 version row. Confirm the rollback. | D25: The previous version (v1.0) status changes back to "deployed". The rolled-back version (v2.0) status changes to "superseded". RAG cache is invalidated. Agents pick up the rolled-back content. | E25: Can connect to server. A previously deployed version exists.
A26: TC-KNO-013 | B26: Edit content of a deployed version is blocked | C26: Navigate to a deployed version. Attempt to click "Chinh sua noi dung" or edit the content directly. | D26: The edit button is disabled or hidden for deployed versions. If the API is called directly, it returns 400 Bad Request with message "Edits forbidden on deployed version". | E26: Can connect to server. Version status is "deployed".
A27: Testing
A28: TC-KNO-014 | B28: Add a test case manually | C28: Navigate to a KB module. Click the "Test cases" tab. Click "Them test case". Enter "What is the past tense marker in Chinese?" in the question field. Enter "Le (?)" in the expected answer field. Click "Luu". | D28: The test case is added to the list. The test case count increases by 1. | E28: Can connect to server. Module exists.
A29: TC-KNO-015 | B29: Generate test cases from KB content | C29: Navigate to a KB module with uploaded content. Click the "Sinh test case" button. Wait for the generation to complete. | D29: The system analyzes the KB content and generates multiple test cases (question/answer pairs). The generated test cases appear in the test case list. | E29: Can connect to server. KB has content. LLM provider is configured.
A30: TC-KNO-016 | B30: Run accuracy test | C30: Navigate to a KB module with test cases. Click the "Chay test" button. Wait for the test to complete. | D30: The system runs each test case against the KB using RAG retrieval. An accuracy score is calculated and displayed. Failed test cases are highlighted. | E30: Can connect to server. Test cases exist. Qdrant has embeddings.
A31: TC-KNO-017 | B31: View accuracy dashboard | C31: Navigate to the KB page. Click the "Do chinh xac" link or navigate to /api/kb/accuracy. | D31: The accuracy dashboard shows per-module accuracy scores, trend over time, and detailed results for each test case. | E31: Can connect to server. Tests have been run.
A32: Suggestions & Auto-classify
A33: TC-KNO-018 | B33: View KB suggestions | C33: Navigate to the KB page. Click the "Goi y" tab. | D33: The suggestions panel shows pending suggestions for KB improvements based on conversation analysis. Each suggestion has a status of "pending", "accepted", or "rejected". | E33: Can connect to server. Suggestions exist.
A34: TC-KNO-019 | B34: Auto-classify uploaded document | C34: Navigate to the KB page. Click the "Phan loai tai lieu" button. Upload a document file. | D34: The system analyzes the document and suggests which KB module it belongs to. The user can confirm or change the classification. | E34: Can connect to server. KB modules exist.

Sheet AI Agent Management
A2: Feature | B2: AI Agent Management
A3: Test requirement | B3: Agent enable/disable, settings, sandbox test, traces, tools catalog, orchestration
A4: Number of TCs | B4: =COUNTA(A12:A1014)
A5: Testing Round | B5: Passed | C5: Failed | D5: Pending | E5: N/A
A6: Round 1 | B6: =COUNTIF($F12:$F1014,B5) | C6: =COUNTIF($F12:$F1014,C5) | D6: =COUNTIF($F12:$F1014,D5) | E6: =COUNTIF($F12:$F1014,E5)
A7: Round 2 | B7: =COUNTIF($I12:$I1014,B5) | C7: =COUNTIF($I12:$I1014,C5) | D7: =COUNTIF($I12:$I1014,D5) | E7: =COUNTIF($I12:$I1014,E5)
A8: Round 3 | B8: =COUNTIF($L12:$L1014,B5) | C8: =COUNTIF($L12:$L1014,C5) | D8: =COUNTIF($L12:$L1014,D5) | E8: =COUNTIF($L12:$L1014,E5)
A10: Test Case ID | B10: Test Case Description | C10: Test Case Procedure | D10: Expected Results | E10: Pre-conditions | F10: Round 1 | G10: Test date | H10: Tester | I10: Round 2 | J10: Test date | K10: Tester | L10: Round 3 | M10: Test date | N10: Tester | O10: Note
A11: Agent List & Status
A12: TC-AI -001 | B12: View all agents on dashboard | C12: Navigate to http://localhost:15876 (dashboard). Click on the "Dieu phoi" or "Doi ngu agent" tab. Observe the agent list. | D12: The dashboard displays all 8 agents (Chat, SaleAssist, Lead, Content, Docs, Ads, Report, Research) with their status (running/stopped/error), agent type, and last activity timestamp. | E12: Can connect to server. AgentService is running.
A13: TC-AI -002 | B13: Enable a stopped agent | C13: Navigate to the agent dashboard. Find an agent with status "stopped". Click the "Bat" button for that agent. Confirm the action. | D13: The agent status transitions from "stopped" to "running". A green status indicator appears. The agent begins processing queued tasks. | E13: Can connect to server. AgentService is running. Agent is currently stopped.
A14: TC-AI -003 | B14: Disable a running agent | C14: Navigate to the agent dashboard. Find an agent with status "running". Click the "Tat" button for that agent. Confirm the action. | D14: The agent status transitions from "running" to "stopped". A gray status indicator appears. The agent stops processing new tasks. | E14: Can connect to server. Agent is currently running.
A15: TC-AI -004 | B15: Agent crash triggers error status | C15: Simulate 3 consecutive agent failures within 5 minutes (e.g., by providing invalid LLM config). Observe the agent status. | D15: After the 3rd crash, the agent status changes to "error". An alert is emitted. The agent does not auto-restart until manually enabled. | E15: Can connect to server. Agent is running. Failure scenario is reproducible.
A16: Agent Configuration
A17: TC-AI -005 | B17: View agent settings | C17: Navigate to the agent dashboard. Click on an agent to open its configuration panel. Click the "Cai dat" tab. | D17: The settings panel displays the agent's current configuration: model provider, model name, temperature, max tokens, system prompt, and available tools. | E17: Can connect to server. Agent exists.
A18: TC-AI -006 | B18: Update agent settings | C18: Navigate to an agent's settings. Change the "Temperature" value to 0.7. Click "Luu". | D18: The settings are saved. The agent uses the updated temperature for subsequent requests. A success message is displayed. | E18: Can connect to server. Agent exists.
A19: TC-AI -007 | B19: Test agent in sandbox | C19: Navigate to the agent dashboard. Click on an agent. Click the "Sandbox" button. Enter "Xin chao, ban co the giup toi gi?" in the test prompt field. Click "Chay". | D19: The agent processes the test prompt and returns a response in the sandbox panel. The response is displayed with latency and token usage metrics. | E19: Can connect to server. Agent is running. LLM provider is configured.
A20: Traces & Monitoring
A21: TC-AI -008 | B21: View agent traces | C21: Navigate to the agent dashboard. Click on an agent. Click the "Nhat ky" tab. | D21: The traces list shows recent agent executions with timestamp, input summary, output summary, status (success/error), latency, and token usage. | E21: Can connect to server. Agent has executed at least one task.
A22: TC-AI -009 | B22: View agent cost breakdown | C22: Navigate to the agent dashboard. Click the "Nhat ky & chi phi" tab. | D22: The cost panel shows token usage and estimated cost per agent, per model, and over time. A chart displays cost trends. | E22: Can connect to server. Agent has token usage data.
A23: Tools & Orchestration
A24: TC-AI -010 | B24: View available tools catalog | C24: Navigate to the agent dashboard. Click the "Cong cu" tab or tools section. | D24: The tools catalog lists all available tools that agents can use (e.g., web search, KB lookup, content generate). Each tool shows its name, description, and which agents can use it. | E24: Can connect to server.
A25: TC-AI -011 | B25: View orchestration schedule | C25: Navigate to the orchestration panel. Click the "Dieu phoi" tab. | D25: The orchestration panel displays the list of scheduled agent tasks, their execution frequency (daily/weekly/monthly), last run time, and next scheduled run. | E25: Can connect to server. Orchestration is configured.
A26: TC-AI -012 | B26: Trigger a scheduled orchestration run | C26: Navigate to the orchestration panel. Click the "Chay ngay" button for a scheduled task. Observe the run status. | D26: The task status changes to "running". After completion, a new run entry appears in the run history with status "completed" or "failed". Trace and A2A messages are recorded. | E26: Can connect to server. Orchestration schedule exists.

Sheet Sale Assist
A2: Feature | B2: Sale Assist
A3: Test requirement | B3: AI draft generation, edit/reject draft, conversation summary, quick reply CRUD, daily summary, upsell
A4: Number of TCs | B4: =COUNTA(A12:A1014)
A5: Testing Round | B5: Passed | C5: Failed | D5: Pending | E5: N/A
A6: Round 1 | B6: =COUNTIF($F12:$F1014,B5) | C6: =COUNTIF($F12:$F1014,C5) | D6: =COUNTIF($F12:$F1014,D5) | E6: =COUNTIF($F12:$F1014,E5)
A7: Round 2 | B7: =COUNTIF($I12:$I1014,B5) | C7: =COUNTIF($I12:$I1014,C5) | D7: =COUNTIF($I12:$I1014,D5) | E7: =COUNTIF($I12:$I1014,E5)
A8: Round 3 | B8: =COUNTIF($L12:$L1014,B5) | C8: =COUNTIF($L12:$L1014,C5) | D8: =COUNTIF($L12:$L1014,D5) | E8: =COUNTIF($L12:$L1014,E5)
A10: Test Case ID | B10: Test Case Description | C10: Test Case Procedure | D10: Expected Results | E10: Pre-conditions | F10: Round 1 | G10: Test date | H10: Tester | I10: Round 2 | J10: Test date | K10: Tester | L10: Round 3 | M10: Test date | N10: Tester | O10: Note
A11: Draft Generation
A12: TC-SAL-001 | B12: Generate AI draft for a conversation | C12: Navigate to http://localhost:15876/conversations. Open a conversation with existing messages. Click the "Tao phan hoi" button in the Sale Assist panel. Wait for the draft to be generated. | D12: The Sale Assist panel displays an AI-generated draft reply. The draft includes context from the conversation history and lead score. A "Gui" button and "Chinh sua" button appear below the draft. | E12: Can connect to server. Conversation has messages. LLM provider is configured.
A13: TC-SAL-002 | B13: Draft includes lead context | C13: Open a conversation linked to a lead with score >= 70. Generate an AI draft. Observe the context sidebar. | D13: The Sale Assist panel shows the lead score, last 5 messages, and suggested next action alongside the draft. The draft is contextualized to the lead's stage and history. | E13: Can connect to server. Conversation is linked to a lead.
A14: TC-SAL-003 | B14: Edit AI draft before sending | C14: Generate an AI draft for a conversation. Click the "Chinh sua" button. Modify the draft text in the edit field. Click "Gui" to send the edited version. | D14: The edited draft is sent as an outbound message. The message appears in the conversation thread with the edited content. | E14: Can connect to server. AI draft has been generated.
A15: TC-SAL-004 | B15: Reject AI draft | C15: Generate an AI draft for a conversation. Click the "Tu choi" button. | D15: The draft is discarded. The Sale Assist panel returns to its default state. The conversation remains open for manual reply. | E15: Can connect to server. AI draft has been generated.
A16: Summary
A17: TC-SAL-005 | B17: Generate conversation summary | C17: Open a conversation with at least 10 messages. Click the "Tom tat" button in the Sale Assist panel. | D17: The system generates a concise summary of the conversation. The summary is displayed in the Sale Assist panel, highlighting key points, customer requests, and current status. | E17: Can connect to server. Conversation has multiple messages. LLM provider is configured.
A18: Quick Replies
A19: TC-SAL-006 | B19: Create a quick reply template | C19: Navigate to the Sale Assist panel. Click the "Phan hoi nhanh" section. Click "Them moi". Enter "HSK4_GOI" in the "Ma goi nho" field. Enter "Tu van" in the "Nhom" field. Enter "facebook, zalo" in the "Kenh" field. Enter the reply content in the body field. Click "Luu". | D19: The quick reply template is saved and appears in the quick reply list. It can be used for future conversations. | E19: Can connect to server. User has conversations:write permission.
A20: TC-SAL-007 | B20: Use quick reply in conversation | C20: Open a conversation. Click the "Phan hoi nhanh" button. Select a quick reply template from the list. | D20: The quick reply content is inserted into the message input field. The sale can review and send it. | E20: Can connect to server. Quick reply templates exist.
A21: TC-SAL-008 | B21: Update quick reply template | C21: Navigate to the quick reply list. Click on a template to edit. Update the reply content. Click "Luu". | D21: The template is updated with the new content. The change is reflected when the template is used next. | E21: Can connect to server. Template exists.
A22: TC-SAL-009 | B22: Delete quick reply template | C22: Navigate to the quick reply list. Click the delete icon next to a template. Confirm the deletion. | D22: The template is removed from the list. It can no longer be used in conversations. | E22: Can connect to server. Template exists.
A23: Daily Summary & Upsell
A24: TC-SAL-010 | B24: View daily summary | C24: Navigate to the Sale Assist panel. Click the "Tong hop ngay" button. | D24: The daily summary shows today's key metrics: conversations handled, messages sent, response time, leads touched, and conversion events. | E24: Can connect to server. Data exists for today.
A25: TC-SAL-011 | B25: View upsell suggestions | C25: Navigate to the Sale Assist panel. Click the "Goi y ban hang" section. | D25: The upsell panel shows product or course recommendations based on the current conversation context and lead profile. Each suggestion includes a reason and confidence score. | E25: Can connect to server. Lead data and product catalog exist.
A26: Idle Alert
A27: TC-SAL-012 | B27: Alert when conversation idle > 5 minutes | C27: Open a conversation assigned to a sale. Do not respond for more than 5 minutes after the customer's last message. Observe the notification. | D27: After 5 minutes, the system sends an alert to the assigned sale via SignalR (in-app notification). The notification indicates the conversation has been waiting too long. | E27: Can connect to server. Conversation is assigned. Sale is logged in.

Sheet Lead & CRM
A2: Feature | B2: Lead & CRM
A3: Test requirement | B3: Lead list/filter, create, assign, stage update, activities, revenue, forecast, CSV import/export
A4: Number of TCs | B4: =COUNTA(A12:A1014)
A5: Testing Round | B5: Passed | C5: Failed | D5: Pending | E5: N/A
A6: Round 1 | B6: =COUNTIF($F12:$F1014,B5) | C6: =COUNTIF($F12:$F1014,C5) | D6: =COUNTIF($F12:$F1014,D5) | E6: =COUNTIF($F12:$F1014,E5)
A7: Round 2 | B7: =COUNTIF($I12:$I1014,B5) | C7: =COUNTIF($I12:$I1014,C5) | D7: =COUNTIF($I12:$I1014,D5) | E7: =COUNTIF($I12:$I1014,E5)
A8: Round 3 | B8: =COUNTIF($L12:$L1014,B5) | C8: =COUNTIF($L12:$L1014,C5) | D8: =COUNTIF($L12:$L1014,D5) | E8: =COUNTIF($L12:$L1014,E5)
A10: Test Case ID | B10: Test Case Description | C10: Test Case Procedure | D10: Expected Results | E10: Pre-conditions | F10: Round 1 | G10: Test date | H10: Tester | I10: Round 2 | J10: Test date | K10: Tester | L10: Round 3 | M10: Test date | N10: Tester | O10: Note
A11: Lead List & Filters
A12: TC-LEA-001 | B12: View all leads | C12: Navigate to http://localhost:15876/leads. Observe the lead list. | D12: The lead list displays all leads in a table with columns for name, phone, email, source platform, stage badge (hot/warm/cold/customer/lost), score, assigned owner, and last activity date. A search bar and stage filter chips are at the top. | E12: Can connect to server. Leads exist in the database.
A13: TC-LEA-002 | B13: Filter leads by stage "Nong" | C13: Navigate to the leads page. Click the "Nong" filter chip (red badge with fire icon). | D13: Only leads with stage "hot" (score >= 70) are displayed. The "Nong" chip is highlighted. | E13: Can connect to server. Hot leads exist.
A14: TC-LEA-003 | B14: Filter leads by stage "Am" | C14: Navigate to the leads page. Click the "Am" filter chip. | D14: Only leads with stage "warm" (score 30-70) are displayed. | E14: Can connect to server. Warm leads exist.
A15: TC-LEA-004 | B15: Filter leads by stage "Lanh" | C15: Navigate to the leads page. Click the "Lanh" filter chip. | D15: Only leads with stage "cold" (score < 30) are displayed. | E15: Can connect to server. Cold leads exist.
A16: TC-LEA-005 | B16: Filter leads by platform | C16: Navigate to the leads page. Use the platform filter dropdown. Select "Facebook". | D16: Only leads from the Facebook platform are displayed. | E16: Can connect to server. Facebook leads exist.
A17: TC-LEA-006 | B17: Search leads by name or phone | C17: Navigate to the leads page. Type a contact name or phone number in the search bar. | D17: The lead list updates to show only leads matching the search query. | E17: Can connect to server. Leads with matching data exist.
A18: TC-LEA-007 | B18: Export leads to CSV | C18: Navigate to the leads page. Click the "Xuat CSV" button. | D18: A CSV file is downloaded containing all leads (or filtered leads) with columns for name, phone, email, stage, score, source, owner, and created date. | E18: Can connect to server. Leads exist.
A19: TC-LEA-008 | B19: Import leads from CSV | C19: Navigate to the leads page. Click the "Nhap CSV" button. Select a CSV file with columns: name, phone, email, source. Click "Nhap". | D19: The system imports the leads from the CSV file. New leads are created with initial stage "cold" and default scoring. A summary shows the number of imported leads. | E19: Can connect to server. Valid CSV file is prepared.
A20: Lead CRUD
A21: TC-LEA-009 | B21: Create a new lead | C21: Navigate to the leads page. Click the "Tao lead" button. Enter "Nguyen Van A" in the "Ho ten" field. Enter "0901234567" in the "So dien thoai" field. Enter "nguyenvana@test.com" in the "Email" field. Select "Facebook" from the "Nguon" dropdown. Click "Tao". | D21: The new lead appears in the lead list with stage "cold" and a calculated score. The lead detail panel shows the contact information and empty activity timeline. | E21: Can connect to server. User has leads:write permission.
A22: TC-LEA-010 | B22: View lead detail | C22: Navigate to the leads page. Click on a lead row in the table. | D22: The lead detail drawer opens on the right side with three tabs: "Timeline", "Bo canh", and "Doanh thu". The timeline shows all activities. The context panel shows lead score, stage, owner, and source. | E22: Can connect to server. Lead exists.
A23: TC-LEA-011 | B23: Update lead stage | C23: Open a lead detail. Click on the stage dropdown. Select "Nong" from the dropdown. Confirm the change. | D23: The lead stage is updated to "hot". The stage badge color changes to red. The score is recalculated if applicable. | E23: Can connect to server. Lead exists.
A24: Scoring
A25: TC-LEA-012 | B25: Lead scoring rules are applied correctly | C25: Navigate to the leads page. Create a new lead with source "facebook" and activity "lead_price_view". Observe the lead score. | D25: The lead score is calculated based on the scoring rules. For example, if facebook platform has weight 0.6 and lead_price_view has weight 0.4, the score reflects these weights. | E25: Can connect to server. Scoring rules are configured.
A26: TC-LEA-013 | B26: View scoring rules | C26: Navigate to the lead scoring rules page or API endpoint GET /api/lead-scoring-rules. | D26: The scoring rules list shows all active rules with their platform, event code, weight, and description. | E26: Can connect to server. Scoring rules exist.
A27: TC-LEA-014 | B27: Seed default scoring rules | C27: Navigate to the lead scoring rules page. Click the "Mac dinh" button to seed default rules. | D27: Default scoring rules are created for common platforms (facebook, zalo, tiktok, instagram, youtube) and events (lead_price_view, lead_phone_call, lead_demo_booked, lead_chat_reply). | E27: Can connect to server. No rules exist yet.
A28: TC-LEA-015 | B28: Rescore all leads | C28: Navigate to the leads page. Click the "Tinh lai diem" button. Confirm the action. | D28: All leads are rescored based on current scoring rules. Lead stages are updated accordingly. | E28: Can connect to server. Scoring rules and leads exist.
A29: Assignment & Activities
A30: TC-LEA-016 | B30: Assign lead to a sale | C30: Open a lead detail. Click the "Phan cong" button. Select a sale user from the dropdown. Confirm the assignment. | D30: The lead is assigned to the selected sale. The owner field updates. The assigned sale receives a notification. | E30: Can connect to server. Sale user exists.
A31: TC-LEA-017 | B31: Record an activity on a lead | C31: Open a lead detail. Click the "Ghi hoat dong" button. Select "Goi tu van" (Phone call) from the activity type dropdown. Enter "Khach hoi ve hoc phi" in the notes field. Click "Luu". | D31: The activity is recorded in the lead timeline. The activity type shows "Goi tu van" with the note and timestamp. The lead score may increase based on the activity type. | E31: Can connect to server. Lead exists.
A32: TC-LEA-018 | B32: Revenue tracking | C32: Open a lead detail. Click the "Doanh thu" tab. Click them. Enter "5000000" in the "So tien" field. Enter "Hoc phi khoa HSK4" in the "Ghi chu" field. Click "Luu". | D32: The revenue entry is saved and appears in the revenue list. The total revenue for the lead is updated. | E32: Can connect to server. Lead exists.
A33: Forecast
A34: TC-LEA-019 | B34: View sales forecast | C34: Navigate to the leads page. Click the "Du bao" button or navigate to GET /api/leads/forecast. | D34: The forecast panel displays projected revenue based on historical lead data. If insufficient data (< 7 days), a message is shown: "Can du lieu it nhat 7 ngay de du bao". | E34: Can connect to server.
A35: TC-LEA-020 | B35: Context panel | C35: Open a lead detail. Click the "Bo canh" tab. | D35: The context panel shows the lead's full history: all conversations, activities, revenue entries, document sends, and content interactions. The panel provides a 360-degree view of the customer relationship. | E35: Can connect to server. Lead has activity history.
A36: Drip Sequences
A37: TC-LEA-021 | B37: Cold lead triggers drip sequence | C37: Create a lead with stage "cold" on the Zalo platform. Wait for the drip sequence job to run (or trigger manually). | D37: The system initiates a 7-day drip sequence for the Zalo platform. Automated messages are scheduled at configured intervals. | E37: Can connect to server. Drip sequence configuration exists for Zalo.
A38: TC-LEA-022 | B38: Lead becomes customer triggers welcome sequence | C38: Open a lead. Change stage to "Khach hang" (customer). Confirm the change. | D38: The system triggers a welcome sequence. An onboarding kit document is generated and sent to the customer. The lead stage is updated to "customer". | E38: Can connect to server. Onboarding template exists.

Sheet Content Management
A2: Feature | B2: Content Management
A3: Test requirement | B3: Brief CRUD, trend scan, item generate/approve/reject, schedule, calendar, repurpose, hooks
A4: Number of TCs | B4: =COUNTA(A12:A1014)
A5: Testing Round | B5: Passed | C5: Failed | D5: Pending | E5: N/A
A6: Round 1 | B6: =COUNTIF($F12:$F1014,B5) | C6: =COUNTIF($F12:$F1014,C5) | D6: =COUNTIF($F12:$F1014,D5) | E6: =COUNTIF($F12:$F1014,E5)
A7: Round 2 | B7: =COUNTIF($I12:$I1014,B5) | C7: =COUNTIF($I12:$I1014,C5) | D7: =COUNTIF($I12:$I1014,D5) | E7: =COUNTIF($I12:$I1014,E5)
A8: Round 3 | B8: =COUNTIF($L12:$L1014,B5) | C8: =COUNTIF($L12:$L1014,C5) | D8: =COUNTIF($L12:$L1014,D5) | E8: =COUNTIF($L12:$L1014,E5)
A10: Test Case ID | B10: Test Case Description | C10: Test Case Procedure | D10: Expected Results | E10: Pre-conditions | F10: Round 1 | G10: Test date | H10: Tester | I10: Round 2 | J10: Test date | K10: Tester | L10: Round 3 | M10: Test date | N10: Tester | O10: Note
A11: Brief Management
A12: TC-CON-001 | B12: Create a content brief | C12: Navigate to http://localhost:15876 (content workspace). Click "Tao brief". Enter "Bai viet HSK4 tips" in the "Tieu de" field. Enter "Noi dung ve phuong phap hoc HSK4" in the "Mo ta" field. Select "Facebook" from the "Nen tang" dropdown. Click "Tao". | D12: The brief is created and appears in the brief list with status "draft". The brief is linked to the Facebook platform. | E12: Can connect to server. User has content:write permission.
A13: TC-CON-002 | B13: List all briefs | C13: Navigate to the content workspace. Click the "Briefs" tab. | D13: The brief list displays all content briefs with title, platform, status, created date, and action buttons. | E13: Can connect to server. Briefs exist.
A14: TC-CON-003 | B14: Update a brief | C14: Navigate to a brief. Click "Chinh sua". Update the "Mo ta" field. Click "Luu". | D14: The brief is updated with the new description. | E14: Can connect to server. Brief exists.
A15: TC-CON-004 | B15: Delete a brief | C15: Navigate to a brief. Click "Xoa". Confirm the deletion. | D15: The brief is removed from the list. Associated content items are not deleted. | E15: Can connect to server. Brief exists.
A16: Trends
A17: TC-CON-005 | B17: View trend list | C17: Navigate to the content workspace. Click the "Xu huong" tab. | D17: The trend list shows trending topics from configured sources (TikTok, YouTube). Each trend shows the topic name, platform, engagement metrics, and relevance score. | E17: Can connect to server. Trend data exists.
A18: TC-CON-006 | B18: Scan for new trends | C18: Navigate to the trends section. Click the "Quet xu huong" button. Wait for the scan to complete. | D18: The system scrapes TikTok and YouTube for trending topics relevant to the configured niche. New trends are added to the list. A success message shows the number of new trends found. | E18: Can connect to server. Trend sources are configured.
A19: Content Items
A20: TC-CON-007 | B20: Generate a content item from brief | C20: Navigate to a brief. Click "Sinh noi dung". Select the content type (article/video script/social post). Click "Sinh". | D20: The AI generates a content item based on the brief. The item appears in the content queue with status "draft". The item includes the generated text, suggested hashtags, and image prompts. | E20: Can connect to server. Brief exists. LLM provider is configured.
A21: TC-CON-008 | B21: View content queue | C21: Navigate to the content workspace. Click the "Hang doi" tab. | D21: The queue displays all content items with their status (draft/approved/scheduled/published/rejected), platform, scheduled date, and action buttons. Status filter chips are available at the top. | E21: Can connect to server. Content items exist.
A22: TC-CON-009 | B22: Filter items by status | C22: Navigate to the content queue. Click the "Cho duyet" filter chip. | D22: Only items with status "draft" (pending approval) are displayed. | E22: Can connect to server. Items with different statuses exist.
A23: TC-CON-010 | B23: Approve a content item | C23: Navigate to the content queue. Find an item with status "draft". Click the "Duyet" button. Confirm the approval. | D23: The item status changes to "approved". The item is now eligible for scheduling. The "Duyet" button is replaced with "Len lich" and "Tu choi" buttons. | E23: Can connect to server. Item status is draft.
A24: TC-CON-011 | B24: Reject a content item | C24: Navigate to the content queue. Find an item with status "draft". Click the "Tu choi" button. Enter a rejection reason. Confirm. | D24: The item status changes to "rejected". The rejection reason is recorded. The item is moved to the rejected filter group. | E24: Can connect to server. Item status is draft.
A25: TC-CON-012 | B25: Schedule an approved item | C25: Navigate to the content queue. Find an item with status "approved". Click the "Len lich" button. Select a date and time from the date picker. Select the target platform (Facebook/Instagram/TikTok). Click "Len lich". | D25: The item status changes to "scheduled". The scheduled date and platform are recorded. The item appears on the content calendar. | E25: Can connect to server. Item is approved.
A26: TC-CON-013 | B26: View content calendar | C26: Navigate to the content workspace. Click the "Lich" tab. | D26: The calendar displays scheduled content items by date. Each item shows the title, platform icon, and scheduled time. Clicking an item opens its detail. | E26: Can connect to server. Items are scheduled.
