Workbook
Name ACTION: #REF!
Name ACTION: #REF!

Sheet Cover
B2: INTEGRATION TEST REPORT DOCUMENT
A4: Project Name | B4: Clawbot | E4: Creator | F4: <Creator>
A5: Project Code | B5: CLAWBOT | E5: Issue Date | F5: 46244.708
A6: Document Code | B6: =B5&"_"&"XXX"&"_"&"vx.x" -> CLAWBOT_XXX_vx.x | E6: Version | F6: 1
A9: Record of change
A10: Effective Date | B10: Version | C10: Change Item | D10: *A,D,M | E10: Change description | F10: Reference
A11: 46244.708 | B11: 1.0 | C11: All modules | D11: A | E11: Initial version

Sheet Test Cases
D1: TEST CASE LIST
B3: Project Name | D3: =Cover!B4 -> Clawbot
B4: Project Code | D4: =Cover!B5 -> CLAWBOT
B5: Test Environment Setup Description | D5: 1. Frontend: React + Vite (localhost:15876) 2. API Backend: .NET 8 (localhost:15874) 3. AgentService gRPC (localhost:15875) 4. SQL Server 2022 (Docker :1433) 5. Redis 7 (Docker :6379) 6. Qdrant vector store (Docker :6333)
B8: No | C8: Function Name | D8: Sheet Name | E8: Description | F8: Pre-Condition
B9: 1 | C9: Login & Authentication | D9: Login & Authentication | E9: JWT authentication with refresh-token rotation, 2FA, session revocation, password reset and change-password flows | F9: API and database are reachable; a seeded tenant account exists
B10: 2 | C10: Omnichannel Inbox | D10: Omnichannel Inbox | E10: Channel connection, message ingestion via webhook and polling, deduplication, outbound replies, auto-reply with AI, pause/resume, draft approval, escalation and conversation search | F10: At least one channel is connected; RabbitMQ consumer is running
B11: 3 | C11: Knowledge Base | D11: Knowledge Base | E11: KB module management, version creation, content deploy to vector store, rollback, accuracy measurement and auto-approving AI suggestions when accuracy does not decrease | F11: Qdrant vector store is reachable; a configured LLM provider is active
B12: 4 | C12: Lead Management | D12: Lead Management | E12: Lead CRUD, pipeline stage transitions driven by score, manual stage override, scoring rule management, lead assignment and activity feed | F12: API is running; lead scoring rules are seeded via POST /api/lead-scoring-rules/seed-defaults
B13: 5 | C13: Content Pipeline | D13: Content Pipeline | E13: Brief management, AI content generation, review gate, human approval, scheduling and publishing lifecycle for social media posts | F13: A configured LLM provider is active; a deployed KB module exists for RAG context
B14: 6 | C14: Agent Orchestration | D14: Agent Orchestration | E14: Create and run orchestration sessions, pause for manual intervention, resume after approval, manage recurring schedules and verify agent tool grants | F14: AgentService gRPC is running; at least one agent definition is bound to an LLM provider
B15: 7 | C15: Documents & Reports | D15: Documents & Reports | E15: Document generation (quote PDF, brochure), document library per contact, and report/analytics export | F15: A contact with an active conversation exists; the document template library is seeded
B16: 8 | C16: Admin & RBAC | D16: Admin & RBAC | E16: User management, role-permission assignment, API key issuance/revocation and audit logging for privileged actions | F16: A tenant admin account exists; RBAC roles are seeded
B17: 9 | C17: Notifications & Labels | D17: Notifications & Labels | E17: In-app notification delivery, per-channel notification preferences, conversation labels and internal notes | F17: A conversation and a background job runner are available
B18: 10 | C18: Sale Assist & Prompts | D18: Sale Assist & Prompts | E18: AI draft suggestions for sale replies, prompt template management, skill grants and chat-scenario matching | F18: A conversation with recent inbound messages exists; at least one prompt template and one chat scenario are seeded
B19: 11 | C19: Channel Integrations | D19: Channel Integrations | E19: Channel connection management, Meta Business webhook variants, social credential encryption and the public embeddable widget | F19: Provider sandbox credentials are available for at least one channel

Sheet Test Statistics
B1: INTEGRATION TEST STATISTICS
B3: Project Name | C3: Clawbot | E3: Creator | G3: <Creator>
B4: Project Code | C4: CLAWBOT | E4: Reviewer/Approver
B5: Document Code | C5: =C4&"_"&"Test Report"&"_"&"vx.x" -> CLAWBOT_Test Report_vx.x | E5: Issue Date | H5: 46244.708
B6: Notes | C6: Login & Auth, Omnichannel Inbox, Knowledge Base, Lead Management, Content Pipeline, Agent Orchestration
B10: No | C10: Module code | D10: Passed | E10: Failed | F10: Pending | G10: N/A | H10: Number of test cases
B11: 1 | C11: ='Login & Authentication'!B2 -> Login & Authentication | D11: ='Login & Authentication'!B6 -> 14 | E11: ='Login & Authentication'!C6 -> 1 | F11: ='Login & Authentication'!D6 -> 0 | G11: ='Login & Authentication'!E6 -> 0 | H11: ='Login & Authentication'!B4 -> 15
B12: 2 | C12: ='Omnichannel Inbox'!B2 -> Omnichannel Inbox | D12: ='Omnichannel Inbox'!B6 -> 23 | E12: ='Omnichannel Inbox'!C6 -> 1 | F12: ='Omnichannel Inbox'!D6 -> 0 | G12: ='Omnichannel Inbox'!E6 -> 0 | H12: ='Omnichannel Inbox'!B4 -> 24
B13: 3 | C13: ='Knowledge Base'!B2 -> Knowledge Base | D13: ='Knowledge Base'!B6 -> 10 | E13: ='Knowledge Base'!C6 -> 1 | F13: ='Knowledge Base'!D6 -> 0 | G13: ='Knowledge Base'!E6 -> 0 | H13: ='Knowledge Base'!B4 -> 11
B14: 4 | C14: ='Lead Management'!B2 -> Lead Management | D14: ='Lead Management'!B6 -> 11 | E14: ='Lead Management'!C6 -> 1 | F14: ='Lead Management'!D6 -> 0 | G14: ='Lead Management'!E6 -> 0 | H14: ='Lead Management'!B4 -> 12
B15: 5 | C15: ='Content Pipeline'!B2 -> Content Pipeline | D15: ='Content Pipeline'!B6 -> 10 | E15: ='Content Pipeline'!C6 -> 1 | F15: ='Content Pipeline'!D6 -> 0 | G15: ='Content Pipeline'!E6 -> 0 | H15: ='Content Pipeline'!B4 -> 11
B16: 6 | C16: ='Agent Orchestration'!B2 -> Agent Orchestration | D16: ='Agent Orchestration'!B6 -> 10 | E16: ='Agent Orchestration'!C6 -> 1 | F16: ='Agent Orchestration'!D6 -> 0 | G16: ='Agent Orchestration'!E6 -> 0 | H16: ='Agent Orchestration'!B4 -> 11
B17: 7 | C17: ='Documents & Reports'!B2 -> Documents & Reports | D17: ='Documents & Reports'!B6 -> 7 | E17: ='Documents & Reports'!C6 -> 1 | F17: ='Documents & Reports'!D6 -> 0 | G17: ='Documents & Reports'!E6 -> 0 | H17: ='Documents & Reports'!B4 -> 8
B18: 8 | C18: ='Admin & RBAC'!B2 -> Admin & RBAC | D18: ='Admin & RBAC'!B6 -> 7 | E18: ='Admin & RBAC'!C6 -> 1 | F18: ='Admin & RBAC'!D6 -> 0 | G18: ='Admin & RBAC'!E6 -> 0 | H18: ='Admin & RBAC'!B4 -> 8
B19: 9 | C19: ='Notifications & Labels'!B2 -> Notifications & Labels | D19: ='Notifications & Labels'!B6 -> 8 | E19: ='Notifications & Labels'!C6 -> 0 | F19: ='Notifications & Labels'!D6 -> 0 | G19: ='Notifications & Labels'!E6 -> 0 | H19: ='Notifications & Labels'!B4 -> 8
B20: 10 | C20: ='Sale Assist & Prompts'!B2 -> Sale Assist & Prompts | D20: ='Sale Assist & Prompts'!B6 -> 6 | E20: ='Sale Assist & Prompts'!C6 -> 1 | F20: ='Sale Assist & Prompts'!D6 -> 0 | G20: ='Sale Assist & Prompts'!E6 -> 0 | H20: ='Sale Assist & Prompts'!B4 -> 7
B21: 11 | C21: ='Channel Integrations'!B2 -> Channel Integrations | D21: ='Channel Integrations'!B6 -> 6 | E21: ='Channel Integrations'!C6 -> 1 | F21: ='Channel Integrations'!D6 -> 0 | G21: ='Channel Integrations'!E6 -> 0 | H21: ='Channel Integrations'!B4 -> 7
C23: Sub total | D23: =SUM(D11:D21) -> 112 | E23: =SUM(E11:E21) -> 10 | F23: =SUM(F11:F21) -> 0 | G23: =SUM(G11:G21) -> 0 | H23: =SUM(H11:H21) -> 122
C25: Test coverage | E25: =(D23+E23)*100/(H23-G23) -> 100 | F25: %
C26: Test successful coverage | E26: =D23*100/(H23-G23) -> 91.803279 | F26: %

Sheet Login & Authentication
A2: Feature | B2: Login & Authentication | S2: Passed
A3: Test requirement | B3: JWT authentication with refresh-token rotation, 2FA, session revocation, password reset and change-password flows | S3: Failed
A4: Number of TCs | B4: =COUNTIF($A$12:$A$1000,"TC-*") -> 15 | S4: Pending
A5: Testing Round | B5: Passed | C5: Failed | D5: Pending | E5: N/A | S5: N/A
A6: Round 1 | B6: =COUNTIF($F10:$F1009,B5) -> 14 | C6: =COUNTIF($F10:$F1009,C5) -> 1 | D6: =COUNTIF($F10:$F1009,D5) -> 0 | E6: =COUNTIF($F10:$F1009,E5) -> 0
A7: Round 2 | B7: =COUNTIF($I10:$I998,B5) -> 15 | C7: =COUNTIF($I10:$I998,C5) -> 0 | D7: =COUNTIF($I10:$I998,D5) -> 0 | E7: =COUNTIF($I10:$I998,E5) -> 0
A8: Round 3 | B8: =COUNTIF($L10:$L998,B5) -> 15 | C8: =COUNTIF($L10:$L998,C5) -> 0 | D8: =COUNTIF($L10:$L998,D5) -> 0 | E8: =COUNTIF($L10:$L998,E5) -> 0
A10: Test Case ID | B10: Test Case Description | C10: Test Case Procedure | D10: Expected Results | E10: Pre-conditions | F10: Round 1 | G10: Test date | H10: Tester | I10: Round 2 | J10: Test date | K10: Tester | L10: Round 3 | M10: Test date | N10: Tester | O10: Defect IDs | P10: Note
A11: Function A
A12: Login
A13: TC-LOG-001 | B13: Sign in with valid credentials | C13: 1. POST /auth/login with a valid email and password. 2. Check the response. | D13: HTTP 200; response body contains accessToken and refreshToken. | E13: The account is active and no lockout is in effect | F13: Passed | G13: 46244.708 | H13: QA1 | I13: Passed | J13: 46247.708 | K13: QA1 | L13: Passed | M13: 46252.708 | N13: QA1
A14: TC-LOG-002 | B14: Reject sign-in with a wrong password | C14: 1. POST /auth/login with a valid email and an incorrect password. | D14: HTTP 401; no token is issued; generic error message returned. | E14: The account is active | F14: Passed | G14: 46244.708 | H14: QA1 | I14: Passed | J14: 46247.708 | K14: QA1 | L14: Passed | M14: 46252.708 | N14: QA1
A15: TC-LOG-003 | B15: Lock the account after five consecutive wrong passwords | C15: 1. POST /auth/login with a wrong password five times. 2. Submit the correct password. | D15: HTTP 429 or 401 on the sixth attempt; the correct password is also rejected until lockout expires. | E15: Lockout threshold is configured to five attempts | F15: Failed | G15: 46244.708 | H15: QA1 | I15: Passed | J15: 46247.708 | K15: QA1 | L15: Passed | M15: 46252.708 | N15: QA1 | O15: DEF-001 | P15: Round 1: the counter reset on every successful request, so the fifth wrong password still returned 401 instead of a lockout. Fixed and retested in round 2.
A16: Refresh and logout
A17: TC-LOG-004 | B17: Refresh an access token using a valid refresh token | C17: 1. POST /auth/refresh with a valid refreshToken. 2. Check the response. | D17: HTTP 200; new accessToken and rotated refreshToken are returned. | E17: A signed-in session exists with a valid refresh token | F17: Passed | G17: 46245.708 | H17: QA1 | I17: Passed | J17: 46247.708 | K17: QA1 | L17: Passed | M17: 46252.708 | N17: QA1
A18: TC-LOG-005 | B18: Replay a refresh token after rotation is rejected | C18: 1. POST /auth/refresh to rotate the token. 2. Replay the original refresh token. | D18: HTTP 401; the replayed token is rejected (rotation invalidates the previous token). | E18: A signed-in session exists | F18: Passed | G18: 46245.708 | H18: QA1 | I18: Passed | J18: 46247.708 | K18: QA1 | L18: Passed | M18: 46252.708 | N18: QA1
A19: TC-LOG-006 | B19: Sign out revokes the refresh token | C19: 1. POST /auth/logout. 2. Attempt to use the previous refresh token. | D19: Logout returns HTTP 200; the revoked refresh token is rejected with HTTP 401. | E19: An active session exists | F19: Passed | G19: 46245.708 | H19: QA1 | I19: Passed | J19: 46247.708 | K19: QA1 | L19: Passed | M19: 46252.708 | N19: QA1
A20: Two-factor authentication
A21: TC-LOG-007 | B21: Enable 2FA and verify the setup TOTP code | C21: 1. POST /auth/2fa/enable to get the TOTP secret. 2. POST /auth/2fa/verify with a valid TOTP code. | D21: 2FA is enabled on the account; subsequent logins require a TOTP step. | E21: Account does not have 2FA enabled | F21: Passed | G21: 46244.708 | H21: QA1 | I21: Passed | J21: 46247.708 | K21: QA1 | L21: Passed | M21: 46252.708 | N21: QA1
A22: TC-LOG-008 | B22: Complete login with a valid TOTP code when 2FA is active | C22: 1. POST /auth/login to receive a partial token. 2. POST /auth/login/2fa with the current TOTP code. | D22: HTTP 200; full accessToken and refreshToken are returned. | E22: 2FA is enabled on the account | F22: Passed | G22: 46244.708 | H22: QA1 | I22: Passed | J22: 46247.708 | K22: QA1 | L22: Passed | M22: 46252.708 | N22: QA1
A23: TC-LOG-009 | B23: Reject login with an incorrect TOTP code | C23: 1. POST /auth/login to receive a partial token. 2. POST /auth/login/2fa with an invalid TOTP code. | D23: HTTP 401; no full token is issued. | E23: 2FA is enabled on the account | F23: Passed | G23: 46244.708 | H23: QA1 | I23: Passed | J23: 46247.708 | K23: QA1 | L23: Passed | M23: 46252.708 | N23: QA1
A24: Password management
A25: TC-LOG-010 | B25: Change password while signed in | C25: 1. POST /auth/change-password with the current and new passwords. 2. Sign out and sign back in with the new password. | D25: Password change returns HTTP 200; old password is no longer accepted. | E25: An active session exists | F25: Passed | G25: 46245.708 | H25: QA1 | I25: Passed | J25: 46247.708 | K25: QA1 | L25: Passed | M25: 46252.708 | N25: QA1
A26: TC-LOG-011 | B26: Request a password reset email | C26: 1. POST /auth/reset/request with the account email. | D26: HTTP 200 is returned regardless of whether the email exists (no user enumeration). | E26: SMTP is configured in the test environment | F26: Passed | G26: 46245.708 | H26: QA1 | I26: Passed | J26: 46247.708 | K26: QA1 | L26: Passed | M26: 46252.708 | N26: QA1
A27: TC-LOG-012 | B27: Confirm a password reset with a valid token | C27: 1. Extract the reset token from the email link. 2. POST /auth/reset/confirm with the token and new password. | D27: HTTP 200; the user can sign in with the new password; the reset token cannot be reused. | E27: A valid reset token was issued within the expiry window | F27: Passed | G27: 46245.708 | H27: QA1 | I27: Passed | J27: 46247.708 | K27: QA1 | L27: Passed | M27: 46252.708 | N27: QA1
A28: TC-LOG-013 | B28: Reject weak password on change-password | C28: 1. POST /auth/change-password with new password '123'. 2. Check response. | D28: HTTP 400; password policy violation is returned. | E28: An active session exists | F28: Passed | G28: 46245.708 | H28: QA1 | I28: Passed | J28: 46247.708 | K28: QA1 | L28: Passed | M28: 46252.708 | N28: QA1
A29: TC-LOG-014 | B29: Issue date on JWT is not in the future | C29: 1. POST /auth/login and decode the accessToken without verification. | D29: iat is within 60 seconds of server time; exp is after iat. | E29: Clock is synchronized | F29: Passed | G29: 46245.708 | H29: QA1 | I29: Passed | J29: 46248.708 | K29: QA1 | L29: Passed | M29: 46253.708 | N29: QA1
A30: TC-LOG-015 | B30: Tenant claim in JWT matches the signed-in tenant | C30: 1. Sign in as tenant B admin. 2. Decode accessToken and read tenant claim. | D30: Tenant claim equals the B tenant identifier; no tenant A data is accessible. | E30: Two tenants exist | F30: Passed | G30: 46246.708 | H30: QA1 | I30: Passed | J30: 46248.708 | K30: QA1 | L30: Passed | M30: 46253.708 | N30: QA1

Sheet Omnichannel Inbox
A2: Feature | B2: Omnichannel Inbox | S2: Passed
A3: Test requirement | B3: Channel connection, message ingestion via webhook and polling, deduplication, outbound replies, auto-reply with AI, pause/resume, draft approval, escalation and conversation search | S3: Failed
A4: Number of TCs | B4: =COUNTIF($A$12:$A$1000,"TC-*") -> 24 | S4: Pending
A5: Testing Round | B5: Passed | C5: Failed | D5: Pending | E5: N/A | S5: N/A
A6: Round 1 | B6: =COUNTIF($F10:$F1019,B5) -> 23 | C6: =COUNTIF($F10:$F1019,C5) -> 1 | D6: =COUNTIF($F10:$F1019,D5) -> 0 | E6: =COUNTIF($F10:$F1019,E5) -> 0
A7: Round 2 | B7: =COUNTIF($I10:$I998,B5) -> 24 | C7: =COUNTIF($I10:$I998,C5) -> 0 | D7: =COUNTIF($I10:$I998,D5) -> 0 | E7: =COUNTIF($I10:$I998,E5) -> 0
A8: Round 3 | B8: =COUNTIF($L10:$L998,B5) -> 24 | C8: =COUNTIF($L10:$L998,C5) -> 0 | D8: =COUNTIF($L10:$L998,D5) -> 0 | E8: =COUNTIF($L10:$L998,E5) -> 0
A10: Test Case ID | B10: Test Case Description | C10: Test Case Procedure | D10: Expected Results | E10: Pre-conditions | F10: Round 1 | G10: Test date | H10: Tester | I10: Round 2 | J10: Test date | K10: Tester | L10: Round 3 | M10: Test date | N10: Tester | O10: Defect IDs | P10: Note
A11: Function A
A12: Channel connection
A13: TC-INB-001 | B13: Connect a channel with a valid page token | C13: 1. POST /api/admin/inboxes with a valid page token. 2. Wait for the first sync to start. | D13: HTTP 201; channel is listed as connected; initial conversation sync begins. | E13: A valid page token is available | F13: Passed | G13: 46244.708 | H13: QA2 | I13: Passed | J13: 46247.708 | K13: QA2 | L13: Passed | M13: 46252.708 | N13: QA2
A14: TC-INB-002 | B14: Reject a channel connection with an invalid token | C14: 1. POST /api/admin/inboxes with an invalid token. | D14: HTTP 422; no inbox row is persisted; error message is returned. | E14: None | F14: Passed | G14: 46244.708 | H14: QA2 | I14: Passed | J14: 46247.708 | K14: QA2 | L14: Passed | M14: 46252.708 | N14: QA2
A15: TC-INB-003 | B15: Reconnect a channel after the token is revoked | C15: 1. Revoke the token at the provider. 2. PUT /api/admin/inboxes/{id} with a new token. | D15: Sync error is cleared; message ingestion resumes for new messages. | E15: The channel is currently connected | F15: Passed | G15: 46244.708 | H15: QA2 | I15: Passed | J15: 46247.708 | K15: QA2 | L15: Passed | M15: 46252.708 | N15: QA2
A16: TC-INB-004 | B16: Conversations from different tenants remain isolated | C16: 1. Connect the same page under two tenants. 2. Send a message. | D16: The message appears only in the correct tenant inbox. | E16: Two active tenant accounts exist | F16: Passed | G16: 46244.708 | H16: QA2 | I16: Passed | J16: 46247.708 | K16: QA2 | L16: Passed | M16: 46252.708 | N16: QA2
A17: Message ingestion
A18: TC-INB-005 | B18: Ingest an inbound message through the webhook | C18: 1. POST a valid signed webhook payload to the Pancake webhook endpoint. 2. GET /api/inbox/conversations/{id}. | D18: The message appears in the conversation within a few seconds. | E18: Webhook secret is configured; HMAC signature is valid | F18: Passed | G18: 46245.708 | H18: QA2 | I18: Passed | J18: 46247.708 | K18: QA2 | L18: Passed | M18: 46252.708 | N18: QA2
A19: TC-INB-006 | B19: Reject a webhook payload with an invalid HMAC signature | C19: 1. POST a webhook payload with a tampered x-pancake-signature header. | D19: HTTP 401; the message is not stored. | E19: Webhook secret is configured | F19: Passed | G19: 46245.708 | H19: QA2 | I19: Passed | J19: 46247.708 | K19: QA2 | L19: Passed | M19: 46252.708 | N19: QA2
A20: TC-INB-007 | B20: Ingest a message through polling when the webhook is unavailable | C20: 1. Disable the webhook. 2. Send a message from the channel. 3. Wait for the next polling cycle. | D20: The message is ingested by the polling worker and appears in the inbox. | E20: Polling is enabled and the channel token is valid | F20: Passed | G20: 46245.708 | H20: QA2 | I20: Passed | J20: 46247.708 | K20: QA2 | L20: Passed | M20: 46252.708 | N20: QA2
A21: TC-INB-008 | B21: Deduplicate a message delivered by both webhook and polling | C21: 1. Enable both ingestion paths. 2. Send a single message from the channel. | D21: Exactly one message record is stored. | E21: Both ingestion paths are active | F21: Passed | G21: 46245.708 | H21: QA2 | I21: Passed | J21: 46247.708 | K21: QA2 | L21: Passed | M21: 46252.708 | N21: QA2
A22: TC-INB-009 | B22: Keep the queue intact when the consumer restarts | C22: 1. Stop the RabbitMQ consumer. 2. Send two messages. 3. Start the consumer again. | D22: Both messages are processed after restart; none is lost. | E22: RabbitMQ persistence is enabled | F22: Failed | G22: 46245.708 | H22: QA2 | I22: Passed | J22: 46247.708 | K22: QA2 | L22: Passed | M22: 46252.708 | N22: QA2 | O22: DEF-002 | P22: Round 1: the polling watermark advanced before the acknowledgement, so one message was swallowed when the consumer restarted. Fixed and retested in round 2.
A23: Reply and auto-reply
A24: TC-INB-010 | B24: Send a manual outbound reply | C24: 1. POST /api/inbox/conversations/{id}/messages with a text body. | D24: HTTP 201; reply is delivered to the channel and shown as outbound. | E24: The conversation is open and assigned | F24: Passed | G24: 46246.708 | H24: QA2 | I24: Passed | J24: 46247.708 | K24: QA2 | L24: Passed | M24: 46252.708 | N24: QA2
A25: TC-INB-011 | B25: Auto-reply answers a question covered by the knowledge base | C25: 1. Enable auto-reply via POST /api/inbox/conversations/{id}/ai. 2. Send an inbound message matching a KB topic. | D25: An accurate automatic reply is sent within the SLA window. | E25: Auto-reply is enabled; KB is deployed | F25: Passed | G25: 46246.708 | H25: QA2 | I25: Passed | J25: 46247.708 | K25: QA2 | L25: Passed | M25: 46252.708 | N25: QA2
A26: TC-INB-012 | B26: A manual reply by an agent pauses auto-reply | C26: 1. Confirm auto-reply is enabled. 2. Send a manual reply as an agent. 3. Send a new inbound message immediately. | D26: Auto-reply does not respond during the configured pause window (default 5 min). | E26: Auto-reply is enabled | F26: Passed | G26: 46246.708 | H26: QA2 | I26: Passed | J26: 46247.708 | K26: QA2 | L26: Passed | M26: 46252.708 | N26: QA2
A27: TC-INB-013 | B27: Auto-reply resumes automatically after the pause window elapses | C27: 1. Trigger a pause by sending a manual reply. 2. Advance the clock past the pause window. 3. Send a new inbound message. | D27: Auto-reply answers the new message without manual intervention. | E27: A pause was triggered; the sweep job is running | F27: Passed | G27: 46246.708 | H27: QA2 | I27: Passed | J27: 46247.708 | K27: QA2 | L27: Passed | M27: 46252.708 | N27: QA2
A28: TC-INB-014 | B28: Escalate a conversation disables auto-reply permanently | C28: 1. POST /api/inbox/conversations/{id}/escalate. | D28: Auto-reply is disabled and resume_at is null; conversation is flagged as escalated. | E28: Auto-reply is enabled | F28: Passed | G28: 46246.708 | H28: QA2 | I28: Passed | J28: 46247.708 | K28: QA2 | L28: Passed | M28: 46252.708 | N28: QA2
A29: Draft approval
A30: TC-INB-015 | B30: Approve an AI draft and confirm it is sent | C30: 1. POST /api/inbox/conversations/{id}/drafts/{messageId}/approve. | D30: HTTP 200; draft is sent to the channel; status changes to delivered. | E30: A pending AI draft exists | F30: Passed | G30: 46244.708 | H30: QA2 | I30: Passed | J30: 46247.708 | K30: QA2 | L30: Passed | M30: 46252.708 | N30: QA2
A31: TC-INB-016 | B31: Reject an AI draft so it is not sent | C31: 1. POST /api/inbox/conversations/{id}/drafts/{messageId}/reject. | D31: HTTP 200; draft is discarded; no outbound message is delivered. | E31: A pending AI draft exists | F31: Passed | G31: 46244.708 | H31: QA2 | I31: Passed | J31: 46247.708 | K31: QA2 | L31: Passed | M31: 46252.708 | N31: QA2
A32: Conversation management
A33: TC-INB-017 | B33: Assign a conversation to a different agent | C33: 1. POST /api/inbox/conversations/{id}/assign with a target agentId. | D33: HTTP 200; the new agent sees the conversation in their queue. | E33: A second agent account exists | F33: Passed | G33: 46245.708 | H33: QA2 | I33: Passed | J33: 46247.708 | K33: QA2 | L33: Passed | M33: 46252.708 | N33: QA2
A34: TC-INB-018 | B34: Resolve a conversation | C34: 1. POST /api/inbox/conversations/{id}/resolve. | D34: HTTP 200; status changes to resolved; removed from the open queue. | E34: The conversation is open | F34: Passed | G34: 46245.708 | H34: QA2 | I34: Passed | J34: 46247.708 | K34: QA2 | L34: Passed | M34: 46252.708 | N34: QA2
A35: TC-INB-019 | B35: Search conversations by keyword | C35: 1. GET /api/inbox/search?q={keyword}. | D35: Only conversations whose messages contain the keyword are returned. | E35: Several conversations with varied message content exist | F35: Passed | G35: 46245.708 | H35: QA2 | I35: Passed | J35: 46247.708 | K35: QA2 | L35: Passed | M35: 46252.708 | N35: QA2
A36: TC-INB-020 | B36: Export conversation history to CSV | C36: 1. GET /api/inbox/conversations/{id}/export.csv. | D36: HTTP 200 with Content-Type text/csv; file contains all messages in order. | E36: The conversation has at least one message | F36: Passed | G36: 46245.708 | H36: QA2 | I36: Passed | J36: 46247.708 | K36: QA2 | L36: Passed | M36: 46252.708 | N36: QA2
A37: TC-INB-021 | B37: Filter inbox by channel and status | C37: 1. GET /api/inbox/conversations?channel=facebook&status=open. | D37: Only facebook open conversations are returned. | E37: Mixed conversations exist | F37: Passed | G37: 46246.708 | H37: QA2 | I37: Passed | J37: 46248.708 | K37: QA2 | L37: Passed | M37: 46253.708 | N37: QA2
A38: TC-INB-022 | B38: Paginate conversation messages | C38: 1. GET /api/inbox/conversations/{id}/messages?page=2&pageSize=20. | D38: HTTP 200; page 2 items are distinct from page 1; total is reported. | E38: Conversation has more than 40 messages | F38: Passed | G38: 46246.708 | H38: QA2 | I38: Passed | J38: 46248.708 | K38: QA2 | L38: Passed | M38: 46253.708 | N38: QA2
A39: TC-INB-023 | B39: Add a note to a conversation | C39: 1. POST /api/inbox/conversations/{id}/notes with content. | D39: HTTP 201; note appears in the conversation timeline. | E39: Conversation exists; user has inbox:write | F39: Passed | G39: 46245.708 | H39: QA2 | I39: Passed | J39: 46248.708 | K39: QA2 | L39: Passed | M39: 46253.708 | N39: QA2
A40: TC-INB-024 | B40: Mark messages as read | C40: 1. POST /api/inbox/conversations/{id}/read. | D40: HTTP 200; unread count drops to zero for that conversation. | E40: Conversation has unread messages | F40: Passed | G40: 46246.708 | H40: QA2 | I40: Passed | J40: 46248.708 | K40: QA2 | L40: Passed | M40: 46253.708 | N40: QA2

Sheet Knowledge Base
A2: Feature | B2: Knowledge Base | S2: Passed
A3: Test requirement | B3: KB module management, version creation, content deploy to vector store, rollback, accuracy measurement and auto-approving AI suggestions when accuracy does not decrease | S3: Failed
A4: Number of TCs | B4: =COUNTIF($A$12:$A$1000,"TC-*") -> 11 | S4: Pending
A5: Testing Round | B5: Passed | C5: Failed | D5: Pending | E5: N/A | S5: N/A
A6: Round 1 | B6: =COUNTIF($F10:$F1004,B5) -> 10 | C6: =COUNTIF($F10:$F1004,C5) -> 1 | D6: =COUNTIF($F10:$F1004,D5) -> 0 | E6: =COUNTIF($F10:$F1004,E5) -> 0
A7: Round 2 | B7: =COUNTIF($I10:$I998,B5) -> 11 | C7: =COUNTIF($I10:$I998,C5) -> 0 | D7: =COUNTIF($I10:$I998,D5) -> 0 | E7: =COUNTIF($I10:$I998,E5) -> 0
A8: Round 3 | B8: =COUNTIF($L10:$L998,B5) -> 11 | C8: =COUNTIF($L10:$L998,C5) -> 0 | D8: =COUNTIF($L10:$L998,D5) -> 0 | E8: =COUNTIF($L10:$L998,E5) -> 0
A10: Test Case ID | B10: Test Case Description | C10: Test Case Procedure | D10: Expected Results | E10: Pre-conditions | F10: Round 1 | G10: Test date | H10: Tester | I10: Round 2 | J10: Test date | K10: Tester | L10: Round 3 | M10: Test date | N10: Tester | O10: Defect IDs | P10: Note
A11: Function A
A12: Module management
A13: TC-KB-001 | B13: Create a knowledge base module | C13: 1. POST /api/kb/modules with a name and description. | D13: HTTP 201; module is created with status draft. | E13: User holds kb:write permission | F13: Passed | G13: 46245.708 | H13: QA1 | I13: Passed | J13: 46247.708 | K13: QA1 | L13: Passed | M13: 46252.708 | N13: QA1
A14: TC-KB-002 | B14: Archive a module removes it from retrieval | C14: 1. POST /api/kb/modules/{id}/archive. 2. Ask a question that was answered by that module. | D14: The archived module is excluded from all retrieval results. | E14: Module is deployed and active | F14: Passed | G14: 46245.708 | H14: QA1 | I14: Passed | J14: 46247.708 | K14: QA1 | L14: Passed | M14: 46252.708 | N14: QA1
A15: Version and deployment
A16: TC-KB-003 | B16: Create a new version with Markdown content | C16: 1. POST /api/kb/modules/{id}/versions with contentMd. | D16: HTTP 201; version is created in draft state; chunk count is zero until deployed. | E16: Module exists | F16: Passed | G16: 46246.708 | H16: QA1 | I16: Passed | J16: 46247.708 | K16: QA1 | L16: Passed | M16: 46252.708 | N16: QA1
A17: TC-KB-004 | B17: Deploy a version embeds chunks into the vector store | C17: 1. POST /api/kb/modules/{id}/versions/{versionId}/deploy. 2. Wait for the deploy job to finish. | D17: Chunk count is greater than zero; module status changes to deployed. | E17: A draft version with content exists; Qdrant is reachable | F17: Passed | G17: 46246.708 | H17: QA1 | I17: Passed | J17: 46247.708 | K17: QA1 | L17: Passed | M17: 46252.708 | N17: QA1
A18: TC-KB-005 | B18: Rollback to the previous deployed version | C18: 1. Deploy version 2. 2. POST /api/kb/modules/{id}/versions/{v1id}/rollback. | D18: Version 1 becomes active; retrieval uses version 1 chunks. | E18: At least two deployed versions exist | F18: Passed | G18: 46246.708 | H18: QA1 | I18: Passed | J18: 46247.708 | K18: QA1 | L18: Passed | M18: 46252.708 | N18: QA1
A19: Accuracy and suggestions
A20: TC-KB-006 | B20: Run the accuracy test suite on a deployed version | C20: 1. POST /api/kb/modules/{id}/versions/{versionId}/test. | D20: Each test case is evaluated; an overall accuracy score is returned. | E20: Test cases exist; the version is deployed | F20: Failed | G20: 46245.708 | H20: QA1 | I20: Passed | J20: 46247.708 | K20: QA1 | L20: Passed | M20: 46252.708 | N20: QA1 | O20: DEF-003 | P20: Round 1: the suite scored zero because the deployed version carried no vector data. Fixed and retested in round 2.
A21: TC-KB-007 | B21: Auto-approve a KB suggestion when accuracy does not decrease | C21: 1. Create a suggestion with verdict=approve and accuracy_after >= accuracy_before. 2. Trigger the auto-approve job. | D21: Suggestion is automatically approved and applied without human action. | E21: Auto-approve rail is enabled; suggestion status is pending | F21: Passed | G21: 46245.708 | H21: QA1 | I21: Passed | J21: 46247.708 | K21: QA1 | L21: Passed | M21: 46252.708 | N21: QA1
A22: TC-KB-008 | B22: Hold a KB suggestion for human review when accuracy decreases | C22: 1. Create a suggestion with verdict=approve and accuracy_after < accuracy_before. 2. Trigger the auto-approve job. | D22: Suggestion is NOT auto-approved; stays in pending state waiting for human decision. | E22: Auto-approve rail is enabled; suggestion status is pending | F22: Passed | G22: 46245.708 | H22: QA1 | I22: Passed | J22: 46247.708 | K22: QA1 | L22: Passed | M22: 46252.708 | N22: QA1
A23: TC-KB-009 | B23: List KB modules with pagination | C23: 1. GET /api/kb/modules?page=1&pageSize=20. | D23: HTTP 200; paginated list with total is returned. | E23: At least one module exists | F23: Passed | G23: 46246.708 | H23: QA1 | I23: Passed | J23: 46248.708 | K23: QA1 | L23: Passed | M23: 46253.708 | N23: QA1
A24: TC-KB-010 | B24: Reject KB deploy when vector store is unavailable | C24: 1. Stop Qdrant. 2. POST deploy for a draft version. | D24: Deploy job fails with a vector store error; module stays on the previous version. | E24: A deployed version exists | F24: Passed | G24: 46246.708 | H24: QA1 | I24: Passed | J24: 46248.708 | K24: QA1 | L24: Passed | M24: 46253.708 | N24: QA1
A25: TC-KB-011 | B25: KB suggestion auto-approval requires accuracy not decreased | C25: 1. Create suggestion with accuracy_after == accuracy_before. 2. Trigger auto-approval. | D25: Suggestion is approved automatically. | E25: KB learning rail is enabled | F25: Passed | G25: 46246.708 | H25: QA1 | I25: Passed | J25: 46248.708 | K25: QA1 | L25: Passed | M25: 46253.708 | N25: QA1

Sheet Lead Management
A2: Feature | B2: Lead Management | S2: Passed
A3: Test requirement | B3: Lead CRUD, pipeline stage transitions driven by score, manual stage override, scoring rule management, lead assignment and activity feed | S3: Failed
A4: Number of TCs | B4: =COUNTIF($A$12:$A$1000,"TC-*") -> 12 | S4: Pending
A5: Testing Round | B5: Passed | C5: Failed | D5: Pending | E5: N/A | S5: N/A
A6: Round 1 | B6: =COUNTIF($F10:$F1005,B5) -> 11 | C6: =COUNTIF($F10:$F1005,C5) -> 1 | D6: =COUNTIF($F10:$F1005,D5) -> 0 | E6: =COUNTIF($F10:$F1005,E5) -> 0
A7: Round 2 | B7: =COUNTIF($I10:$I998,B5) -> 12 | C7: =COUNTIF($I10:$I998,C5) -> 0 | D7: =COUNTIF($I10:$I998,D5) -> 0 | E7: =COUNTIF($I10:$I998,E5) -> 0
A8: Round 3 | B8: =COUNTIF($L10:$L998,B5) -> 12 | C8: =COUNTIF($L10:$L998,C5) -> 0 | D8: =COUNTIF($L10:$L998,D5) -> 0 | E8: =COUNTIF($L10:$L998,E5) -> 0
A10: Test Case ID | B10: Test Case Description | C10: Test Case Procedure | D10: Expected Results | E10: Pre-conditions | F10: Round 1 | G10: Test date | H10: Tester | I10: Round 2 | J10: Test date | K10: Tester | L10: Round 3 | M10: Test date | N10: Tester | O10: Defect IDs | P10: Note
A11: Function A
A12: Lead CRUD
A13: TC-LM-001 | B13: Create a lead from a contact | C13: 1. POST /api/leads with contactId, source and assignedTo. | D13: HTTP 201; lead is created with stage=cold; initial score is 0. | E13: A contact exists; user holds leads:write permission | F13: Passed | G13: 46245.708 | H13: QA2 | I13: Passed | J13: 46248.708 | K13: QA2 | L13: Passed | M13: 46253.708 | N13: QA2
A14: TC-LM-002 | B14: List leads with pagination and stage filter | C14: 1. GET /api/leads?stage=warm&page=1&pageSize=20. | D14: HTTP 200; only leads with stage=warm are returned; pagination metadata is present. | E14: Multiple leads exist across different stages | F14: Failed | G14: 46245.708 | H14: QA2 | I14: Passed | J14: 46248.708 | K14: QA2 | L14: Passed | M14: 46253.708 | N14: QA2 | O14: DEF-004 | P14: Round 1: the owner filter returned an empty page for a sales account because the conversation carried no inbox. Fixed and retested in round 2.
A15: TC-LM-003 | B15: Assign a lead to another sales agent | C15: 1. POST /api/leads/{id}/assign with the target agentId. | D15: HTTP 200; assignedTo is updated; the new agent sees the lead in their queue. | E15: A second agent account exists | F15: Passed | G15: 46245.708 | H15: QA2 | I15: Passed | J15: 46248.708 | K15: QA2 | L15: Passed | M15: 46253.708 | N15: QA2
A16: Lead scoring and stage
A17: TC-LM-004 | B17: Score increases when a purchase_intent activity is recorded | C17: 1. POST /api/leads/{id}/activities with eventCode=purchase_intent. | D17: Lead score increases by the purchase_intent delta (default +20); stage may advance to hot. | E17: Lead scoring rules are seeded; lead is cold | F17: Passed | G17: 46246.708 | H17: QA2 | I17: Passed | J17: 46248.708 | K17: QA2 | L17: Passed | M17: 46253.708 | N17: QA2
A18: TC-LM-005 | B18: Pipeline stage advances automatically when the score threshold is crossed | C18: 1. Record activities until the score reaches 70. 2. GET /api/leads/{id}. | D18: stage=hot (score >= 70); previous warm stage is no longer shown. | E18: Lead scoring rules give enough delta per event | F18: Passed | G18: 46246.708 | H18: QA2 | I18: Passed | J18: 46248.708 | K18: QA2 | L18: Passed | M18: 46253.708 | N18: QA2
A19: TC-LM-006 | B19: Re-score a lead using the latest rules | C19: 1. POST /api/leads/{id}/rescore. | D19: HTTP 200; score is recalculated using the current rule set; stage is updated accordingly. | E19: Lead scoring rules have been modified since the lead was created | F19: Passed | G19: 46246.708 | H19: QA2 | I19: Passed | J19: 46248.708 | K19: QA2 | L19: Passed | M19: 46253.708 | N19: QA2
A20: TC-LM-007 | B20: A lost lead is reactivated when new inbound activity arrives | C20: 1. Mark the lead as lost. 2. POST /api/leads/{id}/activities with any inbound event. | D20: Lead status changes from lost to active; LastActivityAt is updated. | E20: A lost lead exists | F20: Passed | G20: 46246.708 | H20: QA2 | I20: Passed | J20: 46248.708 | K20: QA2 | L20: Passed | M20: 46253.708 | N20: QA2
A21: Scoring rule management
A22: TC-LM-008 | B22: Seed default scoring rules for a tenant | C22: 1. POST /api/lead-scoring-rules/seed-defaults. | D22: HTTP 200; default rules are created (asked_price, purchase_intent, fast_reply etc.); each has the correct default delta. | E22: No rules exist for the tenant yet | F22: Passed | G22: 46245.708 | H22: QA2 | I22: Passed | J22: 46248.708 | K22: QA2 | L22: Passed | M22: 46253.708 | N22: QA2
A23: TC-LM-009 | B23: Create a platform-specific rule that overrides the platform-null rule | C23: 1. POST /api/lead-scoring-rules with eventCode=asked_price and platform=facebook and delta=15. 2. Record asked_price on a facebook conversation. | D23: The facebook-specific rule (delta=15) is used instead of the platform-null rule (delta=9). | E23: A platform-null asked_price rule already exists | F23: Passed | G23: 46245.708 | H23: QA2 | I23: Passed | J23: 46248.708 | K23: QA2 | L23: Passed | M23: 46253.708 | N23: QA2
A24: TC-LM-010 | B24: Delete a draft lead before conversion | C24: 1. POST /api/leads then DELETE /api/leads/{id}. | D24: HTTP 204; lead no longer appears in list. | E24: Lead exists and is not yet assigned | F24: Passed | G24: 46246.708 | H24: QA2 | I24: Passed | J24: 46248.708 | K24: QA2 | L24: Passed | M24: 46253.708 | N24: QA2
A25: TC-LM-011 | B25: Record multiple activities and verify cumulative score | C25: 1. POST three activities with different eventCodes. 2. GET /api/leads/{id}. | D25: Score equals sum of deltas; stage reflects the summed score. | E25: Scoring rules seeded | F25: Passed | G25: 46246.708 | H25: QA2 | I25: Passed | J25: 46248.708 | K25: QA2 | L25: Passed | M25: 46253.708 | N25: QA2
A26: TC-LM-012 | B26: Manual stage override does not change score | C26: 1. POST /api/leads/{id}/stage with stage=warm. | D26: Stage becomes warm while score is unchanged. | E26: Lead is cold with score 10 | F26: Passed | G26: 46246.708 | H26: QA2 | I26: Passed | J26: 46248.708 | K26: QA2 | L26: Passed | M26: 46253.708 | N26: QA2

Sheet Content Pipeline
A2: Feature | B2: Content Pipeline | S2: Passed
A3: Test requirement | B3: Brief management, AI content generation, review gate, human approval, scheduling and publishing lifecycle for social media posts | S3: Failed
A4: Number of TCs | B4: =COUNTIF($A$12:$A$1000,"TC-*") -> 11 | S4: Pending
A5: Testing Round | B5: Passed | C5: Failed | D5: Pending | E5: N/A | S5: N/A
A6: Round 1 | B6: =COUNTIF($F10:$F1004,B5) -> 10 | C6: =COUNTIF($F10:$F1004,C5) -> 1 | D6: =COUNTIF($F10:$F1004,D5) -> 0 | E6: =COUNTIF($F10:$F1004,E5) -> 0
A7: Round 2 | B7: =COUNTIF($I10:$I998,B5) -> 11 | C7: =COUNTIF($I10:$I998,C5) -> 0 | D7: =COUNTIF($I10:$I998,D5) -> 0 | E7: =COUNTIF($I10:$I998,E5) -> 0
A8: Round 3 | B8: =COUNTIF($L10:$L998,B5) -> 11 | C8: =COUNTIF($L10:$L998,C5) -> 0 | D8: =COUNTIF($L10:$L998,D5) -> 0 | E8: =COUNTIF($L10:$L998,E5) -> 0
A10: Test Case ID | B10: Test Case Description | C10: Test Case Procedure | D10: Expected Results | E10: Pre-conditions | F10: Round 1 | G10: Test date | H10: Tester | I10: Round 2 | J10: Test date | K10: Tester | L10: Round 3 | M10: Test date | N10: Tester | O10: Defect IDs | P10: Note
A11: Function A
A12: Brief and generation
A13: TC-CP-001 | B13: Create a content brief | C13: 1. POST /api/content/briefs with platform, topic and target audience. | D13: HTTP 201; brief is created in draft state. | E13: User holds content:write permission | F13: Passed | G13: 46246.708 | H13: QA1 | I13: Passed | J13: 46248.708 | K13: QA1 | L13: Passed | M13: 46253.708 | N13: QA1
A14: TC-CP-002 | B14: Generate a content item from a brief | C14: 1. POST /api/content/items/generate with briefId. | D14: HTTP 202; a background job is queued; polling shows the item transitions to draft with a non-empty body. | E14: A brief exists; LLM provider is configured | F14: Passed | G14: 46246.708 | H14: QA1 | I14: Passed | J14: 46248.708 | K14: QA1 | L14: Passed | M14: 46253.708 | N14: QA1
A15: TC-CP-003 | B15: Generation is blocked when the body contains an absolute guarantee phrase | C15: 1. Configure the LLM stub to return a body that contains an absolute-guarantee phrase. 2. Trigger generation. | D15: The content lint step fails; item status becomes needs_human with ErrorCode=lint_absolute_guarantee. | E15: ContentLint is enabled; LLM stub is available | F15: Passed | G15: 46246.708 | H15: QA1 | I15: Passed | J15: 46248.708 | K15: QA1 | L15: Passed | M15: 46253.708 | N15: QA1
A16: Review and approval
A17: TC-CP-004 | B17: Agent review passes and item moves to approved | C17: 1. Wait for the AI reviewer agent to process the draft item. | D17: AgentReviewStatus=passed; item is eligible for human approval or auto-publish depending on policy. | E17: A reviewer agent is configured and bound to an LLM | F17: Failed | G17: 46247.708 | H17: QA1 | I17: Passed | J17: 46248.708 | K17: QA1 | L17: Passed | M17: 46253.708 | N17: QA1 | O17: DEF-005 | P17: Round 1: a retry of the review returned HTTP 500 because the unique index was not filtered on the soft-delete column. Fixed and retested in round 2.
A18: TC-CP-005 | B18: Human approves an item that requires human review | C18: 1. POST /api/content/items/{id}/approve. | D18: HTTP 200; item status=approved; ApprovedAt and ApprovedBy are set. | E18: Item is in needs_human state with agent review passed | F18: Passed | G18: 46247.708 | H18: QA1 | I18: Passed | J18: 46248.708 | K18: QA1 | L18: Passed | M18: 46253.708 | N18: QA1
A19: TC-CP-006 | B19: Human rejects an item with a reason | C19: 1. POST /api/content/items/{id}/reject with a reason string. | D19: HTTP 200; item status=rejected; RejectedReason is stored. | E19: Item is in draft or needs_human state | F19: Passed | G19: 46247.708 | H19: QA1 | I19: Passed | J19: 46248.708 | K19: QA1 | L19: Passed | M19: 46253.708 | N19: QA1
A20: Scheduling and publishing
A21: TC-CP-007 | B21: Schedule an approved item for a future golden-hour slot | C21: 1. POST /api/content/items/{id}/schedule with a future publishAt timestamp. | D21: HTTP 200; item status=scheduled; publishAt is stored. | E21: Item is approved | F21: Passed | G21: 46246.708 | H21: QA1 | I21: Passed | J21: 46248.708 | K21: QA1 | L21: Passed | M21: 46253.708 | N21: QA1
A22: TC-CP-008 | B22: Repurpose a published item for a different platform | C22: 1. POST /api/content/items/{id}/repurpose with targetPlatform. | D22: HTTP 202; a new draft item is created for the target platform; the original item is unchanged. | E22: The item has been published; a brief exists for the target platform | F22: Passed | G22: 46246.708 | H22: QA1 | I22: Passed | J22: 46248.708 | K22: QA1 | L22: Passed | M22: 46253.708 | N22: QA1
A23: TC-CP-009 | B23: List content items with status filter | C23: 1. GET /api/content/items?status=draft. | D23: Only draft items are returned. | E23: Mixed items exist | F23: Passed | G23: 46247.708 | H23: QA1 | I23: Passed | J23: 46248.708 | K23: QA1 | L23: Passed | M23: 46253.708 | N23: QA1
A24: TC-CP-010 | B24: Delete a draft item | C24: 1. DELETE /api/content/items/{id}. | D24: HTTP 204; item no longer listed. | E24: Draft item exists | F24: Passed | G24: 46247.708 | H24: QA1 | I24: Passed | J24: 46248.708 | K24: QA1 | L24: Passed | M24: 46253.708 | N24: QA1
A25: TC-CP-011 | B25: Regenerate a rejected item | C25: 1. POST /api/content/items/{id}/regenerate with revised brief. | D25: HTTP 202; new draft job is queued; status returns to queued. | E25: Item is rejected | F25: Passed | G25: 46247.708 | H25: QA1 | I25: Passed | J25: 46248.708 | K25: QA1 | L25: Passed | M25: 46253.708 | N25: QA1

Sheet Agent Orchestration
A2: Feature | B2: Agent Orchestration | S2: Passed
A3: Test requirement | B3: Create and run orchestration sessions, pause for manual intervention, resume after approval, manage recurring schedules and verify agent tool grants | S3: Failed
A4: Number of TCs | B4: =COUNTIF($A$12:$A$1000,"TC-*") -> 11 | S4: Pending
A5: Testing Round | B5: Passed | C5: Failed | D5: Pending | E5: N/A | S5: N/A
A6: Round 1 | B6: =COUNTIF($F10:$F1004,B5) -> 10 | C6: =COUNTIF($F10:$F1004,C5) -> 1 | D6: =COUNTIF($F10:$F1004,D5) -> 0 | E6: =COUNTIF($F10:$F1004,E5) -> 0
A7: Round 2 | B7: =COUNTIF($I10:$I998,B5) -> 11 | C7: =COUNTIF($I10:$I998,C5) -> 0 | D7: =COUNTIF($I10:$I998,D5) -> 0 | E7: =COUNTIF($I10:$I998,E5) -> 0
A8: Round 3 | B8: =COUNTIF($L10:$L998,B5) -> 11 | C8: =COUNTIF($L10:$L998,C5) -> 0 | D8: =COUNTIF($L10:$L998,D5) -> 0 | E8: =COUNTIF($L10:$L998,E5) -> 0
A10: Test Case ID | B10: Test Case Description | C10: Test Case Procedure | D10: Expected Results | E10: Pre-conditions | F10: Round 1 | G10: Test date | H10: Tester | I10: Round 2 | J10: Test date | K10: Tester | L10: Round 3 | M10: Test date | N10: Tester | O10: Defect IDs | P10: Note
A11: Function A
A12: Session lifecycle
A13: TC-ORC-001 | B13: Create and start an orchestration run | C13: 1. POST /api/orchestration/runs with a planId. 2. Poll GET /api/orchestration/runs/{id} until status=running. | D13: Run transitions from queued to running; agent tasks begin executing. | E13: A plan exists; agents are bound to LLM providers | F13: Passed | G13: 46246.708 | H13: QA2 | I13: Passed | J13: 46248.708 | K13: QA2 | L13: Passed | M13: 46253.708 | N13: QA2
A14: TC-ORC-002 | B14: Pause a running session for manual intervention | C14: 1. POST /api/orchestration/runs/{id}/pause. | D14: HTTP 200; run status=paused; no new tasks are started. | E14: A run is in running status | F14: Passed | G14: 46246.708 | H14: QA2 | I14: Passed | J14: 46248.708 | K14: QA2 | L14: Passed | M14: 46253.708 | N14: QA2
A15: TC-ORC-003 | B15: Intervene by editing a task output then resume the run | C15: 1. POST /api/orchestration/runs/{id}/intervene with an edited taskId and new output. 2. POST /api/orchestration/runs/{id}/resume. | D15: HTTP 200; the run resumes with the edited output; downstream tasks use the corrected data. | E15: Run is paused | F15: Passed | G15: 46246.708 | H15: QA2 | I15: Passed | J15: 46248.708 | K15: QA2 | L15: Passed | M15: 46253.708 | N15: QA2
A16: TC-ORC-004 | B16: Cancel a running session | C16: 1. POST /api/orchestration/runs/{id}/cancel. | D16: HTTP 200; run status=cancelled; all pending tasks are marked skipped. | E16: A run is in running or paused status | F16: Passed | G16: 46246.708 | H16: QA2 | I16: Passed | J16: 46248.708 | K16: QA2 | L16: Passed | M16: 46253.708 | N16: QA2
A17: Schedules
A18: TC-ORC-005 | B18: Create a recurring weekly schedule | C18: 1. POST /api/orchestration/schedules with cadence=weekly and a valid timezone. | D18: HTTP 201; schedule is created; nextRunAt is set to the correct window in the given timezone. | E18: A plan exists | F18: Passed | G18: 46247.708 | H18: QA2 | I18: Passed | J18: 46248.708 | K18: QA2 | L18: Passed | M18: 46253.708 | N18: QA2
A19: TC-ORC-006 | B19: Pause and reactivate a schedule | C19: 1. POST /api/orchestration/schedules/{id}/pause. 2. POST /api/orchestration/schedules/{id}/activate. | D19: Pause: status=paused, no new runs are triggered. Activate: status=active, nextRunAt is recalculated. | E19: An active schedule exists | F19: Passed | G19: 46247.708 | H19: QA2 | I19: Passed | J19: 46248.708 | K19: QA2 | L19: Passed | M19: 46253.708 | N19: QA2
A20: Agent tool grants
A21: TC-ORC-007 | B21: An agent without tool grants cannot call restricted tools | C21: 1. Create an agent definition with no tool grants. 2. Start a run that requires a restricted tool. | D21: The tool call is blocked; the agent task fails with a permission error; the run does not crash. | E21: A restricted tool exists in the tool registry | F21: Failed | G21: 46246.708 | H21: QA2 | I21: Passed | J21: 46248.708 | K21: QA2 | L21: Passed | M21: 46253.708 | N21: QA2 | O21: DEF-006 | P21: Round 1: an empty tool grant produced a text-only completion reported as success instead of an explicit refusal. Fixed and retested in round 2.
A22: TC-ORC-008 | B22: Grant a tool to an agent and confirm the tool call succeeds | C22: 1. POST /api/orchestration/agents/{id}/grants with the tool name. 2. Restart the run. | D22: The tool call succeeds; the run completes the task. | E22: TC-ORC-007 has been completed | F22: Passed | G22: 46246.708 | H22: QA2 | I22: Passed | J22: 46248.708 | K22: QA2 | L22: Passed | M22: 46253.708 | N22: QA2
A23: TC-ORC-009 | B23: List orchestration runs with pagination | C23: 1. GET /api/orchestration/runs?page=1&pageSize=20. | D23: HTTP 200; paginated list with total is returned. | E23: At least one run exists | F23: Passed | G23: 46247.708 | H23: QA2 | I23: Passed | J23: 46248.708 | K23: QA2 | L23: Passed | M23: 46253.708 | N23: QA2
A24: TC-ORC-010 | B24: Get run detail with tasks | C24: 1. GET /api/orchestration/runs/{id}. | D24: HTTP 200; tasks array is present with status per task. | E24: A running or completed run exists | F24: Passed | G24: 46247.708 | H24: QA2 | I24: Passed | J24: 46248.708 | K24: QA2 | L24: Passed | M24: 46253.708 | N24: QA2
A25: TC-ORC-011 | B25: Schedule next run is in the correct timezone | C25: 1. Create a schedule with timezone Asia/Ho_Chi_Minh and cron 0 8 * * MON. | D25: nextRunAt is Monday 08:00 in the given timezone. | E25: Plan exists | F25: Passed | G25: 46247.708 | H25: QA2 | I25: Passed | J25: 46248.708 | K25: QA2 | L25: Passed | M25: 46253.708 | N25: QA2

Sheet Documents & Reports
A2: Feature | B2: Documents & Reports | S2: Passed
A3: Test requirement | B3: Document generation (quote PDF, brochure), document library per contact, and report/analytics export | S3: Failed
A4: Number of TCs | B4: =COUNTIF($A$12:$A$1000,"TC-*") -> 8 | S4: Pending
A5: Testing Round | B5: Passed | C5: Failed | D5: Pending | E5: N/A | S5: N/A
A6: Round 1 | B6: =COUNTIF($F10:$F1000,B5) -> 7 | C6: =COUNTIF($F10:$F1000,C5) -> 1 | D6: =COUNTIF($F10:$F1000,D5) -> 0 | E6: =COUNTIF($F10:$F1000,E5) -> 0
A7: Round 2 | B7: =COUNTIF($I10:$I998,B5) -> 8 | C7: =COUNTIF($I10:$I998,C5) -> 0 | D7: =COUNTIF($I10:$I998,D5) -> 0 | E7: =COUNTIF($I10:$I998,E5) -> 0
A8: Round 3 | B8: =COUNTIF($L10:$L998,B5) -> 8 | C8: =COUNTIF($L10:$L998,C5) -> 0 | D8: =COUNTIF($L10:$L998,D5) -> 0 | E8: =COUNTIF($L10:$L998,E5) -> 0
A10: Test Case ID | B10: Test Case Description | C10: Test Case Procedure | D10: Expected Results | E10: Pre-conditions | F10: Round 1 | G10: Test date | H10: Tester | I10: Round 2 | J10: Test date | K10: Tester | L10: Round 3 | M10: Test date | N10: Tester | O10: Defect IDs | P10: Note
A11: Function A
A12: Document generation
A13: TC-DOC-001 | B13: Generate a quote PDF from conversation context | C13: 1. POST /api/documents/generate with contactId and templateId=quote. 2. Poll until status=ready. | D13: HTTP 202 then ready; the PDF contains the contact name and the discussed package. | E13: Conversation has an identifiable contact and a proposed package | F13: Passed | G13: 46247.708 | H13: QA1 | I13: Passed | J13: 46249.708 | K13: QA1 | L13: Passed | M13: 46253.708 | N13: QA1
A14: TC-DOC-002 | B14: Reject document generation with a missing template | C14: 1. POST /api/documents/generate with templateId=does-not-exist. | D14: HTTP 404; no document row is persisted. | E14: None | F14: Passed | G14: 46247.708 | H14: QA1 | I14: Passed | J14: 46249.708 | K14: QA1 | L14: Passed | M14: 46253.708 | N14: QA1
A15: TC-DOC-003 | B15: List documents created for a contact | C15: 1. GET /api/documents?contactId={id}. | D15: HTTP 200; only documents for that contact are returned, newest first. | E15: At least two documents exist for two different contacts | F15: Passed | G15: 46248.708 | H15: QA1 | I15: Passed | J15: 46249.708 | K15: QA1 | L15: Passed | M15: 46253.708 | N15: QA1
A16: TC-DOC-004 | B16: Send a generated document through the active channel | C16: 1. POST /api/documents/{id}/send with channel=zalo. | D16: HTTP 200; SentVia and a timestamp are recorded; the document link is delivered to the conversation. | E16: A ready document exists; the conversation channel is connected | F16: Passed | G16: 46248.708 | H16: QA1 | I16: Passed | J16: 46249.708 | K16: QA1 | L16: Passed | M16: 46253.708 | N16: QA1
A17: TC-DOC-005 | B17: Document link expires after the configured window | C17: 1. Generate a document. 2. Advance time past the link expiry (7 days). 3. Open the stored link. | D17: The link returns HTTP 410 or an expired-link page; the file is not streamed. | E17: A document with a 7-day expiry exists | F17: Failed | G17: 46248.708 | H17: QA1 | I17: Passed | J17: 46249.708 | K17: QA1 | L17: Passed | M17: 46253.708 | N17: QA1 | O17: DEF-007 | P17: Round 1: the expiry check compared UTC to a local timestamp so links stayed valid two extra hours. Fixed and retested in round 2.
A18: Reporting and analytics
A19: TC-DOC-006 | B19: Export a KPI report to CSV for a date range | C19: 1. GET /api/reports/kpi/export?from=2026-08-01&to=2026-08-20&format=csv. | D19: HTTP 200 with Content-Type text/csv; row count matches the date range. | E19: kpi_daily rows exist for the range | F19: Passed | G19: 46249.708 | H19: QA1 | I19: Passed | J19: 46249.708 | K19: QA1 | L19: Passed | M19: 46253.708 | N19: QA1
A20: TC-DOC-007 | B20: Analytics dashboard aggregates leads by channel | C20: 1. GET /api/analytics/omnichannel?from=2026-08-01&to=2026-08-20. | D20: HTTP 200; totals per channel sum to the overall total with no double counting. | E20: Leads exist across at least three channels | F20: Passed | G20: 46250.708 | H20: QA1 | I20: Passed | J20: 46249.708 | K20: QA1 | L20: Passed | M20: 46253.708 | N20: QA1
A21: TC-DOC-008 | B21: Schedule a recurring weekly report | C21: 1. POST /api/reports/schedule with cadence=weekly and a recipient list. | D21: HTTP 201; the schedule is created; nextRunAt is set to the next matching weekday. | E21: At least one report template exists | F21: Passed | G21: 46250.708 | H21: QA1 | I21: Passed | J21: 46249.708 | K21: QA1 | L21: Passed | M21: 46253.708 | N21: QA1

Sheet Admin & RBAC
A2: Feature | B2: Admin & RBAC | S2: Passed
A3: Test requirement | B3: User management, role-permission assignment, API key issuance/revocation and audit logging for privileged actions | S3: Failed
A4: Number of TCs | B4: =COUNTIF($A$12:$A$1000,"TC-*") -> 8 | S4: Pending
A5: Testing Round | B5: Passed | C5: Failed | D5: Pending | E5: N/A | S5: N/A
A6: Round 1 | B6: =COUNTIF($F10:$F1000,B5) -> 7 | C6: =COUNTIF($F10:$F1000,C5) -> 1 | D6: =COUNTIF($F10:$F1000,D5) -> 0 | E6: =COUNTIF($F10:$F1000,E5) -> 0
A7: Round 2 | B7: =COUNTIF($I10:$I998,B5) -> 8 | C7: =COUNTIF($I10:$I998,C5) -> 0 | D7: =COUNTIF($I10:$I998,D5) -> 0 | E7: =COUNTIF($I10:$I998,E5) -> 0
A8: Round 3 | B8: =COUNTIF($L10:$L998,B5) -> 8 | C8: =COUNTIF($L10:$L998,C5) -> 0 | D8: =COUNTIF($L10:$L998,D5) -> 0 | E8: =COUNTIF($L10:$L998,E5) -> 0
A10: Test Case ID | B10: Test Case Description | C10: Test Case Procedure | D10: Expected Results | E10: Pre-conditions | F10: Round 1 | G10: Test date | H10: Tester | I10: Round 2 | J10: Test date | K10: Tester | L10: Round 3 | M10: Test date | N10: Tester | O10: Defect IDs | P10: Note
A11: Function A
A12: User and role management
A13: TC-ADM-001 | B13: Create a new staff user with a role | C13: 1. POST /api/admin/users with email, name and roleId. | D13: HTTP 201; user is created; an invitation email is queued. | E13: The role exists; the caller holds users:write | F13: Passed | G13: 46246.708 | H13: QA1 | I13: Passed | J13: 46249.708 | K13: QA1 | L13: Passed | M13: 46253.708 | N13: QA1
A14: TC-ADM-002 | B14: Change a user's role revokes the old permission set | C14: 1. PUT /api/admin/users/{id}/role with a new roleId. 2. Call an endpoint gated by the old role's permission. | D14: The old permission is no longer granted; the new role's permissions apply immediately. | E14: User currently holds a role with at least one permission the new role lacks | F14: Passed | G14: 46246.708 | H14: QA1 | I14: Passed | J14: 46249.708 | K14: QA1 | L14: Passed | M14: 46253.708 | N14: QA1
A15: TC-ADM-003 | B15: Deactivate a user blocks sign-in | C15: 1. POST /api/admin/users/{id}/deactivate. 2. Attempt to sign in as that user. | D15: Sign-in returns HTTP 403; existing sessions are also rejected on the next request. | E15: User account is active | F15: Passed | G15: 46247.708 | H15: QA1 | I15: Passed | J15: 46249.708 | K15: QA1 | L15: Passed | M15: 46253.708 | N15: QA1
A16: TC-ADM-004 | B16: Create a custom role with a specific permission set | C16: 1. POST /api/roles with name and a list of permission codes. | D16: HTTP 201; role is created; a user assigned this role gets exactly those permissions. | E16: Permission codes exist in the catalog | F16: Passed | G16: 46247.708 | H16: QA1 | I16: Passed | J16: 46249.708 | K16: QA1 | L16: Passed | M16: 46253.708 | N16: QA1
A17: API keys and audit
A18: TC-ADM-005 | B18: Issue an API key scoped to read-only | C18: 1. POST /api/api-keys with scope=read. 2. Call a write endpoint with the key. | D18: The write call is rejected with HTTP 403; a read call with the same key succeeds. | E18: Caller holds api-keys:write | F18: Failed | G18: 46248.708 | H18: QA1 | I18: Passed | J18: 46249.708 | K18: QA1 | L18: Passed | M18: 46253.708 | N18: QA1 | O18: DEF-008 | P18: Round 1: the scope check only ran on endpoints tagged explicitly, so an untagged write endpoint accepted the read-only key. Fixed and retested in round 2.
A19: TC-ADM-006 | B19: Revoke an API key immediately invalidates it | C19: 1. POST /api/api-keys/{id}/revoke. 2. Call any endpoint with the revoked key. | D19: HTTP 401 on the next call; no grace period. | E19: An active API key exists | F19: Passed | G19: 46249.708 | H19: QA1 | I19: Passed | J19: 46249.708 | K19: QA1 | L19: Passed | M19: 46253.708 | N19: QA1
A20: TC-ADM-007 | B20: Privileged action writes an audit row | C20: 1. Perform a role change, a deactivation and an API key revoke as an admin. 2. GET /api/admin/audit. | D20: Each action appears with actor, target, action type and timestamp. | E20: Caller holds audit:read | F20: Passed | G20: 46250.708 | H20: QA1 | I20: Passed | J20: 46249.708 | K20: QA1 | L20: Passed | M20: 46253.708 | N20: QA1
A21: TC-ADM-008 | B21: Login history lists recent sign-ins for a user | C21: 1. Sign in three times across two days. 2. GET /api/admin/users/{id}/login-history. | D21: HTTP 200; three entries are returned with timestamp and source address, newest first. | E21: Caller holds users:read | F21: Passed | G21: 46250.708 | H21: QA1 | I21: Passed | J21: 46249.708 | K21: QA1 | L21: Passed | M21: 46253.708 | N21: QA1

Sheet Notifications & Labels
A2: Feature | B2: Notifications & Labels | S2: Passed
A3: Test requirement | B3: In-app notification delivery, per-channel notification preferences, conversation labels and internal notes | S3: Failed
A4: Number of TCs | B4: =COUNTIF($A$12:$A$1000,"TC-*") -> 8 | S4: Pending
A5: Testing Round | B5: Passed | C5: Failed | D5: Pending | E5: N/A | S5: N/A
A6: Round 1 | B6: =COUNTIF($F10:$F1000,B5) -> 8 | C6: =COUNTIF($F10:$F1000,C5) -> 0 | D6: =COUNTIF($F10:$F1000,D5) -> 0 | E6: =COUNTIF($F10:$F1000,E5) -> 0
A7: Round 2 | B7: =COUNTIF($I10:$I998,B5) -> 8 | C7: =COUNTIF($I10:$I998,C5) -> 0 | D7: =COUNTIF($I10:$I998,D5) -> 0 | E7: =COUNTIF($I10:$I998,E5) -> 0
A8: Round 3 | B8: =COUNTIF($L10:$L998,B5) -> 8 | C8: =COUNTIF($L10:$L998,C5) -> 0 | D8: =COUNTIF($L10:$L998,D5) -> 0 | E8: =COUNTIF($L10:$L998,E5) -> 0
A10: Test Case ID | B10: Test Case Description | C10: Test Case Procedure | D10: Expected Results | E10: Pre-conditions | F10: Round 1 | G10: Test date | H10: Tester | I10: Round 2 | J10: Test date | K10: Tester | L10: Round 3 | M10: Test date | N10: Tester | O10: Defect IDs | P10: Note
A11: Function A
A12: Notifications
A13: TC-NTF-001 | B13: Escalating a conversation notifies the owning sale user | C13: 1. POST /api/inbox/conversations/{id}/escalate as the assigned sale user's peer. | D13: A notification row is created for the owner within a few seconds; unread count increases. | E13: Conversation has an assigned owner | F13: Passed | G13: 46247.708 | H13: QA2 | I13: Passed | J13: 46249.708 | K13: QA1 | L13: Passed | M13: 46253.708 | N13: QA1
