Workbook
Name ACTION: #REF!

Sheet Guideline
A1: Guideline to make and understand Unit Test Case
A3: 1. Overview
A4: - In the template, Unit test cases are based on functions. Each sheet presents test cases for one function.
A5: - Cover: General information of the project and Unit Test cases
A6: - FunctionList: The list of Classes and Functions in the document. + To control that the number of Unit TC meets customer's requirement or the norm, user should fill value for 'Normal number of Test cases/KLOC'.
A7: + Click on Function link to open the related Test cases of the function. Note: You should create new Function sheet before creating the link
A8: - Test Report: provive the overview results of Functions Unit test: Test coverage, Test successful coverage (Summary, for normal/abnormal/boundary cases)
A9: Note: Should check the formula of "Sub Total" if you add more functions
A11: 2. Content in Test function sheet
A12: 2.1 Combination of test cases.
A13: - To verify that number of Unit TC meets customer's requirement or not. User has to fill number LOC of tested function and fill value of 'Normal number test cases/KLOC' item in FunctionList sheet, which is required by customer or normal value. The number of lacked TC is shown in 'Lack of test cases' item.
A14: - If the number of Unit TC does not meet the requirement, creator should explain the reasons.
... A46: - Test requirement: Brief description about requirements which are tested in this function, it is not mandatory.

Sheet Cover
B2: UNIT TEST DOCUMENT
A4: Project Name | B4: Clawbot | E4: Creator | F4: <Creator>
A5: Project Code | B5: CLAWBOT | E5: Issue Date | F5: 46244.708
A6: Document Code | B6: =B5&"_"&"XXX"&"_"&"vx.x" -> CLAWBOT_XXX_vx.x | E6: Version | F6: v1.0
A9: Record of change
A10: Effective Date | B10: Version | C10: Change Item | D10: *A,D,M | E10: Change description | F10: Reference
A11: 46244.708 | B11: v1.0 | C11: Unit Test Report | D11: A | E11: Initial version

Sheet MethodList
C2: Method List
A4: Project Name | C4: =Cover!B4 -> Clawbot
A5: Project Code | C5: =Cover!B5 -> CLAWBOT
A6: Test Environment Setup Description | C6: 1. Windows 11 + .NET 8 SDK 2. SQL Server 2022 (Docker :1433) 3. Redis 7 (Docker :6379) 4. xUnit + FluentAssertions 5. Moq (DNS stub via LlmBaseUrlGuard.ResolveHostAddresses test seam)
A8: No | B8: Module Name | C8: Method Name | D8: Sheet Name | E8: Description | F8: Pre-Condition
A9: 1 | B9: Clawbot.Agents.Core.Chat | C9: LlmBaseUrlGuard.IsAllowedBaseUrl | D9: IsAllowedBaseUrl | E9: Validate a base URL before an outbound HttpClient is created for an LLM provider | F9: The DNS test seam (LlmBaseUrlGuard.ResolveHostAddresses) is replaced with a stub in test setup
A10: 2 | B10: Clawbot.Infrastructure.Security | C10: AesEncryptor.ParseKey (constructor validation) | D10: NormalizeApiKey | E10: Validate the Encryption:Base64Key option when AesEncryptor is constructed via DI | F10: AesEncryptor is constructed directly using OptionsWrapper<EncryptionOptions>
A11: 3 | B11: Clawbot.Agents.Core.Content | C11: ContentLint.Check | D11: ContentLintCheck | E11: Static content lint that runs before the LLM reviewer gate | F11: No external dependencies; pure function
A12: 4 | B12: Clawbot.Domain.ChatScenarios | C12: ChatScenarioMatcher.Match | D12: ScenarioMatcher | E12: Pure scenario selector used by the auto-reply pipeline to pick the correct response template | F12: No external dependencies; pure function with in-memory candidate list
A13: 5 | B13: Clawbot.SharedKernel.Content | C13: DefaultGoldenHourResolver.ResolveNext | D13: GoldenHourResolve | E13: Calculates the next optimal posting time per platform for the content scheduler | F13: No external dependencies; pure function
A14: 6 | B14: Clawbot.Agents.Core.Orchestrator | C14: RecurrenceCalculator.NextRunUtc + WindowKey | D14: RecurrenceCalc | E14: Recurrence engine used by AgentSchedules to compute the next run time and deduplicate runs within a window | F14: Timezone ID must be a valid IANA/Windows timezone (e.g. SE Asia Standard Time)
A15: 7 | B15: Clawbot.Domain.KnowledgeBase | C15: KbSuggestion.IsAutoApprovable + Approve | D15: KbSuggestionApprove | E15: Domain aggregate methods controlling the KB suggestion lifecycle | F15: KbSuggestion instance built via KbSuggestion.Create with valid parameters
A16: 8 | B16: Clawbot.Domain.Conversations | C16: Conversation.TryResumeAiAutoReply + PauseAiAutoReplyUntil | D16: ConversationResume | E16: AI auto-reply state machine on the Conversation aggregate | F16: Conversation instance is in a valid state (not resolved/deleted)
A17: 9 | B17: Clawbot.Agents.Core.Orchestrator | C17: OrchestrationPlanValidator.Validate | D17: PlanValidator | E17: Validate a planner-produced plan document against the bound agent catalog | F17: A catalog is supplied with at least one entry where Orchestratable is true
A18: 10 | B18: Clawbot.Agents.Core.Orchestrator | C18: OrchestratorCostGuard.CanStartAsync / TryReserveAsync / RecordAsync | D18: CostGuard | E18: Enforce the per-tenant monthly LLM cost cap before and during an orchestration run | F18: A fake ILlmCostTracker returns a controlled SummaryAsync result; a separate fake also implements ILlmCostReservationStore
A19: 11 | B19: Clawbot.Infrastructure.Content.Publishing | C19: DnsPublicUrlSafetyValidator.IsSafeAsync | D19: PublicUrlSafety | E19: Validate a public media URL before it is submitted to an external publishing API | F19: A stub IHostAddressResolver is injected; the resolution timeout is shortened for the timeout case
A20: 12 | B20: Clawbot.Agents.Core.Content | C20: StrictContentReviewOutcomeParser.Parse / ParseVision | D20: ReviewOutcomeParse | E20: Parse a content reviewer completion into an accepted verdict or a machine-readable error code | F20: ReviewCompletionEnvelope is constructed directly in the test; no LLM call is made
... A22: 14 | B22: Clawbot.SharedKernel.Security | C22: AuthPolicy (SPEC-11 timing constants) | D22: AuthPolicyConstants | E22: Lock auth timing constants and confirm bound options match after PostConfigure | F22: A host is built with a deliberately wrong appsettings value for each option under test

Sheet Statistics
A2: UNIT TEST REPORT
A4: Project Name | B4: =Cover!B4 -> Clawbot | D4: Creator | F4: <Creator>
A5: Project Code | B5: =Cover!B5 -> CLAWBOT | D5: Reviewer/Approver | F5: <Reviewer/Approver>
A6: Document Code | B6: =B5&"_"&"Test Report"&"_"&"vx.x" -> CLAWBOT_Test Report_vx.x | D6: Issue Date | F6: 46244.708
A7: Notes | B7: Clawbot.Agents.Core.Chat, Clawbot.Agents.Core.Content, Clawbot.Domain.ChatScenarios, Clawbot.SharedKernel.Content, Clawbot.Agents.Core.Orchestrator, Clawbot.Domain.KnowledgeBase, Clawbot.Domain.Conversations, Clawbot.Infrastructure.Security, Clawbot.Infrastructure.Content.Publishing, Clawbot.Domain.Leads, Clawbot.SharedKernel.Security
A11: No | B11: Function code | C11: Passed | D11: Failed | E11: Untested | F11: N | G11: A | H11: B | I11: Total Test Cases
A12: 1 | B12: LlmBaseUrlGuard.IsAllowedBaseUrl | C12: =IsAllowedBaseUrl!A5 -> 14 | D12: =IsAllowedBaseUrl!C5 -> 0 | E12: =IsAllowedBaseUrl!F5 -> 0 | F12: =IsAllowedBaseUrl!L5 -> 6 | G12: =IsAllowedBaseUrl!M5 -> 7 | H12: =IsAllowedBaseUrl!N5 -> 1 | I12: =IsAllowedBaseUrl!O5 -> 14
A13: 2 | B13: AesEncryptor.ParseKey (constructor validation) | C13: =NormalizeApiKey!A5 -> 6 | D13: =NormalizeApiKey!C5 -> 0 | E13: =NormalizeApiKey!F5 -> 0 | F13: =NormalizeApiKey!L5 -> 3 | G13: =NormalizeApiKey!M5 -> 1 | H13: =NormalizeApiKey!N5 -> 2 | I13: =NormalizeApiKey!O5 -> 6
A14: 3 | B14: ContentLint.Check | C14: =ContentLintCheck!A5 -> 10 | D14: =ContentLintCheck!C5 -> 0 | E14: =ContentLintCheck!F5 -> 0 | F14: =ContentLintCheck!L5 -> 3 | G14: =ContentLintCheck!M5 -> 6 | H14: =ContentLintCheck!N5 -> 1 | I14: =ContentLintCheck!O5 -> 10
A15: 4 | B15: ChatScenarioMatcher.Match | C15: =ScenarioMatcher!A5 -> 9 | D15: =ScenarioMatcher!C5 -> 0 | E15: =ScenarioMatcher!F5 -> 0 | F15: =ScenarioMatcher!L5 -> 3 | G15: =ScenarioMatcher!M5 -> 6 | H15: =ScenarioMatcher!N5 -> 0 | I15: =ScenarioMatcher!O5 -> 9
A16: 5 | B16: DefaultGoldenHourResolver.ResolveNext | C16: =GoldenHourResolve!A5 -> 8 | D16: =GoldenHourResolve!C5 -> 0 | E16: =GoldenHourResolve!F5 -> 0 | F16: =GoldenHourResolve!L5 -> 3 | G16: =GoldenHourResolve!M5 -> 4 | H16: =GoldenHourResolve!N5 -> 1 | I16: =GoldenHourResolve!O5 -> 8
A17: 6 | B17: RecurrenceCalculator.NextRunUtc + WindowKey | C17: =RecurrenceCalc!A5 -> 10 | D17: =RecurrenceCalc!C5 -> 0 | E17: =RecurrenceCalc!F5 -> 0 | F17: =RecurrenceCalc!L5 -> 7 | G17: =RecurrenceCalc!M5 -> 1 | H17: =RecurrenceCalc!N5 -> 2 | I17: =RecurrenceCalc!O5 -> 10
A18: 7 | B18: KbSuggestion.IsAutoApprovable + Approve | C18: =KbSuggestionApprove!A5 -> 8 | D18: =KbSuggestionApprove!C5 -> 0 | E18: =KbSuggestionApprove!F5 -> 0 | F18: =KbSuggestionApprove!L5 -> 1 | G18: =KbSuggestionApprove!M5 -> 6 | H18: =KbSuggestionApprove!N5 -> 1 | I18: =KbSuggestionApprove!O5 -> 8
A19: 8 | B19: Conversation.TryResumeAiAutoReply + PauseAiAutoReplyUntil | C19: =ConversationResume!A5 -> 8 | D19: =ConversationResume!C5 -> 0 | E19: =ConversationResume!F5 -> 0 | F19: =ConversationResume!L5 -> 2 | G19: =ConversationResume!M5 -> 5 | H19: =ConversationResume!N5 -> 1 | I19: =ConversationResume!O5 -> 8
A20: 9 | B20: OrchestrationPlanValidator.Validate | C20: =PlanValidator!A5 -> 16 | D20: =PlanValidator!C5 -> 0 | E20: =PlanValidator!F5 -> 0 | F20: =PlanValidator!L5 -> 4 | G20: =PlanValidator!M5 -> 12 | H20: =PlanValidator!N5 -> 0 | I20: =PlanValidator!O5 -> 16
A21: 10 | B21: OrchestratorCostGuard.CanStartAsync / TryReserveAsync / RecordAsync | C21: =CostGuard!A5 -> 14 | D21: =CostGuard!C5 -> 0 | E21: =CostGuard!F5 -> 0 | F21: =CostGuard!L5 -> 5 | G21: =CostGuard!M5 -> 9 | H21: =CostGuard!N5 -> 0 | I21: =CostGuard!O5 -> 14
A22: 11 | B22: DnsPublicUrlSafetyValidator.IsSafeAsync | C22: =PublicUrlSafety!A5 -> 21 | D22: =PublicUrlSafety!C5 -> 0 | E22: =PublicUrlSafety!F5 -> 0 | F22: =PublicUrlSafety!L5 -> 2 | G22: =PublicUrlSafety!M5 -> 19 | H22: =PublicUrlSafety!N5 -> 0 | I22: =PublicUrlSafety!O5 -> 21
A23: 12 | B23: StrictContentReviewOutcomeParser.Parse / ParseVision | C23: =ReviewOutcomeParse!A5 -> 25 | D23: =ReviewOutcomeParse!C5 -> 0 | E23: =ReviewOutcomeParse!F5 -> 0 | F23: =ReviewOutcomeParse!L5 -> 4 | G23: =ReviewOutcomeParse!M5 -> 21 | H23: =ReviewOutcomeParse!N5 -> 0 | I23: =ReviewOutcomeParse!O5 -> 25
A24: 13 | B24: LeadScoringDefaults.Rules | C24: =LeadScoringWeights!A5 -> 12 | D24: =LeadScoringWeights!C5 -> 0 | E24: =LeadScoringWeights!F5 -> 0 | F24: =LeadScoringWeights!L5 -> 12 | G24: =LeadScoringWeights!M5 -> 0 | H24: =LeadScoringWeights!N5 -> 0 | I24: =LeadScoringWeights!O5 -> 12
A25: 14 | B25: AuthPolicy (SPEC-11 timing constants) | C25: =AuthPolicyConstants!A5 -> 11 | D25: =AuthPolicyConstants!C5 -> 0 | E25: =AuthPolicyConstants!F5 -> 0 | F25: =AuthPolicyConstants!L5 -> 8 | G25: =AuthPolicyConstants!M5 -> 3 | H25: =AuthPolicyConstants!N5 -> 0 | I25: =AuthPolicyConstants!O5 -> 11
B28: Sub total | C28: =SUM(C12:C25) -> 172 | D28: =SUM(D12:D25) -> 0 | E28: =SUM(E12:E25) -> 0 | F28: =SUM(F12:F25) -> 63 | G28: =SUM(G12:G25) -> 100 | H28: =SUM(H12:H25) -> 9 | I28: =SUM(I12:I25) -> 172
B30: Test coverage | D30: =(C28+D28)*100/(I28) -> 100 | E30: %
B31: Test successful coverage | D31: =C28*100/(I28) -> 100 | E31: %
B32: Normal case | D32: =F28*100/I28 -> 36.627907 | E32: %
B33: Abnormal case | D33: =G28*100/I28 -> 58.139535 | E33: %
B34: Boundary case | D34: =H28*100/I28 -> 5.2325581 | E34: %

Sheet IsAllowedBaseUrl
A1: Code Module | C1: Clawbot.Agents.Core.Chat | F1: Method | L1: LlmBaseUrlGuard.IsAllowedBaseUrl
A2: Created By | C2: <Developer Name> | F2: Executed By | L2: <Tester Name>
A3: Test requirement | C3: Guard outbound LLM provider URLs against SSRF: reject non-http/https schemes, embedded credentials, public cleartext HTTP, and private hosts without explicit operator grant. Fail closed when DNS resolves to a mix of public and private addresses or when resolution fails.
A4: Passed | C4: Failed | F4: Untested | L4: N/A/B | O4: Total Test Cases
A5: =COUNTIF(F32:HQ32,"P") -> 14 | C5: =COUNTIF(F32:HQ32,"F") -> 0 | F5: =SUM(O5,- A5,- C5) -> 0 | L5: =COUNTIF(E31:HQ31,"N") -> 6 | M5: =COUNTIF(E31:HQ31,"A") -> 7 | N5: =COUNTIF(E31:HQ31,"B") -> 1 | O5: =COUNTA(E7:HT7) -> 14
F7: UTCID01 | G7: UTCID02 | H7: UTCID03 | I7: UTCID04 | J7: UTCID05 | K7: UTCID06 | L7: UTCID07 | M7: UTCID08 | N7: UTCID09 | O7: UTCID10 | P7: UTCID11 | Q7: UTCID12 | R7: UTCID13 | S7: UTCID14
A8: Condition | B8: baseUrl
D9: "not-a-uri" (malformed, no scheme) | F9: O
D10: "ftp://api.example.com" (unsupported scheme) | G10: O
D11: "https://user:pass@api.example.com" (userInfo present) | H11: O
D12: "http://api.openai.com" (HTTP + public host) | I12: O
D13: "http://10.0.0.5:8080" (HTTP + private RFC-1918 host) | J13: O | K13: O | L13: O
D14: "https://api.openai.com" (HTTPS + public host) | M14: O | N14: O | O14: O | P14: O
D15: "https://localhost:11434" (HTTPS + loopback) | Q15: O | R15: O
D16: "https://10.0.0.5:8080" (HTTPS + private RFC-1918) | S16: O
B17: allowPrivateHosts
D18: false (default) | F18: O | G18: O | H18: O | J18: O | L18: O | M18: O | N18: O | O18: O | P18: O | Q18: O | S18: O
D19: true (operator grant) | I19: O | K19: O | R19: O
B20: allowedPrivateOrigins
D21: empty list | F21: O | G21: O | H21: O | I21: O | J21: O | K21: O | M21: O | N21: O | O21: O | P21: O | Q21: O | R21: O | S21: O
D22: list containing "http://10.0.0.5:8080" | L22: O
B23: DNS stub
D24: returns public IPv4 only (e.g. 1.2.3.4) | F24: O | G24: O | H24: O | I24: O | M24: O
D25: returns private IPv4 only (e.g. 10.0.0.5) | J25: O | K25: O | L25: O | N25: O | Q25: O | R25: O | S25: O
D26: returns mix: one public + one private address | O26: O
D27: throws SocketException (DNS resolution failure) | P27: O
A28: Confirm | B28: Return
D29: true (URL is allowed) | K29: O | L29: O | M29: O | R29: O
D30: false (URL is blocked) | F30: O | G30: O | H30: O | I30: O | J30: O | N30: O | O30: O | P30: O | Q30: O | S30: O
A31: Result | B31: Type(N : Normal, A : Abnormal, B : Boundary) | F31: N | G31: N | H31: A | I31: A | J31: N | K31: A | L31: A | M31: N | N31: A | O31: B | P31: A | Q31: N | R31: A | S31: N
B32: Passed/Failed | F32: P | G32: P | H32: P | I32: P | J32: P | K32: P | L32: P | M32: P | N32: P | O32: P | P32: P | Q32: P | R32: P | S32: P
B33: Executed Date | F33: 46244.708 | G33: 46244.708 | H33: 46244.708 | I33: 46244.708 | J33: 46244.708 | K33: 46244.708 | L33: 46244.708 | M33: 46244.708 | N33: 46244.708 | O33: 46244.708 | P33: 46244.708 | Q33: 46244.708 | R33: 46244.708 | S33: 46244.708
B34: Defect ID

Sheet NormalizeApiKey
A1: Code Module | C1: Clawbot.Infrastructure.Security | F1: Method | L1: AesEncryptor.ParseKey (constructor validation)
A2: Created By | C2: <Developer Name> | F2: Executed By | L2: <Tester Name>
A3: Test requirement | C3: The AesEncryptor constructor must reject missing, malformed, or wrong-length base64 keys with a clear InvalidOperationException before any encryption call can be made.
A4: Passed | C4: Failed | F4: Untested | L4: N/A/B | O4: Total Test Cases
A5: =COUNTIF(F19:HQ19,"P") -> 6 | C5: =COUNTIF(F19:HQ19,"F") -> 0 | F5: =SUM(O5,- A5,- C5) -> 0 | L5: =COUNTIF(E18:HQ18,"N") -> 3 | M5: =COUNTIF(E18:HQ18,"A") -> 1 | N5: =COUNTIF(E18:HQ18,"B") -> 2 | O5: =COUNTA(E7:HT7) -> 6
F7: UTCID01 | G7: UTCID02 | H7: UTCID03 | I7: UTCID04 | J7: UTCID05 | K7: UTCID06
A8: Condition | B8: Base64Key option
D9: null or empty string | F9: O
D10: whitespace-only string | G10: O
D11: valid base64 but decodes to 16 bytes (wrong length) | H11: O
D12: valid base64 but decodes to 64 bytes (wrong length) | I12: O
D13: non-base64 characters (e.g. "!!invalid!!") | J13: O
D14: valid base64 that decodes to exactly 32 bytes | K14: O
A15: Confirm | B15: Outcome
D16: Constructor succeeds; Encrypt returns a non-empty base64 string | K16: O
D17: InvalidOperationException is thrown with a descriptive message | F17: O | G17: O | H17: O | I17: O | J17: O
A18: Result | B18: Type(N : Normal, A : Abnormal, B : Boundary) | F18: N | G18: N | H18: B | I18: B | J18: A | K18: N
B19: Passed/Failed | F19: P | G19: P | H19: P | I19: P | J19: P | K19: P
B20: Executed Date | F20: 46244.708 | G20: 46244.708 | H20: 46244.708 | I20: 46244.708 | J20: 46244.708 | K20: 46244.708
B21: Defect ID

Sheet ContentLintCheck
A1: Code Module | C1: Clawbot.Agents.Core.Content | F1: Method | L1: ContentLint.Check
A2: Created By | C2: <Developer Name> | F2: Executed By | L2: <Tester Name>
A3: Test requirement | C3: Deterministic pre-LLM lint: reject content bodies that contain absolute outcome guarantees, external links or junk encoding characters. Pass empty/whitespace bodies and clean bodies unchanged.
A4: Passed | C4: Failed | F4: Untested | L4: N/A/B | O4: Total Test Cases
A5: =COUNTIF(F28:HQ28,"P") -> 10 | C5: =COUNTIF(F28:HQ28,"F") -> 0 | F5: =SUM(O5,- A5,- C5) -> 0 | L5: =COUNTIF(E27:HQ27,"N") -> 3 | M5: =COUNTIF(E27:HQ27,"A") -> 6 | N5: =COUNTIF(E27:HQ27,"B") -> 1 | O5: =COUNTA(E7:HT7) -> 10
F7: UTCID01 | G7: UTCID02 | H7: UTCID03 | I7: UTCID04 | J7: UTCID05 | K7: UTCID06 | L7: UTCID07 | M7: UTCID08 | N7: UTCID09 | O7: UTCID10
A8: Condition | B8: body
D9: null | F9: O
D10: whitespace-only string | G10: O
D11: clean body text (no violations) | H11: O
D12: body with tab and newline only (allowed control chars) | I12: O
D13: body containing an absolute-guarantee phrase (prohibited commitment) | J13: O
D14: body containing "100% do" (absolute guarantee phrase, uppercase variant) | K14: O
D15: body containing "https://example.com" (external link) | L15: O
D16: body containing "www.example.com" (www link) | M16: O
D17: body containing U+FFFD replacement character (mojibake) | N17: O
D18: body containing C0 control char 0x01 (junk) | O18: O
A19: Confirm | B19: Succeeded
D20: TRUE | F20: O | G20: O | H20: O | I20: O
D21: FALSE | J21: O | K21: O | L21: O | M21: O | N21: O | O21: O
B22: ErrorCode
D23: (empty string) | F23: O | G23: O | H23: O | I23: O
D24: lint_absolute_guarantee | J24: O | K24: O
D25: lint_external_link | L25: O | M25: O
D26: lint_junk_chars | N26: O | O26: O
A27: Result | B27: Type(N : Normal, A : Abnormal, B : Boundary) | F27: N | G27: N | H27: N | I27: B | J27: A | K27: A | L27: A | M27: A | N27: A | O27: A
B28: Passed/Failed | F28: P | G28: P | H28: P | I28: P | J28: P | K28: P | L28: P | M28: P | N28: P | O28: P
B29: Executed Date | F29: 46244.708 | G29: 46244.708 | H29: 46244.708 | I29: 46244.708 | J29: 46244.708 | K29: 46244.708 | L29: 46244.708 | M29: 46244.708 | N29: 46244.708 | O29: 46244.708
B30: Defect ID

Sheet ScenarioMatcher
A1: Code Module | C1: Clawbot.Domain.ChatScenarios | F1: Method | L1: ChatScenarioMatcher.Match
A2: Created By | C2: <Developer Name> | F2: Executed By | L2: <Tester Name>
A3: Test requirement | C3: Return the best-matching ChatScenario for an inbound text. Regex trigger scores 1000 + match.Length; substring scores trigger.Length. Tiebreak: higher SuccessRate then lower Code. Platform CSV filter: empty or 'all' matches any platform.
A4: Passed | C4: Failed | F4: Untested | L4: N/A/B | O4: Total Test Cases
A5: =COUNTIF(F27:HQ27,"P") -> 9 | C5: =COUNTIF(F27:HQ27,"F") -> 0 | F5: =SUM(O5,- A5,- C5) -> 0 | L5: =COUNTIF(E26:HQ26,"N") -> 3 | M5: =COUNTIF(E26:HQ26,"A") -> 6 | N5: =COUNTIF(E26:HQ26,"B") -> 0 | O5: =COUNTA(E7:HT7) -> 9
F7: UTCID01 | G7: UTCID02 | H7: UTCID03 | I7: UTCID04 | J7: UTCID05 | K7: UTCID06 | L7: UTCID07 | M7: UTCID08 | N7: UTCID09
A8: Condition | B8: text
D9: null or empty string | F9: O
D10: text matching one scenario via regex | G10: O | H10: O | L10: O | M10: O | N10: O
D11: text matching two scenarios; one has longer regex match (more specific) | I11: O
D12: text matching two scenarios; equal score; one has higher SuccessRate | J12: O
D13: text matching two scenarios; equal score and rate; one has lower Code (ordinal) | K13: O
B14: candidates
D15: empty list | G15: O
D16: single scenario, no platform filter (platforms empty) | F16: O | H16: O | I16: O | J16: O | K16: O
D17: scenarios with platform = "facebook" | L17: O | M17: O
D18: scenarios with platform = "all" | N18: O
B19: platform arg
D20: null | F20: O | G20: O | H20: O | I20: O | J20: O | K20: O
D21: "facebook" | L21: O
D22: "zalo" | M22: O | N22: O
A23: Confirm | B23: Return
D24: null (no match) | F24: O | G24: O | M24: O
D25: the expected scenario | H25: O | I25: O | J25: O | K25: O | L25: O | N25: O
A26: Result | B26: Type(N : Normal, A : Abnormal, B : Boundary) | F26: N | G26: N | H26: N | I26: A | J26: A | K26: A | L26: A | M26: A | N26: A
B27: Passed/Failed | F27: P | G27: P | H27: P | I27: P | J27: P | K27: P | L27: P | M27: P | N27: P
B28: Executed Date | F28: 46244.708 | G28: 46244.708 | H28: 46244.708 | I28: 46244.708 | J28: 46244.708 | K28: 46244.708 | L28: 46244.708 | M28: 46244.708 | N28: 46244.708
B29: Defect ID

Sheet GoldenHourResolve
A1: Code Module | C1: Clawbot.SharedKernel.Content | F1: Method | L1: DefaultGoldenHourResolver.ResolveNext
A2: Created By | C2: <Developer Name> | F2: Executed By | L2: <Tester Name>
A3: Test requirement | C3: Return the next golden-hour slot in UTC+7 for a given platform. Known platforms: facebook=20:30, tiktok=20:00, instagram=19:30, youtube=18:00, zalo=08:00. Unknown platform defaults to 19:00. If the candidate slot has already passed today, return the same slot tomorrow.
A4: Passed | C4: Failed | F4: Untested | L4: N/A/B | O4: Total Test Cases
A5: =COUNTIF(F24:HQ24,"P") -> 8 | C5: =COUNTIF(F24:HQ24,"F") -> 0 | F5: =SUM(O5,- A5,- C5) -> 0 | L5: =COUNTIF(E23:HQ23,"N") -> 3 | M5: =COUNTIF(E23:HQ23,"A") -> 4 | N5: =COUNTIF(E23:HQ23,"B") -> 1 | O5: =COUNTA(E7:HT7) -> 8
F7: UTCID01 | G7: UTCID02 | H7: UTCID03 | I7: UTCID04 | J7: UTCID05 | K7: UTCID06 | L7: UTCID07 | M7: UTCID08
A8: Condition | B8: platform
D9: "facebook" | F9: O | G9: O | H9: O
D10: "tiktok" | I10: O
D11: "instagram" | M11: O
D12: "youtube"
D13: "zalo" | J13: O
D14: "unknown_platform" (not in the map) | K14: O
D15: "FACEBOOK" (uppercase — case-insensitive check) | L15: O
B16: utcNow (Vietnam time context)
D17: before the platform golden hour today (e.g. 10:00 VN for facebook 20:30) | F17: O | I17: O | J17: O | K17: O | L17: O
D18: after the platform golden hour today (e.g. 21:00 VN for facebook 20:30) | G18: O | M18: O
D19: exactly at the platform golden hour (boundary) | H19: O
A20: Confirm | B20: Return
D21: today's golden hour in UTC+7 (converted to UTC) | F21: O | I21: O | J21: O | K21: O | L21: O
D22: tomorrow's golden hour in UTC+7 (converted to UTC) | G22: O | H22: O | M22: O
A23: Result | B23: Type(N : Normal, A : Abnormal, B : Boundary) | F23: N | G23: A | H23: B | I23: N | J23: N | K23: A | L23: A | M23: A
B24: Passed/Failed | F24: P | G24: P | H24: P | I24: P | J24: P | K24: P | L24: P | M24: P
B25: Executed Date | F25: 46244.708 | G25: 46244.708 | H25: 46244.708 | I25: 46244.708 | J25: 46244.708 | K25: 46244.708 | L25: 46244.708 | M25: 46244.708
B26: Defect ID

Sheet RecurrenceCalc
A1: Code Module | C1: Clawbot.Agents.Core.Orchestrator | F1: Method | L1: RecurrenceCalculator.NextRunUtc + WindowKey
A2: Created By | C2: <Developer Name> | F2: Executed By | L2: <Tester Name>
A3: Test requirement | C3: NextRunUtc advances a UTC timestamp by one cadence unit in the given timezone. WindowKey returns a deterministic string key for the cadence window (e.g. weekly:2026-W33, quarterly:2026-Q3). Month-end dates are clamped to the last valid day of the target month.
A4: Passed | C4: Failed | F4: Untested | L4: N/A/B | O4: Total Test Cases
A5: =COUNTIF(F30:HQ30,"P") -> 10 | C5: =COUNTIF(F30:HQ30,"F") -> 0 | F5: =SUM(O5,- A5,- C5) -> 0 | L5: =COUNTIF(E29:HQ29,"N") -> 7 | M5: =COUNTIF(E29:HQ29,"A") -> 1 | N5: =COUNTIF(E29:HQ29,"B") -> 2 | O5: =COUNTA(E7:HT7) -> 10
F7: UTCID01 | G7: UTCID02 | H7: UTCID03 | I7: UTCID04 | J7: UTCID05 | K7: UTCID06 | L7: UTCID07 | M7: UTCID08 | N7: UTCID09 | O7: UTCID10
A8: Condition | B8: method
D9: NextRunUtc | F9: O | G9: O | H9: O | I9: O | J9: O | K9: O | L9: O
D10: WindowKey | M10: O | N10: O | O10: O
B11: cadence
D12: "daily" | F12: O | O12: O
D13: "weekly" | G13: O | M13: O
D14: "monthly" | H14: O | J14: O
D15: "quarterly" | I15: O | K15: O | N15: O
D16: "biennial" (unsupported) | L16: O
B17: fromUtc / dueAtUtc
D18: normal date (e.g. 2026-08-11 10:00 UTC) | F18: O | G18: O | H18: O | I18: O | L18: O | M18: O | N18: O | O18: O
D19: Jan 31 (month end, +1 month → Feb should clamp to Feb 28) | J19: O
D20: last day of a quarter (e.g. Sep 30 for Q3) | K20: O
A21: Confirm | B21: Return
D22: next daily timestamp (+1 day) | F22: O
D23: next weekly timestamp (+7 days) | G23: O
D24: next monthly timestamp (+1 month, clamped) | H24: O | J24: O
D25: next quarterly timestamp (+3 months, clamped) | I25: O | K25: O
D26: window key string matching expected format | M26: O | N26: O | O26: O
B27: Exception
D28: ArgumentOutOfRangeException | L28: O
A29: Result | B29: Type(N : Normal, A : Abnormal, B : Boundary) | F29: N | G29: N | H29: N | I29: N | J29: B | K29: B | L29: A | M29: N | N29: N | O29: N
B30: Passed/Failed | F30: P | G30: P | H30: P | I30: P | J30: P | K30: P | L30: P | M30: P | N30: P | O30: P
B31: Executed Date | F31: 46244.708 | G31: 46244.708 | H31: 46244.708 | I31: 46244.708 | J31: 46244.708 | K31: 46244.708 | L31: 46244.708 | M31: 46244.708 | N31: 46244.708 | O31: 46244.708
B32: Defect ID

Sheet KbSuggestionApprove
A1: Code Module | C1: Clawbot.Domain.KnowledgeBase | F1: Method | L1: KbSuggestion.IsAutoApprovable + Approve
A2: Created By | C2: <Developer Name> | F2: Executed By | L2: <Tester Name>
A3: Test requirement | C3: IsAutoApprovable returns true only when: Status=pending, Verdict=approve, both accuracy values present, accuracy_after >= accuracy_before. Approve(auto) requires IsAutoApprovable=true and no decidedBy. Approve(human) requires a decidedBy userId. Reject requires a non-empty reason string.
A4: Passed | C4: Failed | F4: Untested | L4: N/A/B | O4: Total Test Cases
A5: =COUNTIF(F31:HQ31,"P") -> 8 | C5: =COUNTIF(F31:HQ31,"F") -> 0 | F5: =SUM(O5,- A5,- C5) -> 0 | L5: =COUNTIF(E30:HQ30,"N") -> 1 | M5: =COUNTIF(E30:HQ30,"A") -> 6 | N5: =COUNTIF(E30:HQ30,"B") -> 1 | O5: =COUNTA(E7:HT7) -> 8
F7: UTCID01 | G7: UTCID02 | H7: UTCID03 | I7: UTCID04 | J7: UTCID05 | K7: UTCID06 | L7: UTCID07 | M7: UTCID08
A8: Condition | B8: Status
D9: pending | F9: O | G9: O | H9: O | I9: O | J9: O | L9: O
D10: approved (already processed) | K10: O
D11: rejected (already processed) | M11: O
B12: Verdict
D13: approve | F13: O | G13: O | H13: O | I13: O | K13: O | L13: O | M13: O
D14: reject | J14: O
B15: accuracy_after vs accuracy_before
D16: after > before (improved) | F16: O | J16: O | K16: O | L16: O | M16: O
D17: after == before (unchanged) | G17: O
D18: after < before (degraded) | H18: O
D19: either value is null | I19: O
B20: decidedBy
D21: null (auto path) | F21: O | G21: O | H21: O | I21: O | J21: O | K21: O | M21: O
D22: valid userId (human path) | L22: O
A23: Confirm | B23: IsAutoApprovable
D24: TRUE | F24: O | G24: O | L24: O
D25: FALSE | H25: O | I25: O | J25: O | K25: O | M25: O
B26: Approve outcome
D27: auto-approved (ApprovalMode=automatic) | F27: O | G27: O
D28: human-approved (ApprovalMode=human) | L28: O
D29: InvalidOperationException | K29: O | M29: O
A30: Result | B30: Type(N : Normal, A : Abnormal, B : Boundary) | F30: N | G30: B | H30: A | I30: A | J30: A | K30: A | L30: A | M30: A
B31: Passed/Failed | F31: P | G31: P | H31: P | I31: P | J31: P | K31: P | L31: P | M31: P
B32: Executed Date | F32: 46244.708 | G32: 46244.708 | H32: 46244.708 | I32: 46244.708 | J32: 46244.708 | K32: 46244.708 | L32: 46244.708 | M32: 46244.708
B33: Defect ID

Sheet ConversationResume
A1: Code Module | C1: Clawbot.Domain.Conversations | F1: Method | L1: Conversation.TryResumeAiAutoReply + PauseAiAutoReplyUntil
A2: Created By | C2: <Developer Name> | F2: Executed By | L2: <Tester Name>
A3: Test requirement | C3: PauseAiAutoReplyUntil sets enabled=false and records resumeAt. TryResumeAiAutoReply returns true and clears resumeAt only when enabled=false AND resumeAt <= now. SetAiAutoReply(false) is a permanent toggle (clears resumeAt). Escalate sets enabled=false with resumeAt=null permanently.
A4: Passed | C4: Failed | F4: Untested | L4: N/A/B | O4: Total Test Cases
A5: =COUNTIF(F26:HQ26,"P") -> 8 | C5: =COUNTIF(F26:HQ26,"F") -> 0 | F5: =SUM(O5,- A5,- C5) -> 0 | L5: =COUNTIF(E25:HQ25,"N") -> 2 | M5: =COUNTIF(E25:HQ25,"A") -> 5 | N5: =COUNTIF(E25:HQ25,"B") -> 1 | O5: =COUNTA(E7:HT7) -> 8
F7: UTCID01 | G7: UTCID02 | H7: UTCID03 | I7: UTCID04 | J7: UTCID05 | K7: UTCID06 | L7: UTCID07 | M7: UTCID08
A8: Condition | B8: method called
D9: PauseAiAutoReplyUntil(resumeAt) | F9: O
D10: TryResumeAiAutoReply(now) | G10: O | H10: O | I10: O | J10: O
D11: SetAiAutoReply(false) | K11: O
D12: Escalate() | L12: O | M12: O
B13: enabled state before call
D14: TRUE | F14: O | I14: O | J14: O | K14: O | L14: O | M14: O
D15: FALSE | G15: O | H15: O
B16: resumeAt vs now
D17: resumeAt <= now (window elapsed) | G17: O | K17: O | L17: O
D18: resumeAt > now (still in window) | H18: O | I18: O
D19: resumeAt is null | F19: O | J19: O | M19: O
A20: Confirm | B20: Return / side-effect
D21: TryResume returns true; enabled=true; resumeAt=null | G21: O
D22: TryResume returns false; state unchanged | H22: O | I22: O | J22: O
D23: enabled=false; resumeAt set to the given future time | F23: O
D24: enabled=false; resumeAt=null (permanent disable) | K24: O | L24: O | M24: O
A25: Result | B25: Type(N : Normal, A : Abnormal, B : Boundary) | F25: N | G25: N | H25: A | I25: A | J25: B | K25: A | L25: A | M25: A
B26: Passed/Failed | F26: P | G26: P | H26: P | I26: P | J26: P | K26: P | L26: P | M26: P
B27: Executed Date | F27: 46244.708 | G27: 46244.708 | H27: 46244.708 | I27: 46244.708 | J27: 46244.708 | K27: 46244.708 | L27: 46244.708 | M27: 46244.708
B28: Defect ID

Sheet PlanValidator
A1: Code Module | C1: Clawbot.Agents.Core.Orchestrator | F1: Method | L1: OrchestrationPlanValidator.Validate
A2: Created By | C2: <Developer Name> | F2: Executed By | L2: <Tester Name>
A3: Test requirement | C3: Reject an orchestration plan before any agent runs: empty plan, task count above MaxTaskCount (50), missing or duplicate task id, task input above MaxTaskInputChars (8192), agent not present in the orchestratable catalog, dangling dependency, and dependency cycle. Fail closed with a machine-readable error code.
A4: Passed | C4: Failed | F4: Untested | L4: N/A/B | O4: Total Test Cases
A5: =COUNTIF(F42:HR42,"P") -> 16 | C5: =COUNTIF(F42:HR42,"F") -> 0 | F5: =SUM(O5,- A5,- C5) -> 0 | L5: =COUNTIF(E41:HR41,"N") -> 4 | M5: =COUNTIF(E41:HR41,"A") -> 12 | N5: =COUNTIF(E41:HR41,"B") -> 0 | O5: =COUNTA(E7:HU7) -> 16
F7: UTCID01 | G7: UTCID02 | H7: UTCID03 | I7: UTCID04 | J7: UTCID05 | K7: UTCID06 | L7: UTCID07 | M7: UTCID08 | N7: UTCID09 | O7: UTCID10 | P7: UTCID11 | Q7: UTCID12 | R7: UTCID13 | S7: UTCID14 | T7: UTCID15 | U7: UTCID16
A8: Condition | B8: plan.Tasks
D9: null (property not set) | F9: O
D10: empty collection | G10: O
D11: 51 tasks (above MaxTaskCount) | H11: O
D12: one task, null element | I12: O
D13: one task, Id is whitespace | J13: O
D14: two tasks with the same Id (different casing) | K14: O
D15: one task, input total length 8193 chars | L15: O
D16: one valid task | M16: O | N16: O | Q16: O | R16: O | S16: O
D17: two tasks, second DependsOn an unknown id | O17: O
D18: two tasks forming a dependency cycle | P18: O
D19: three tasks in a valid dependency chain | T19: O
B20: task.Agent
D21: matches catalog Code exactly | H21: O | K21: O | L21: O | N21: O | O21: O | P21: O | Q21: O | T21: O
D22: matches catalog ShortName (different casing) | R22: O
D23: matches catalog AgentType | S23: O
D24: not present in the catalog | M24: O
B25: catalog entry Orchestratable
D26: true (agent is bound and orchestratable) | H26: O | K26: O | L26: O | M26: O | O26: O | P26: O | Q26: O | R26: O | S26: O | T26: O
D27: false (agent exists but is not orchestratable) | N27: O
A28: Confirm | B28: Result
D29: Valid (IsValid is true) | Q29: O | R29: O | S29: O | T29: O
D30: Invalid "empty_plan" | F30: O | G30: O
D31: Invalid "too_many_tasks:51:50" | H31: O
D32: Invalid "task_required" | I32: O
D33: Invalid "task_id_required" | J33: O
D34: Invalid "duplicate_task:..." | K34: O
D35: Invalid "input_too_large:..." | L35: O
D36: Invalid "unknown_agent:..." listing allowed codes | M36: O | N36: O
D37: Invalid "dangling_dependency:..." | O37: O
D38: Invalid "cycle_detected" | P38: O
B39: Exception
D40: ArgumentNullException (plan or catalog is null) | U40: O
A41: Result | B41: Type(N : Normal, A : Abnormal, B : Boundary) | F41: A | G41: A | H41: A | I41: A | J41: A | K41: A | L41: A | M41: A | N41: A | O41: A | P41: A | Q41: N | R41: N | S41: N | T41: N | U41: A
...

Sheet CostGuard
A1: Code Module | C1: Clawbot.Agents.Core.Orchestrator | F1: Method | L1: OrchestratorCostGuard.CanStartAsync / TryReserveAsync / RecordAsync
A2: Created By | C2: <Developer Name> | F2: Executed By | L2: <Tester Name>
A3: Test requirement | C3: Block an orchestration run when the month-to-date spend plus the estimate would exceed the tenant cap. Treat a negative estimate as zero. Prefer the reservation store when the tracker implements it. Always write a ledger entry when there are tokens, even when the computed cost is zero, so the monthly cap cannot silently lose data.
A4: Passed | C4: Failed | F4: Untested | L4: N/A/B | O4: Total Test Cases
A5: =COUNTIF(F42:HQ42,"P") -> 14 | C5: =COUNTIF(F42:HQ42,"F") -> 0 | F5: =SUM(O5,- A5,- C5) -> 0 | L5: =COUNTIF(E41:HQ41,"N") -> 5 | M5: =COUNTIF(E41:HQ41,"A") -> 9 | N5: =COUNTIF(E41:HQ41,"B") -> 0 | O5: =COUNTA(E7:HT7) -> 14
F7: UTCID01 | G7: UTCID02 | H7: UTCID03 | I7: UTCID04 | J7: UTCID05 | K7: UTCID06 | L7: UTCID07 | M7: UTCID08 | N7: UTCID09 | O7: UTCID10 | P7: UTCID11 | Q7: UTCID12 | R7: UTCID13 | S7: UTCID14
A8: Condition | B8: method under test
D9: CanStartAsync (preflight) | F9: O | G9: O | H9: O | I9: O
D10: TryReserveAsync (mid-run) | J10: O | K10: O | L10: O | M10: O
D11: RecordAsync (ledger write) | N11: O | O11: O | P11: O
D12: ReleaseReservationAsync | Q12: O | R12: O | S12: O
B13: summary MonthToDate vs Cap
D14: MonthToDate 10 + estimate 5, Cap 200 (well under) | F14: O | J14: O | L14: O | M14: O
D15: MonthToDate 195 + estimate 5, Cap 200 (exactly at cap) | G15: O
D16: MonthToDate 199 + estimate 5, Cap 200 (over cap) | H16: O | I16: O | K16: O
B17: estimatedUsd
D18: positive value | F18: O | G18: O | H18: O | J18: O | K18: O | L18: O | M18: O
D19: zero
D20: negative value (clamped to zero) | I20: O
B21: tracker implements reservation store
D22: no (plain tracker) | F22: O | G22: O | H22: O | I22: O | J22: O | K22: O | S22: O
D23: yes, store allows the reservation | L23: O | Q23: O | R23: O
D24: yes, store denies the reservation | M24: O
B25: reply tokens / cost
D26: cost 0, input 0, output 0 (nothing to record) | N26: O
D27: cost 0 but input tokens above zero (provider returned no usage rate) | O27: O
D28: cost above zero with tokens | P28: O
B29: reservationId
D30: null | N30: O | O30: O | R30: O
D31: a valid Guid | P31: O | Q31: O | S31: O
A32: Confirm | B32: Outcome
D33: Allowed is true, Reason is null | F33: O | G33: O | J33: O
D34: Denied "cost_cap_preflight" | H34: O | I34: O
D35: Denied "cost_cap_midrun" | K35: O | M35: O
D36: Allowed is true with the store ReservationId propagated | L36: O
D37: RecordAsync writes one CostEntry to the tracker | O37: O | P37: O
D38: RecordAsync writes nothing (short-circuit) | N38: O
D39: ReleaseReservationAsync forwards to the store | Q39: O
D40: ReleaseReservationAsync is a no-op | R40: O | S40: O
A41: Result | B41: Type(N : Normal, A : Abnormal, B : Boundary) | F41: N | G41: A | H41: A | I41: A | J41: N | K41: A | L41: N | M41: A | N41: A | O41: A | P41: N | Q41: N | R41: A | S41: A
...

Sheet PublicUrlSafety
A1: Code Module | C1: Clawbot.Infrastructure.Content.Publishing | F1: Method | L1: DnsPublicUrlSafetyValidator.IsSafeAsync
A2: Created By | C2: <Developer Name> | F2: Executed By | L2: <Tester Name>
A3: Test requirement | C3: Only allow HTTPS URLs that resolve exclusively to public addresses before media is handed to a social platform. Reject non-HTTPS schemes, embedded credentials, loopback and .local or .localhost names, RFC-1918 and shared-address ranges, IPv4-mapped IPv6 loopback, link-local and site-local IPv6, documentation prefixes, DNS failures and resolution timeouts.
A4: Passed | C4: Failed | F4: Untested | L4: N/A/B | O4: Total Test Cases
A5: =COUNTIF(F41:HW41,"P") -> 21 | C5: =COUNTIF(F41:HW41,"F") -> 0 | F5: =SUM(O5,- A5,- C5) -> 0 | L5: =COUNTIF(E40:HW40,"N") -> 2 | M5: =COUNTIF(E40:HW40,"A") -> 19 | N5: =COUNTIF(E40:HW40,"B") -> 0 | O5: =COUNTA(E7:HZ7) -> 21
F7: UTCID01 | G7: UTCID02 | H7: UTCID03 | I7: UTCID04 | J7: UTCID05 | K7: UTCID06 | L7: UTCID07 | M7: UTCID08 | N7: UTCID09 | O7: UTCID10 | P7: UTCID11 | Q7: UTCID12 | R7: UTCID13 | S7: UTCID14 | T7: UTCID15 | U7: UTCID16 | V7: UTCID17 | W7: UTCID18 | X7: UTCID19 | Y7: UTCID20 | Z7: UTCID21
A8: Condition | B8: uri
D9: relative URI (not absolute) | F9: O
D10: "http://cdn.example.com/a.jpg" (HTTPS required) | G10: O
D11: "https://user:pass@cdn.example.com/a.jpg" (userInfo present) | H11: O
D12: "https://localhost/a.jpg" | I12: O
D13: "https://svc.local/a.jpg" (mDNS suffix) | J13: O
D14: "https://cdn/a.jpg" (single label, no dot) | K14: O
D15: "https://127.0.0.1/a.jpg" (loopback literal) | L15: O
D16: "https://10.1.2.3/a.jpg" (RFC-1918 literal) | M16: O
D17: "https://100.64.0.1/a.jpg" (shared address space) | N17: O
D18: "https://169.254.1.1/a.jpg" (link-local literal) | O18: O
D19: "https://[::1]/a.jpg" (IPv6 loopback in brackets) | P19: O
D20: "https://[2001:db8::1]/a.jpg" (IPv6 documentation prefix) | Q20: O
D21: "https://8.8.8.8/a.jpg" (public IPv4 literal) | R21: O
D22: "https://cdn.example.com/a.jpg" (public DNS name) | S22: O | T22: O | U22: O | V22: O | W22: O | X22: O | Y22: O
B23: resolver stub
D24: not called (literal or early reject) | F24: O | G24: O | H24: O | I24: O | J24: O | K24: O | L24: O | M24: O | N24: O | O24: O | P24: O | Q24: O | R24: O
D25: returns one public IPv4 | S25: O
D26: returns one private IPv4 | T26: O
D27: returns public and private together | U27: O
D28: returns an empty array | V28: O
D29: throws SocketException | W29: O
D30: never completes (forces the resolution timeout) | X30: O | Y30: O
B31: cancellationToken
D32: None | F32: O | G32: O | H32: O | I32: O | J32: O | K32: O | L32: O | M32: O | N32: O | O32: O | P32: O | Q32: O | R32: O | S32: O | T32: O | U32: O | V32: O | W32: O | X32: O
D33: already cancelled | Y33: O
A34: Confirm | B34: Return
D35: true (URL is safe to publish) | R35: O | S35: O
D36: false (URL is rejected) | F36: O | G36: O | H36: O | I36: O | J36: O | K36: O | L36: O | M36: O | N36: O | O36: O | P36: O | Q36: O | T36: O | U36: O | V36: O | W36: O | X36: O
B37: Exception
D38: OperationCanceledException (caller cancelled) | Y38: O
D39: ArgumentNullException (uri is null) | Z39: O
A40: Result | B40: Type(N : Normal, A : Abnormal, B : Boundary) | F40: A | G40: A | H40: A | I40: A | J40: A | K40: A | L40: A | M40: A | N40: A | O40: A | P40: A | Q40: A | R40: N | S40: N | T40: A | U40: A | V40: A | W40: A | X40: A | Y40: A | Z40: A
B41: Passed/Failed | F41: P | G41: P | H41: P | I41: P | J41: P | K41: P | L41: P | M41: P | N41: P | O41: P | P41: P | Q41: P | R41: P | S41: P | T41: P | U41: P | V41: P | W41: P | X41: P | Y41: P | Z41: P
...

Sheet ReviewOutcomeParse
A1: Code Module | C1: Clawbot.Agents.Core.Content | F1: Method | L1: StrictContentReviewOutcomeParser.Parse / ParseVision
A2: Created By | C2: <Developer Name> | F2: Executed By | L2: <Tester Name>
A3: Test requirement | C3: Fail closed when parsing a reviewer verdict. Check the completion envelope first (terminal success, refusal, content filter, truncation, finish reason), then require the whole trimmed output to be exactly one closed-schema JSON object. Reject prose, code fences, trailing tokens, unknown fields, duplicate keys, an unknown verdict and a reason exceeding the length limit. The vision path additionally requires reviewedPartIds to match the requested and sent part ids exactly.
A4: Passed | C4: Failed | F4: Untested | L4: N/A/B | O4: Total Test Cases
A5: =COUNTIF(F53:IA53,"P") -> 25 | C5: =COUNTIF(F53:IA53,"F") -> 0 | F5: =SUM(O5,- A5,- C5) -> 0 | L5: =COUNTIF(E52:IA52,"N") -> 4 | M5: =COUNTIF(E52:IA52,"A") -> 21 | N5: =COUNTIF(E52:IA52,"B") -> 0 | O5: =COUNTA(E7:ID7) -> 25
F7: UTCID01 | G7: UTCID02 | H7: UTCID03 | I7: UTCID04 | J7: UTCID05 | K7: UTCID06 | L7: UTCID07 | M7: UTCID08 | N7: UTCID09 | O7: UTCID10 | P7: UTCID11 | Q7: UTCID12 | R7: UTCID13 | S7: UTCID14 | T7: UTCID15 | U7: UTCID16 | V7: UTCID17 | W7: UTCID18 | X7: UTCID19 | Y7: UTCID20 | Z7: UTCID21 | AA7: UTCID22 | AB7: UTCID23 | AC7: UTCID24 | AD7: UTCID25
A8: Condition | B8: envelope flags
D9: ObservedTerminalSuccess is false | F9: O
D10: IsRefused is true | G10: O
D11: IsContentFiltered is true | H11: O
D12: IsTruncated is true | I12: O
D13: all clear (terminal success, nothing set) | J13: O | K13: O | L13: O | M13: O | N13: O | O13: O | P13: O | Q13: O | R13: O | S13: O | T13: O | U13: O | V13: O | W13: O | X13: O | Y13: O | Z13: O | AA13: O | AB13: O | AC13: O | AD13: O
B14: FinishReason
D15: "end_turn" (allowed) | F15: O | G15: O | H15: O | I15: O | N15: O | O15: O | Q15: O | R15: O | S15: O | T15: O | U15: O | V15: O | W15: O | X15: O | Y15: O | Z15: O | AA15: O | AB15: O | AC15: O | AD15: O
D16: "stop" (allowed) | P16: O
D17: whitespace only | J17: O
D18: "max_tokens" | K18: O
D19: "length" | L19: O
D20: "tool_use" (not allowed) | M20: O
B21: RawText
D22: empty after trim | N22: O
D23: {"verdict":"approve","reason":"ok"} | F23: O | G23: O | H23: O | I23: O | J23: O | K23: O | L23: O | M23: O | O23: O | AD23: O
D24: {"verdict":"reject","reason":"off brand"} | P24: O
D25: {"verdict":"needs_human","reason":"unclear"} | Q25: O
D26: prose wrapping a JSON object | R26: O
D27: a fenced code block containing JSON | S27: O
D28: a valid object followed by a trailing token | T28: O
D29: an object with an unknown extra field | U29: O
D30: an object with verdict repeated twice | V30: O
D31: {"verdict":"maybe"} (unknown verdict) | W31: O
D32: a valid object with a reason above the length limit | X32: O
D33: {"verdict":"approve","reason":"ok","reviewedPartIds":["p1"]} | Y33: O | Z33: O | AA33: O | AB33: O | AC33: O
B34: part ids (vision path)
D35: requested, sent and reviewed all match | Z35: O | AD35: O
D36: reviewed misses one requested id | AA36: O
D37: requested and sent differ | AB37: O
D38: all three are empty | AC38: O
A39: Confirm | B39: Outcome
D40: Accepted, ReviewStatus "passed" | O40: O | Z40: O
D41: Accepted, ReviewStatus "rejected" | P41: O
...

Sheet LeadScoringWeights
A1: Code Module | C1: Clawbot.Domain.Leads | F1: Method | L1: LeadScoringDefaults.Rules
A2: Created By | C2: <Developer Name> | F2: Executed By | L2: <Tester Name>
A3: Test requirement | C3: The default rule set is the contract between the seed-defaults endpoint and the message classifier event codes. Every event code emitted by the classifier must have exactly one rule, weights must match the agreed values, and no code may be duplicated. purchase_intent must outweigh every other single signal.
A4: Passed | C4: Failed | F4: Untested | L4: N/A/B | O4: Total Test Cases
A5: =COUNTIF(F34:HQ34,"P") -> 12 | C5: =COUNTIF(F34:HQ34,"F") -> 0 | F5: =SUM(O5,- A5,- C5) -> 0 | L5: =COUNTIF(E33:HQ33,"N") -> 12 | M5: =COUNTIF(E33:HQ33,"A") -> 0 | N5: =COUNTIF(E33:HQ33,"B") -> 0 | O5: =COUNTA(E7:HT7) -> 12
F7: UTCID01 | G7: UTCID02 | H7: UTCID03 | I7: UTCID04 | J7: UTCID05 | K7: UTCID06 | L7: UTCID07 | M7: UTCID08 | N7: UTCID09 | O7: UTCID10 | P7: UTCID11 | Q7: UTCID12
A8: Condition | B8: assertion target
D9: rule count | F9: O
D10: asked_substantive_question weight | G10: O
D11: asked_class_size weight | H11: O
D12: asked_schedule weight | I12: O
D13: asked_teacher weight | J13: O
D14: asked_commitment weight | K14: O
D15: asked_price weight | L15: O
D16: purchase_intent weight | M16: O
D17: fast_reply weight | N17: O
D18: event code uniqueness | O18: O
D19: purchase_intent is the highest weight | P19: O
D20: every rule has a non-empty description | Q20: O
A21: Confirm | B21: Expected
D22: 8 rules | F22: O
D23: weight is 8 | G23: O
D24: weight is 12 | H24: O
D25: weight is 10 | I25: O | J25: O
D26: weight is 15 | K26: O
D27: weight is 9 | L27: O
D28: weight is 20 | M28: O
D29: weight is 5 | N29: O
D30: no duplicate event code | O30: O
D31: purchase_intent weight is strictly greater than all others | P31: O
D32: description length is above zero for every rule | Q32: O
A33: Result | B33: Type(N : Normal, A : Abnormal, B : Boundary) | F33: N | G33: N | H33: N | I33: N | J33: N | K33: N | L33: N | M33: N | N33: N | O33: N | P33: N | Q33: N
B34: Passed/Failed | F34: P | G34: P | H34: P | I34: P | J34: P | K34: P | L34: P | M34: P | N34: P | O34: P | P34: P | Q34: P
B35: Executed Date | F35: 46244.708 | G35: 46244.708 | H35: 46244.708 | I35: 46244.708 | J35: 46244.708 | K35: 46244.708 | L35: 46244.708 | M35: 46244.708 | N35: 46244.708 | O35: 46244.708 | P35: 46244.708 | Q35: 46244.708
B36: Defect ID

Sheet AuthPolicyConstants
A1: Code Module | C1: Clawbot.SharedKernel.Security | F1: Method | L1: AuthPolicy (SPEC-11 timing constants)
A2: Created By | C2: <Developer Name> | F2: Executed By | L2: <Tester Name>
A3: Test requirement | C3: Code is the single source of truth for auth timing. The API JwtOptions and the Infrastructure RefreshTokenOptions and Identity lockout all PostConfigure from these constants, so a stray appsettings value cannot drift the access-token lifetime, clock skew, refresh window or lockout out of sync. The Gateway is isolated by ADR-007 and must carry an identical ClockSkewSeconds in its own configuration.
A4: Passed | C4: Failed | F4: Untested | L4: N/A/B | O4: Total Test Cases
A5: =COUNTIF(F32:HQ32,"P") -> 11 | C5: =COUNTIF(F32:HQ32,"F") -> 0 | F5: =SUM(O5,- A5,- C5) -> 0 | L5: =COUNTIF(E31:HQ31,"N") -> 8 | M5: =COUNTIF(E31:HQ31,"A") -> 3 | N5: =COUNTIF(E31:HQ31,"B") -> 0 | O5: =COUNTA(E7:HT7) -> 11
F7: UTCID01 | G7: UTCID02 | H7: UTCID03 | I7: UTCID04 | J7: UTCID05 | K7: UTCID06 | L7: UTCID07 | M7: UTCID08 | N7: UTCID09 | O7: UTCID10 | P7: UTCID11
A8: Condition | B8: constant / bound option
D9: AccessTokenMinutes | F9: O
D10: ClockSkewSeconds | G10: O
D11: RefreshTokenDays | H11: O
D12: RefreshGraceSeconds | I12: O
D13: MaxFailedAccessAttempts | J13: O
D14: LockoutMinutes | K14: O
D15: JwtOptions after PostConfigure | L15: O | O15: O
D16: RefreshTokenOptions after PostConfigure | M16: O
D17: Identity lockout options after PostConfigure | N17: O
D18: Gateway configuration ClockSkewSeconds | P18: O
B19: appsettings value
D20: absent | F20: O | G20: O | H20: O | I20: O | J20: O | K20: O
D21: matches the constant | O21: O | P21: O
D22: deliberately different from the constant | L22: O | M22: O | N22: O
A23: Confirm | B23: Expected
D24: value is 15 | F24: O
D25: value is 30 | G25: O | K25: O
D26: value is 7 | H26: O
D27: value is 10 | I27: O
D28: value is 5 | J28: O
D29: bound option equals the constant, appsettings is ignored | L29: O | M29: O | N29: O | O29: O
D30: Gateway value equals AuthPolicy.ClockSkewSeconds | P30: O
A31: Result | B31: Type(N : Normal, A : Abnormal, B : Boundary) | F31: N | G31: N | H31: N | I31: N | J31: N | K31: N | L31: A | M31: A | N31: A | O31: N | P31: N
B32: Passed/Failed | F32: P | G32: P | H32: P | I32: P | J32: P | K32: P | L32: P | M32: P | N32: P | O32: P | P32: P
B33: Executed Date | F33: 46244.708 | G33: 46244.708 | H33: 46244.708 | I33: 46244.708 | J33: 46244.708 | K33: 46244.708 | L33: 46244.708 | M33: 46244.708 | N33: 46244.708 | O33: 46244.708 | P33: 46244.708
B34: Defect ID
